# Phase 11a: West guest house
# --- West Guest House (10 bedrooms) ---
fill ~-40 ~-1 ~105 ~-10 ~-1 ~135 quartz_block
fill ~-40 ~-1 ~136 ~-10 ~-1 ~155 quartz_block
fill ~-9 ~-1 ~105 ~-5 ~-1 ~135 quartz_block
fill ~-9 ~-1 ~136 ~-5 ~-1 ~155 quartz_block
fill ~-40 ~0 ~105 ~-10 ~0 ~135 dark_oak_planks
fill ~-40 ~0 ~136 ~-10 ~0 ~155 dark_oak_planks
fill ~-9 ~0 ~105 ~-5 ~0 ~135 dark_oak_planks
fill ~-9 ~0 ~136 ~-5 ~0 ~155 dark_oak_planks
fill ~-40 ~1 ~105 ~-10 ~8 ~135 quartz_block
fill ~-40 ~1 ~136 ~-10 ~8 ~155 quartz_block
fill ~-9 ~1 ~105 ~-5 ~8 ~135 quartz_block
fill ~-9 ~1 ~136 ~-5 ~8 ~155 quartz_block
fill ~-38 ~1 ~107 ~-8 ~7 ~137 air
fill ~-38 ~1 ~138 ~-8 ~7 ~153 air
fill ~-7 ~1 ~107 ~-7 ~7 ~137 air
fill ~-7 ~1 ~138 ~-7 ~7 ~153 air
fill ~-40 ~1 ~105 ~-10 ~1 ~105 gold_block
fill ~-9 ~1 ~105 ~-5 ~1 ~105 gold_block
fill ~-40 ~1 ~155 ~-10 ~1 ~155 gold_block
fill ~-9 ~1 ~155 ~-5 ~1 ~155 gold_block
fill ~-40 ~2 ~109 ~-40 ~6 ~113 glass
fill ~-5 ~2 ~109 ~-5 ~6 ~113 glass
fill ~-40 ~2 ~117 ~-40 ~6 ~121 glass
fill ~-5 ~2 ~117 ~-5 ~6 ~121 glass
fill ~-40 ~2 ~125 ~-40 ~6 ~129 glass
fill ~-5 ~2 ~125 ~-5 ~6 ~129 glass
fill ~-40 ~2 ~133 ~-40 ~6 ~137 glass
fill ~-5 ~2 ~133 ~-5 ~6 ~137 glass
fill ~-40 ~2 ~141 ~-40 ~6 ~145 glass
fill ~-5 ~2 ~141 ~-5 ~6 ~145 glass
fill ~-40 ~2 ~149 ~-40 ~6 ~153 glass
fill ~-5 ~2 ~149 ~-5 ~6 ~153 glass
fill ~-37 ~1 ~109 ~-24 ~1 ~114 white_wool
fill ~-38 ~1 ~108 ~-23 ~7 ~108 quartz_block
fill ~-38 ~1 ~115 ~-23 ~7 ~115 quartz_block
fill ~-23 ~1 ~108 ~-23 ~7 ~115 quartz_block
fill ~-37 ~2 ~109 ~-24 ~7 ~114 air
fill ~-32 ~1 ~112 ~-30 ~1 ~113 white_wool
fill ~-32 ~1 ~114 ~-30 ~2 ~114 gold_block
fill ~-32 ~1 ~113 ~-30 ~1 ~113 red_wool
setblock ~-33 ~1 ~113 dark_oak_planks
setblock ~-29 ~1 ~113 dark_oak_planks
setblock ~-33 ~2 ~113 sea_lantern
setblock ~-29 ~2 ~113 sea_lantern
fill ~-25 ~1 ~110 ~-25 ~1 ~112 dark_oak_planks
setblock ~-36 ~1 ~110 spruce_planks
fill ~-36 ~2 ~108 ~-35 ~3 ~108 air
fill ~-36 ~4 ~108 ~-35 ~4 ~108 gold_block
setblock ~-31 ~7 ~111 glowstone
fill ~-21 ~1 ~109 ~-8 ~1 ~114 orange_wool
fill ~-22 ~1 ~108 ~-7 ~7 ~108 quartz_block
fill ~-22 ~1 ~115 ~-7 ~7 ~115 quartz_block
fill ~-7 ~1 ~108 ~-7 ~7 ~115 quartz_block
fill ~-21 ~2 ~109 ~-8 ~7 ~114 air
fill ~-16 ~1 ~112 ~-14 ~1 ~113 white_wool
fill ~-16 ~1 ~114 ~-14 ~2 ~114 gold_block
fill ~-16 ~1 ~113 ~-14 ~1 ~113 red_wool
setblock ~-17 ~1 ~113 dark_oak_planks
setblock ~-13 ~1 ~113 dark_oak_planks
setblock ~-17 ~2 ~113 sea_lantern
setblock ~-13 ~2 ~113 sea_lantern
fill ~-9 ~1 ~110 ~-9 ~1 ~112 dark_oak_planks
setblock ~-20 ~1 ~110 spruce_planks
fill ~-20 ~2 ~108 ~-19 ~3 ~108 air
fill ~-20 ~4 ~108 ~-19 ~4 ~108 gold_block
setblock ~-15 ~7 ~111 glowstone
fill ~-37 ~1 ~118 ~-24 ~1 ~123 red_wool
fill ~-38 ~1 ~117 ~-23 ~7 ~117 quartz_block
fill ~-38 ~1 ~124 ~-23 ~7 ~124 quartz_block
fill ~-23 ~1 ~117 ~-23 ~7 ~124 quartz_block
fill ~-37 ~2 ~118 ~-24 ~7 ~123 air
fill ~-32 ~1 ~121 ~-30 ~1 ~122 white_wool
fill ~-32 ~1 ~123 ~-30 ~2 ~123 gold_block
fill ~-32 ~1 ~122 ~-30 ~1 ~122 red_wool
setblock ~-33 ~1 ~122 dark_oak_planks
setblock ~-29 ~1 ~122 dark_oak_planks
setblock ~-33 ~2 ~122 sea_lantern
setblock ~-29 ~2 ~122 sea_lantern
fill ~-25 ~1 ~119 ~-25 ~1 ~121 dark_oak_planks
setblock ~-36 ~1 ~119 spruce_planks
fill ~-36 ~2 ~117 ~-35 ~3 ~117 air
fill ~-36 ~4 ~117 ~-35 ~4 ~117 gold_block
setblock ~-31 ~7 ~120 glowstone
fill ~-21 ~1 ~118 ~-8 ~1 ~123 lime_wool
fill ~-22 ~1 ~117 ~-7 ~7 ~117 quartz_block
fill ~-22 ~1 ~124 ~-7 ~7 ~124 quartz_block
fill ~-7 ~1 ~117 ~-7 ~7 ~124 quartz_block
fill ~-21 ~2 ~118 ~-8 ~7 ~123 air
fill ~-16 ~1 ~121 ~-14 ~1 ~122 white_wool
fill ~-16 ~1 ~123 ~-14 ~2 ~123 gold_block
fill ~-16 ~1 ~122 ~-14 ~1 ~122 red_wool
setblock ~-17 ~1 ~122 dark_oak_planks
setblock ~-13 ~1 ~122 dark_oak_planks
setblock ~-17 ~2 ~122 sea_lantern
setblock ~-13 ~2 ~122 sea_lantern
fill ~-9 ~1 ~119 ~-9 ~1 ~121 dark_oak_planks
setblock ~-20 ~1 ~119 spruce_planks
fill ~-20 ~2 ~117 ~-19 ~3 ~117 air
fill ~-20 ~4 ~117 ~-19 ~4 ~117 gold_block
setblock ~-15 ~7 ~120 glowstone
fill ~-37 ~1 ~127 ~-24 ~1 ~132 blue_wool
fill ~-38 ~1 ~126 ~-23 ~7 ~126 quartz_block
fill ~-38 ~1 ~133 ~-23 ~7 ~133 quartz_block
fill ~-23 ~1 ~126 ~-23 ~7 ~133 quartz_block
fill ~-37 ~2 ~127 ~-24 ~7 ~132 air
fill ~-32 ~1 ~130 ~-30 ~1 ~131 white_wool
fill ~-32 ~1 ~132 ~-30 ~2 ~132 gold_block
fill ~-32 ~1 ~131 ~-30 ~1 ~131 red_wool
setblock ~-33 ~1 ~131 dark_oak_planks
setblock ~-29 ~1 ~131 dark_oak_planks
setblock ~-33 ~2 ~131 sea_lantern
setblock ~-29 ~2 ~131 sea_lantern
fill ~-25 ~1 ~128 ~-25 ~1 ~130 dark_oak_planks
setblock ~-36 ~1 ~128 spruce_planks
fill ~-36 ~2 ~126 ~-35 ~3 ~126 air
fill ~-36 ~4 ~126 ~-35 ~4 ~126 gold_block
setblock ~-31 ~7 ~129 glowstone
fill ~-21 ~1 ~127 ~-8 ~1 ~132 yellow_wool
fill ~-22 ~1 ~126 ~-7 ~7 ~126 quartz_block
fill ~-22 ~1 ~133 ~-7 ~7 ~133 quartz_block
fill ~-7 ~1 ~126 ~-7 ~7 ~133 quartz_block
fill ~-21 ~2 ~127 ~-8 ~7 ~132 air
fill ~-16 ~1 ~130 ~-14 ~1 ~131 white_wool
fill ~-16 ~1 ~132 ~-14 ~2 ~132 gold_block
fill ~-16 ~1 ~131 ~-14 ~1 ~131 red_wool
setblock ~-17 ~1 ~131 dark_oak_planks
setblock ~-13 ~1 ~131 dark_oak_planks
setblock ~-17 ~2 ~131 sea_lantern
setblock ~-13 ~2 ~131 sea_lantern
fill ~-9 ~1 ~128 ~-9 ~1 ~130 dark_oak_planks
setblock ~-20 ~1 ~128 spruce_planks
fill ~-20 ~2 ~126 ~-19 ~3 ~126 air
fill ~-20 ~4 ~126 ~-19 ~4 ~126 gold_block
setblock ~-15 ~7 ~129 glowstone
fill ~-37 ~1 ~136 ~-24 ~1 ~141 cyan_wool
fill ~-38 ~1 ~135 ~-23 ~7 ~135 quartz_block
fill ~-38 ~1 ~142 ~-23 ~7 ~142 quartz_block
fill ~-23 ~1 ~135 ~-23 ~7 ~142 quartz_block
fill ~-37 ~2 ~136 ~-24 ~7 ~141 air
fill ~-32 ~1 ~139 ~-30 ~1 ~140 white_wool
fill ~-32 ~1 ~141 ~-30 ~2 ~141 gold_block
fill ~-32 ~1 ~140 ~-30 ~1 ~140 red_wool
setblock ~-33 ~1 ~140 dark_oak_planks
setblock ~-29 ~1 ~140 dark_oak_planks
setblock ~-33 ~2 ~140 sea_lantern
setblock ~-29 ~2 ~140 sea_lantern
fill ~-25 ~1 ~137 ~-25 ~1 ~139 dark_oak_planks
setblock ~-36 ~1 ~137 spruce_planks
fill ~-36 ~2 ~135 ~-35 ~3 ~135 air
fill ~-36 ~4 ~135 ~-35 ~4 ~135 gold_block
setblock ~-31 ~7 ~138 glowstone
fill ~-21 ~1 ~136 ~-8 ~1 ~141 purple_wool
fill ~-22 ~1 ~135 ~-7 ~7 ~135 quartz_block
fill ~-22 ~1 ~142 ~-7 ~7 ~142 quartz_block
fill ~-7 ~1 ~135 ~-7 ~7 ~142 quartz_block
fill ~-21 ~2 ~136 ~-8 ~7 ~141 air
fill ~-16 ~1 ~139 ~-14 ~1 ~140 white_wool
fill ~-16 ~1 ~141 ~-14 ~2 ~141 gold_block
fill ~-16 ~1 ~140 ~-14 ~1 ~140 red_wool
setblock ~-17 ~1 ~140 dark_oak_planks
setblock ~-13 ~1 ~140 dark_oak_planks
setblock ~-17 ~2 ~140 sea_lantern
setblock ~-13 ~2 ~140 sea_lantern
fill ~-9 ~1 ~137 ~-9 ~1 ~139 dark_oak_planks
setblock ~-20 ~1 ~137 spruce_planks
fill ~-20 ~2 ~135 ~-19 ~3 ~135 air
fill ~-20 ~4 ~135 ~-19 ~4 ~135 gold_block
setblock ~-15 ~7 ~138 glowstone
fill ~-37 ~1 ~145 ~-24 ~1 ~150 pink_wool
fill ~-38 ~1 ~144 ~-23 ~7 ~144 quartz_block
fill ~-38 ~1 ~151 ~-23 ~7 ~151 quartz_block
fill ~-23 ~1 ~144 ~-23 ~7 ~151 quartz_block
fill ~-37 ~2 ~145 ~-24 ~7 ~150 air
fill ~-32 ~1 ~148 ~-30 ~1 ~149 white_wool
fill ~-32 ~1 ~150 ~-30 ~2 ~150 gold_block
fill ~-32 ~1 ~149 ~-30 ~1 ~149 red_wool
setblock ~-33 ~1 ~149 dark_oak_planks
setblock ~-29 ~1 ~149 dark_oak_planks
setblock ~-33 ~2 ~149 sea_lantern
setblock ~-29 ~2 ~149 sea_lantern
fill ~-25 ~1 ~146 ~-25 ~1 ~148 dark_oak_planks
setblock ~-36 ~1 ~146 spruce_planks
fill ~-36 ~2 ~144 ~-35 ~3 ~144 air
fill ~-36 ~4 ~144 ~-35 ~4 ~144 gold_block
setblock ~-31 ~7 ~147 glowstone
fill ~-21 ~1 ~145 ~-8 ~1 ~150 magenta_wool
fill ~-22 ~1 ~144 ~-7 ~7 ~144 quartz_block
fill ~-22 ~1 ~151 ~-7 ~7 ~151 quartz_block
fill ~-7 ~1 ~144 ~-7 ~7 ~151 quartz_block
fill ~-21 ~2 ~145 ~-8 ~7 ~150 air
fill ~-16 ~1 ~148 ~-14 ~1 ~149 white_wool
fill ~-16 ~1 ~150 ~-14 ~2 ~150 gold_block
fill ~-16 ~1 ~149 ~-14 ~1 ~149 red_wool
setblock ~-17 ~1 ~149 dark_oak_planks
setblock ~-13 ~1 ~149 dark_oak_planks
setblock ~-17 ~2 ~149 sea_lantern
setblock ~-13 ~2 ~149 sea_lantern
fill ~-9 ~1 ~146 ~-9 ~1 ~148 dark_oak_planks
setblock ~-20 ~1 ~146 spruce_planks
fill ~-20 ~2 ~144 ~-19 ~3 ~144 air
fill ~-20 ~4 ~144 ~-19 ~4 ~144 gold_block
setblock ~-15 ~7 ~147 glowstone
fill ~-40 ~8 ~105 ~-10 ~8 ~135 dark_oak_planks
fill ~-40 ~8 ~136 ~-10 ~8 ~155 dark_oak_planks
fill ~-9 ~8 ~105 ~-5 ~8 ~135 dark_oak_planks
fill ~-9 ~8 ~136 ~-5 ~8 ~155 dark_oak_planks
fill ~-40 ~9 ~105 ~-10 ~16 ~135 quartz_block
fill ~-40 ~9 ~136 ~-10 ~16 ~155 quartz_block
fill ~-9 ~9 ~105 ~-5 ~16 ~135 quartz_block
fill ~-9 ~9 ~136 ~-5 ~16 ~155 quartz_block
fill ~-38 ~9 ~107 ~-8 ~15 ~137 air
fill ~-38 ~9 ~138 ~-8 ~15 ~153 air
fill ~-7 ~9 ~107 ~-7 ~15 ~137 air
fill ~-7 ~9 ~138 ~-7 ~15 ~153 air
fill ~-40 ~9 ~105 ~-10 ~9 ~105 gold_block
fill ~-9 ~9 ~105 ~-5 ~9 ~105 gold_block
fill ~-40 ~9 ~155 ~-10 ~9 ~155 gold_block
fill ~-9 ~9 ~155 ~-5 ~9 ~155 gold_block
fill ~-40 ~10 ~109 ~-40 ~14 ~113 glass
fill ~-5 ~10 ~109 ~-5 ~14 ~113 glass
fill ~-40 ~10 ~117 ~-40 ~14 ~121 glass
fill ~-5 ~10 ~117 ~-5 ~14 ~121 glass
fill ~-40 ~10 ~125 ~-40 ~14 ~129 glass
fill ~-5 ~10 ~125 ~-5 ~14 ~129 glass
fill ~-40 ~10 ~133 ~-40 ~14 ~137 glass
fill ~-5 ~10 ~133 ~-5 ~14 ~137 glass
fill ~-40 ~10 ~141 ~-40 ~14 ~145 glass
fill ~-5 ~10 ~141 ~-5 ~14 ~145 glass
fill ~-40 ~10 ~149 ~-40 ~14 ~153 glass
fill ~-5 ~10 ~149 ~-5 ~14 ~153 glass
fill ~-37 ~9 ~109 ~-24 ~9 ~114 white_wool
fill ~-38 ~9 ~108 ~-23 ~15 ~108 quartz_block
fill ~-38 ~9 ~115 ~-23 ~15 ~115 quartz_block
fill ~-23 ~9 ~108 ~-23 ~15 ~115 quartz_block
fill ~-37 ~10 ~109 ~-24 ~15 ~114 air
fill ~-32 ~9 ~112 ~-30 ~9 ~113 white_wool
fill ~-32 ~9 ~114 ~-30 ~10 ~114 gold_block
fill ~-32 ~9 ~113 ~-30 ~9 ~113 red_wool
setblock ~-33 ~9 ~113 dark_oak_planks
setblock ~-29 ~9 ~113 dark_oak_planks
setblock ~-33 ~10 ~113 sea_lantern
setblock ~-29 ~10 ~113 sea_lantern
fill ~-25 ~9 ~110 ~-25 ~9 ~112 dark_oak_planks
setblock ~-36 ~9 ~110 spruce_planks
fill ~-36 ~10 ~108 ~-35 ~11 ~108 air
fill ~-36 ~12 ~108 ~-35 ~12 ~108 gold_block
setblock ~-31 ~15 ~111 glowstone
fill ~-21 ~9 ~109 ~-8 ~9 ~114 orange_wool
fill ~-22 ~9 ~108 ~-7 ~15 ~108 quartz_block
fill ~-22 ~9 ~115 ~-7 ~15 ~115 quartz_block
fill ~-7 ~9 ~108 ~-7 ~15 ~115 quartz_block
fill ~-21 ~10 ~109 ~-8 ~15 ~114 air
fill ~-16 ~9 ~112 ~-14 ~9 ~113 white_wool
fill ~-16 ~9 ~114 ~-14 ~10 ~114 gold_block
fill ~-16 ~9 ~113 ~-14 ~9 ~113 red_wool
setblock ~-17 ~9 ~113 dark_oak_planks
setblock ~-13 ~9 ~113 dark_oak_planks
setblock ~-17 ~10 ~113 sea_lantern
setblock ~-13 ~10 ~113 sea_lantern
fill ~-9 ~9 ~110 ~-9 ~9 ~112 dark_oak_planks
setblock ~-20 ~9 ~110 spruce_planks
fill ~-20 ~10 ~108 ~-19 ~11 ~108 air
fill ~-20 ~12 ~108 ~-19 ~12 ~108 gold_block
setblock ~-15 ~15 ~111 glowstone
fill ~-37 ~9 ~118 ~-24 ~9 ~123 red_wool
fill ~-38 ~9 ~117 ~-23 ~15 ~117 quartz_block
fill ~-38 ~9 ~124 ~-23 ~15 ~124 quartz_block
fill ~-23 ~9 ~117 ~-23 ~15 ~124 quartz_block
fill ~-37 ~10 ~118 ~-24 ~15 ~123 air
fill ~-32 ~9 ~121 ~-30 ~9 ~122 white_wool
fill ~-32 ~9 ~123 ~-30 ~10 ~123 gold_block
fill ~-32 ~9 ~122 ~-30 ~9 ~122 red_wool
setblock ~-33 ~9 ~122 dark_oak_planks
setblock ~-29 ~9 ~122 dark_oak_planks
setblock ~-33 ~10 ~122 sea_lantern
setblock ~-29 ~10 ~122 sea_lantern
fill ~-25 ~9 ~119 ~-25 ~9 ~121 dark_oak_planks
setblock ~-36 ~9 ~119 spruce_planks
fill ~-36 ~10 ~117 ~-35 ~11 ~117 air
fill ~-36 ~12 ~117 ~-35 ~12 ~117 gold_block
setblock ~-31 ~15 ~120 glowstone
fill ~-21 ~9 ~118 ~-8 ~9 ~123 lime_wool
fill ~-22 ~9 ~117 ~-7 ~15 ~117 quartz_block
fill ~-22 ~9 ~124 ~-7 ~15 ~124 quartz_block
fill ~-7 ~9 ~117 ~-7 ~15 ~124 quartz_block
fill ~-21 ~10 ~118 ~-8 ~15 ~123 air
fill ~-16 ~9 ~121 ~-14 ~9 ~122 white_wool
fill ~-16 ~9 ~123 ~-14 ~10 ~123 gold_block
fill ~-16 ~9 ~122 ~-14 ~9 ~122 red_wool
setblock ~-17 ~9 ~122 dark_oak_planks
setblock ~-13 ~9 ~122 dark_oak_planks
setblock ~-17 ~10 ~122 sea_lantern
setblock ~-13 ~10 ~122 sea_lantern
fill ~-9 ~9 ~119 ~-9 ~9 ~121 dark_oak_planks
setblock ~-20 ~9 ~119 spruce_planks
fill ~-20 ~10 ~117 ~-19 ~11 ~117 air
fill ~-20 ~12 ~117 ~-19 ~12 ~117 gold_block
setblock ~-15 ~15 ~120 glowstone
fill ~-37 ~9 ~127 ~-24 ~9 ~132 blue_wool
fill ~-38 ~9 ~126 ~-23 ~15 ~126 quartz_block
fill ~-38 ~9 ~133 ~-23 ~15 ~133 quartz_block
fill ~-23 ~9 ~126 ~-23 ~15 ~133 quartz_block
fill ~-37 ~10 ~127 ~-24 ~15 ~132 air
fill ~-32 ~9 ~130 ~-30 ~9 ~131 white_wool
fill ~-32 ~9 ~132 ~-30 ~10 ~132 gold_block
fill ~-32 ~9 ~131 ~-30 ~9 ~131 red_wool
setblock ~-33 ~9 ~131 dark_oak_planks
setblock ~-29 ~9 ~131 dark_oak_planks
setblock ~-33 ~10 ~131 sea_lantern
setblock ~-29 ~10 ~131 sea_lantern
fill ~-25 ~9 ~128 ~-25 ~9 ~130 dark_oak_planks
setblock ~-36 ~9 ~128 spruce_planks
fill ~-36 ~10 ~126 ~-35 ~11 ~126 air
fill ~-36 ~12 ~126 ~-35 ~12 ~126 gold_block
setblock ~-31 ~15 ~129 glowstone
fill ~-21 ~9 ~127 ~-8 ~9 ~132 yellow_wool
fill ~-22 ~9 ~126 ~-7 ~15 ~126 quartz_block
fill ~-22 ~9 ~133 ~-7 ~15 ~133 quartz_block
fill ~-7 ~9 ~126 ~-7 ~15 ~133 quartz_block
fill ~-21 ~10 ~127 ~-8 ~15 ~132 air
fill ~-16 ~9 ~130 ~-14 ~9 ~131 white_wool
fill ~-16 ~9 ~132 ~-14 ~10 ~132 gold_block
fill ~-16 ~9 ~131 ~-14 ~9 ~131 red_wool
setblock ~-17 ~9 ~131 dark_oak_planks
setblock ~-13 ~9 ~131 dark_oak_planks
setblock ~-17 ~10 ~131 sea_lantern
setblock ~-13 ~10 ~131 sea_lantern
fill ~-9 ~9 ~128 ~-9 ~9 ~130 dark_oak_planks
setblock ~-20 ~9 ~128 spruce_planks
fill ~-20 ~10 ~126 ~-19 ~11 ~126 air
fill ~-20 ~12 ~126 ~-19 ~12 ~126 gold_block
setblock ~-15 ~15 ~129 glowstone
fill ~-37 ~9 ~136 ~-24 ~9 ~141 cyan_wool
fill ~-38 ~9 ~135 ~-23 ~15 ~135 quartz_block
fill ~-38 ~9 ~142 ~-23 ~15 ~142 quartz_block
fill ~-23 ~9 ~135 ~-23 ~15 ~142 quartz_block
fill ~-37 ~10 ~136 ~-24 ~15 ~141 air
fill ~-32 ~9 ~139 ~-30 ~9 ~140 white_wool
fill ~-32 ~9 ~141 ~-30 ~10 ~141 gold_block
fill ~-32 ~9 ~140 ~-30 ~9 ~140 red_wool
setblock ~-33 ~9 ~140 dark_oak_planks
setblock ~-29 ~9 ~140 dark_oak_planks
setblock ~-33 ~10 ~140 sea_lantern
setblock ~-29 ~10 ~140 sea_lantern
fill ~-25 ~9 ~137 ~-25 ~9 ~139 dark_oak_planks
setblock ~-36 ~9 ~137 spruce_planks
fill ~-36 ~10 ~135 ~-35 ~11 ~135 air
fill ~-36 ~12 ~135 ~-35 ~12 ~135 gold_block
setblock ~-31 ~15 ~138 glowstone
fill ~-21 ~9 ~136 ~-8 ~9 ~141 purple_wool
fill ~-22 ~9 ~135 ~-7 ~15 ~135 quartz_block
fill ~-22 ~9 ~142 ~-7 ~15 ~142 quartz_block
fill ~-7 ~9 ~135 ~-7 ~15 ~142 quartz_block
fill ~-21 ~10 ~136 ~-8 ~15 ~141 air
fill ~-16 ~9 ~139 ~-14 ~9 ~140 white_wool
fill ~-16 ~9 ~141 ~-14 ~10 ~141 gold_block
fill ~-16 ~9 ~140 ~-14 ~9 ~140 red_wool
setblock ~-17 ~9 ~140 dark_oak_planks
setblock ~-13 ~9 ~140 dark_oak_planks
setblock ~-17 ~10 ~140 sea_lantern
setblock ~-13 ~10 ~140 sea_lantern
fill ~-9 ~9 ~137 ~-9 ~9 ~139 dark_oak_planks
setblock ~-20 ~9 ~137 spruce_planks
fill ~-20 ~10 ~135 ~-19 ~11 ~135 air
fill ~-20 ~12 ~135 ~-19 ~12 ~135 gold_block
setblock ~-15 ~15 ~138 glowstone
fill ~-37 ~9 ~145 ~-24 ~9 ~150 pink_wool
fill ~-38 ~9 ~144 ~-23 ~15 ~144 quartz_block
fill ~-38 ~9 ~151 ~-23 ~15 ~151 quartz_block
fill ~-23 ~9 ~144 ~-23 ~15 ~151 quartz_block
fill ~-37 ~10 ~145 ~-24 ~15 ~150 air
fill ~-32 ~9 ~148 ~-30 ~9 ~149 white_wool
fill ~-32 ~9 ~150 ~-30 ~10 ~150 gold_block
fill ~-32 ~9 ~149 ~-30 ~9 ~149 red_wool
setblock ~-33 ~9 ~149 dark_oak_planks
setblock ~-29 ~9 ~149 dark_oak_planks
setblock ~-33 ~10 ~149 sea_lantern
setblock ~-29 ~10 ~149 sea_lantern
fill ~-25 ~9 ~146 ~-25 ~9 ~148 dark_oak_planks
setblock ~-36 ~9 ~146 spruce_planks
fill ~-36 ~10 ~144 ~-35 ~11 ~144 air
fill ~-36 ~12 ~144 ~-35 ~12 ~144 gold_block
setblock ~-31 ~15 ~147 glowstone
fill ~-21 ~9 ~145 ~-8 ~9 ~150 magenta_wool
fill ~-22 ~9 ~144 ~-7 ~15 ~144 quartz_block
fill ~-22 ~9 ~151 ~-7 ~15 ~151 quartz_block
fill ~-7 ~9 ~144 ~-7 ~15 ~151 quartz_block
fill ~-21 ~10 ~145 ~-8 ~15 ~150 air
fill ~-16 ~9 ~148 ~-14 ~9 ~149 white_wool
fill ~-16 ~9 ~150 ~-14 ~10 ~150 gold_block
fill ~-16 ~9 ~149 ~-14 ~9 ~149 red_wool
setblock ~-17 ~9 ~149 dark_oak_planks
setblock ~-13 ~9 ~149 dark_oak_planks
setblock ~-17 ~10 ~149 sea_lantern
setblock ~-13 ~10 ~149 sea_lantern
fill ~-9 ~9 ~146 ~-9 ~9 ~148 dark_oak_planks
setblock ~-20 ~9 ~146 spruce_planks
fill ~-20 ~10 ~144 ~-19 ~11 ~144 air
fill ~-20 ~12 ~144 ~-19 ~12 ~144 gold_block
setblock ~-15 ~15 ~147 glowstone
fill ~-40 ~16 ~105 ~-10 ~16 ~135 quartz_block
fill ~-40 ~16 ~136 ~-10 ~16 ~155 quartz_block
fill ~-9 ~16 ~105 ~-5 ~16 ~135 quartz_block
fill ~-9 ~16 ~136 ~-5 ~16 ~155 quartz_block
fill ~-25 ~1 ~105 ~-21 ~4 ~105 air
fill ~-25 ~5 ~105 ~-21 ~5 ~105 gold_block
function bezos_guesthouse2
