# Phase 11b: East guest house
# --- East Guest House (10 bedrooms) ---
fill ~145 ~-1 ~105 ~175 ~-1 ~135 quartz_block
fill ~145 ~-1 ~136 ~175 ~-1 ~155 quartz_block
fill ~176 ~-1 ~105 ~180 ~-1 ~135 quartz_block
fill ~176 ~-1 ~136 ~180 ~-1 ~155 quartz_block
fill ~145 ~0 ~105 ~175 ~0 ~135 dark_oak_planks
fill ~145 ~0 ~136 ~175 ~0 ~155 dark_oak_planks
fill ~176 ~0 ~105 ~180 ~0 ~135 dark_oak_planks
fill ~176 ~0 ~136 ~180 ~0 ~155 dark_oak_planks
fill ~145 ~1 ~105 ~175 ~8 ~135 quartz_block
fill ~145 ~1 ~136 ~175 ~8 ~155 quartz_block
fill ~176 ~1 ~105 ~180 ~8 ~135 quartz_block
fill ~176 ~1 ~136 ~180 ~8 ~155 quartz_block
fill ~147 ~1 ~107 ~177 ~7 ~137 air
fill ~147 ~1 ~138 ~177 ~7 ~153 air
fill ~178 ~1 ~107 ~178 ~7 ~137 air
fill ~178 ~1 ~138 ~178 ~7 ~153 air
fill ~145 ~1 ~105 ~175 ~1 ~105 gold_block
fill ~176 ~1 ~105 ~180 ~1 ~105 gold_block
fill ~145 ~1 ~155 ~175 ~1 ~155 gold_block
fill ~176 ~1 ~155 ~180 ~1 ~155 gold_block
fill ~145 ~2 ~109 ~145 ~6 ~113 glass
fill ~180 ~2 ~109 ~180 ~6 ~113 glass
fill ~145 ~2 ~117 ~145 ~6 ~121 glass
fill ~180 ~2 ~117 ~180 ~6 ~121 glass
fill ~145 ~2 ~125 ~145 ~6 ~129 glass
fill ~180 ~2 ~125 ~180 ~6 ~129 glass
fill ~145 ~2 ~133 ~145 ~6 ~137 glass
fill ~180 ~2 ~133 ~180 ~6 ~137 glass
fill ~145 ~2 ~141 ~145 ~6 ~145 glass
fill ~180 ~2 ~141 ~180 ~6 ~145 glass
fill ~145 ~2 ~149 ~145 ~6 ~153 glass
fill ~180 ~2 ~149 ~180 ~6 ~153 glass
fill ~148 ~1 ~109 ~161 ~1 ~114 white_wool
fill ~147 ~1 ~108 ~162 ~7 ~108 quartz_block
fill ~147 ~1 ~115 ~162 ~7 ~115 quartz_block
fill ~162 ~1 ~108 ~162 ~7 ~115 quartz_block
fill ~148 ~2 ~109 ~161 ~7 ~114 air
fill ~153 ~1 ~112 ~155 ~1 ~113 white_wool
fill ~153 ~1 ~114 ~155 ~2 ~114 gold_block
fill ~153 ~1 ~113 ~155 ~1 ~113 red_wool
setblock ~152 ~1 ~113 dark_oak_planks
setblock ~156 ~1 ~113 dark_oak_planks
setblock ~152 ~2 ~113 sea_lantern
setblock ~156 ~2 ~113 sea_lantern
fill ~160 ~1 ~110 ~160 ~1 ~112 dark_oak_planks
setblock ~149 ~1 ~110 spruce_planks
fill ~149 ~2 ~108 ~150 ~3 ~108 air
fill ~149 ~4 ~108 ~150 ~4 ~108 gold_block
setblock ~154 ~7 ~111 glowstone
fill ~164 ~1 ~109 ~177 ~1 ~114 orange_wool
fill ~163 ~1 ~108 ~178 ~7 ~108 quartz_block
fill ~163 ~1 ~115 ~178 ~7 ~115 quartz_block
fill ~178 ~1 ~108 ~178 ~7 ~115 quartz_block
fill ~164 ~2 ~109 ~177 ~7 ~114 air
fill ~169 ~1 ~112 ~171 ~1 ~113 white_wool
fill ~169 ~1 ~114 ~171 ~2 ~114 gold_block
fill ~169 ~1 ~113 ~171 ~1 ~113 red_wool
setblock ~168 ~1 ~113 dark_oak_planks
setblock ~172 ~1 ~113 dark_oak_planks
setblock ~168 ~2 ~113 sea_lantern
setblock ~172 ~2 ~113 sea_lantern
fill ~176 ~1 ~110 ~176 ~1 ~112 dark_oak_planks
setblock ~165 ~1 ~110 spruce_planks
fill ~165 ~2 ~108 ~166 ~3 ~108 air
fill ~165 ~4 ~108 ~166 ~4 ~108 gold_block
setblock ~170 ~7 ~111 glowstone
fill ~148 ~1 ~118 ~161 ~1 ~123 red_wool
fill ~147 ~1 ~117 ~162 ~7 ~117 quartz_block
fill ~147 ~1 ~124 ~162 ~7 ~124 quartz_block
fill ~162 ~1 ~117 ~162 ~7 ~124 quartz_block
fill ~148 ~2 ~118 ~161 ~7 ~123 air
fill ~153 ~1 ~121 ~155 ~1 ~122 white_wool
fill ~153 ~1 ~123 ~155 ~2 ~123 gold_block
fill ~153 ~1 ~122 ~155 ~1 ~122 red_wool
setblock ~152 ~1 ~122 dark_oak_planks
setblock ~156 ~1 ~122 dark_oak_planks
setblock ~152 ~2 ~122 sea_lantern
setblock ~156 ~2 ~122 sea_lantern
fill ~160 ~1 ~119 ~160 ~1 ~121 dark_oak_planks
setblock ~149 ~1 ~119 spruce_planks
fill ~149 ~2 ~117 ~150 ~3 ~117 air
fill ~149 ~4 ~117 ~150 ~4 ~117 gold_block
setblock ~154 ~7 ~120 glowstone
fill ~164 ~1 ~118 ~177 ~1 ~123 lime_wool
fill ~163 ~1 ~117 ~178 ~7 ~117 quartz_block
fill ~163 ~1 ~124 ~178 ~7 ~124 quartz_block
fill ~178 ~1 ~117 ~178 ~7 ~124 quartz_block
fill ~164 ~2 ~118 ~177 ~7 ~123 air
fill ~169 ~1 ~121 ~171 ~1 ~122 white_wool
fill ~169 ~1 ~123 ~171 ~2 ~123 gold_block
fill ~169 ~1 ~122 ~171 ~1 ~122 red_wool
setblock ~168 ~1 ~122 dark_oak_planks
setblock ~172 ~1 ~122 dark_oak_planks
setblock ~168 ~2 ~122 sea_lantern
setblock ~172 ~2 ~122 sea_lantern
fill ~176 ~1 ~119 ~176 ~1 ~121 dark_oak_planks
setblock ~165 ~1 ~119 spruce_planks
fill ~165 ~2 ~117 ~166 ~3 ~117 air
fill ~165 ~4 ~117 ~166 ~4 ~117 gold_block
setblock ~170 ~7 ~120 glowstone
fill ~148 ~1 ~127 ~161 ~1 ~132 blue_wool
fill ~147 ~1 ~126 ~162 ~7 ~126 quartz_block
fill ~147 ~1 ~133 ~162 ~7 ~133 quartz_block
fill ~162 ~1 ~126 ~162 ~7 ~133 quartz_block
fill ~148 ~2 ~127 ~161 ~7 ~132 air
fill ~153 ~1 ~130 ~155 ~1 ~131 white_wool
fill ~153 ~1 ~132 ~155 ~2 ~132 gold_block
fill ~153 ~1 ~131 ~155 ~1 ~131 red_wool
setblock ~152 ~1 ~131 dark_oak_planks
setblock ~156 ~1 ~131 dark_oak_planks
setblock ~152 ~2 ~131 sea_lantern
setblock ~156 ~2 ~131 sea_lantern
fill ~160 ~1 ~128 ~160 ~1 ~130 dark_oak_planks
setblock ~149 ~1 ~128 spruce_planks
fill ~149 ~2 ~126 ~150 ~3 ~126 air
fill ~149 ~4 ~126 ~150 ~4 ~126 gold_block
setblock ~154 ~7 ~129 glowstone
fill ~164 ~1 ~127 ~177 ~1 ~132 yellow_wool
fill ~163 ~1 ~126 ~178 ~7 ~126 quartz_block
fill ~163 ~1 ~133 ~178 ~7 ~133 quartz_block
fill ~178 ~1 ~126 ~178 ~7 ~133 quartz_block
fill ~164 ~2 ~127 ~177 ~7 ~132 air
fill ~169 ~1 ~130 ~171 ~1 ~131 white_wool
fill ~169 ~1 ~132 ~171 ~2 ~132 gold_block
fill ~169 ~1 ~131 ~171 ~1 ~131 red_wool
setblock ~168 ~1 ~131 dark_oak_planks
setblock ~172 ~1 ~131 dark_oak_planks
setblock ~168 ~2 ~131 sea_lantern
setblock ~172 ~2 ~131 sea_lantern
fill ~176 ~1 ~128 ~176 ~1 ~130 dark_oak_planks
setblock ~165 ~1 ~128 spruce_planks
fill ~165 ~2 ~126 ~166 ~3 ~126 air
fill ~165 ~4 ~126 ~166 ~4 ~126 gold_block
setblock ~170 ~7 ~129 glowstone
fill ~148 ~1 ~136 ~161 ~1 ~141 cyan_wool
fill ~147 ~1 ~135 ~162 ~7 ~135 quartz_block
fill ~147 ~1 ~142 ~162 ~7 ~142 quartz_block
fill ~162 ~1 ~135 ~162 ~7 ~142 quartz_block
fill ~148 ~2 ~136 ~161 ~7 ~141 air
fill ~153 ~1 ~139 ~155 ~1 ~140 white_wool
fill ~153 ~1 ~141 ~155 ~2 ~141 gold_block
fill ~153 ~1 ~140 ~155 ~1 ~140 red_wool
setblock ~152 ~1 ~140 dark_oak_planks
setblock ~156 ~1 ~140 dark_oak_planks
setblock ~152 ~2 ~140 sea_lantern
setblock ~156 ~2 ~140 sea_lantern
fill ~160 ~1 ~137 ~160 ~1 ~139 dark_oak_planks
setblock ~149 ~1 ~137 spruce_planks
fill ~149 ~2 ~135 ~150 ~3 ~135 air
fill ~149 ~4 ~135 ~150 ~4 ~135 gold_block
setblock ~154 ~7 ~138 glowstone
fill ~164 ~1 ~136 ~177 ~1 ~141 purple_wool
fill ~163 ~1 ~135 ~178 ~7 ~135 quartz_block
fill ~163 ~1 ~142 ~178 ~7 ~142 quartz_block
fill ~178 ~1 ~135 ~178 ~7 ~142 quartz_block
fill ~164 ~2 ~136 ~177 ~7 ~141 air
fill ~169 ~1 ~139 ~171 ~1 ~140 white_wool
fill ~169 ~1 ~141 ~171 ~2 ~141 gold_block
fill ~169 ~1 ~140 ~171 ~1 ~140 red_wool
setblock ~168 ~1 ~140 dark_oak_planks
setblock ~172 ~1 ~140 dark_oak_planks
setblock ~168 ~2 ~140 sea_lantern
setblock ~172 ~2 ~140 sea_lantern
fill ~176 ~1 ~137 ~176 ~1 ~139 dark_oak_planks
setblock ~165 ~1 ~137 spruce_planks
fill ~165 ~2 ~135 ~166 ~3 ~135 air
fill ~165 ~4 ~135 ~166 ~4 ~135 gold_block
setblock ~170 ~7 ~138 glowstone
fill ~148 ~1 ~145 ~161 ~1 ~150 pink_wool
fill ~147 ~1 ~144 ~162 ~7 ~144 quartz_block
fill ~147 ~1 ~151 ~162 ~7 ~151 quartz_block
fill ~162 ~1 ~144 ~162 ~7 ~151 quartz_block
fill ~148 ~2 ~145 ~161 ~7 ~150 air
fill ~153 ~1 ~148 ~155 ~1 ~149 white_wool
fill ~153 ~1 ~150 ~155 ~2 ~150 gold_block
fill ~153 ~1 ~149 ~155 ~1 ~149 red_wool
setblock ~152 ~1 ~149 dark_oak_planks
setblock ~156 ~1 ~149 dark_oak_planks
setblock ~152 ~2 ~149 sea_lantern
setblock ~156 ~2 ~149 sea_lantern
fill ~160 ~1 ~146 ~160 ~1 ~148 dark_oak_planks
setblock ~149 ~1 ~146 spruce_planks
fill ~149 ~2 ~144 ~150 ~3 ~144 air
fill ~149 ~4 ~144 ~150 ~4 ~144 gold_block
setblock ~154 ~7 ~147 glowstone
fill ~164 ~1 ~145 ~177 ~1 ~150 magenta_wool
fill ~163 ~1 ~144 ~178 ~7 ~144 quartz_block
fill ~163 ~1 ~151 ~178 ~7 ~151 quartz_block
fill ~178 ~1 ~144 ~178 ~7 ~151 quartz_block
fill ~164 ~2 ~145 ~177 ~7 ~150 air
fill ~169 ~1 ~148 ~171 ~1 ~149 white_wool
fill ~169 ~1 ~150 ~171 ~2 ~150 gold_block
fill ~169 ~1 ~149 ~171 ~1 ~149 red_wool
setblock ~168 ~1 ~149 dark_oak_planks
setblock ~172 ~1 ~149 dark_oak_planks
setblock ~168 ~2 ~149 sea_lantern
setblock ~172 ~2 ~149 sea_lantern
fill ~176 ~1 ~146 ~176 ~1 ~148 dark_oak_planks
setblock ~165 ~1 ~146 spruce_planks
fill ~165 ~2 ~144 ~166 ~3 ~144 air
fill ~165 ~4 ~144 ~166 ~4 ~144 gold_block
setblock ~170 ~7 ~147 glowstone
fill ~145 ~8 ~105 ~175 ~8 ~135 dark_oak_planks
fill ~145 ~8 ~136 ~175 ~8 ~155 dark_oak_planks
fill ~176 ~8 ~105 ~180 ~8 ~135 dark_oak_planks
fill ~176 ~8 ~136 ~180 ~8 ~155 dark_oak_planks
fill ~145 ~9 ~105 ~175 ~16 ~135 quartz_block
fill ~145 ~9 ~136 ~175 ~16 ~155 quartz_block
fill ~176 ~9 ~105 ~180 ~16 ~135 quartz_block
fill ~176 ~9 ~136 ~180 ~16 ~155 quartz_block
fill ~147 ~9 ~107 ~177 ~15 ~137 air
fill ~147 ~9 ~138 ~177 ~15 ~153 air
fill ~178 ~9 ~107 ~178 ~15 ~137 air
fill ~178 ~9 ~138 ~178 ~15 ~153 air
fill ~145 ~9 ~105 ~175 ~9 ~105 gold_block
fill ~176 ~9 ~105 ~180 ~9 ~105 gold_block
fill ~145 ~9 ~155 ~175 ~9 ~155 gold_block
fill ~176 ~9 ~155 ~180 ~9 ~155 gold_block
fill ~145 ~10 ~109 ~145 ~14 ~113 glass
fill ~180 ~10 ~109 ~180 ~14 ~113 glass
fill ~145 ~10 ~117 ~145 ~14 ~121 glass
fill ~180 ~10 ~117 ~180 ~14 ~121 glass
fill ~145 ~10 ~125 ~145 ~14 ~129 glass
fill ~180 ~10 ~125 ~180 ~14 ~129 glass
fill ~145 ~10 ~133 ~145 ~14 ~137 glass
fill ~180 ~10 ~133 ~180 ~14 ~137 glass
fill ~145 ~10 ~141 ~145 ~14 ~145 glass
fill ~180 ~10 ~141 ~180 ~14 ~145 glass
fill ~145 ~10 ~149 ~145 ~14 ~153 glass
fill ~180 ~10 ~149 ~180 ~14 ~153 glass
fill ~148 ~9 ~109 ~161 ~9 ~114 white_wool
fill ~147 ~9 ~108 ~162 ~15 ~108 quartz_block
fill ~147 ~9 ~115 ~162 ~15 ~115 quartz_block
fill ~162 ~9 ~108 ~162 ~15 ~115 quartz_block
fill ~148 ~10 ~109 ~161 ~15 ~114 air
fill ~153 ~9 ~112 ~155 ~9 ~113 white_wool
fill ~153 ~9 ~114 ~155 ~10 ~114 gold_block
fill ~153 ~9 ~113 ~155 ~9 ~113 red_wool
setblock ~152 ~9 ~113 dark_oak_planks
setblock ~156 ~9 ~113 dark_oak_planks
setblock ~152 ~10 ~113 sea_lantern
setblock ~156 ~10 ~113 sea_lantern
fill ~160 ~9 ~110 ~160 ~9 ~112 dark_oak_planks
setblock ~149 ~9 ~110 spruce_planks
fill ~149 ~10 ~108 ~150 ~11 ~108 air
fill ~149 ~12 ~108 ~150 ~12 ~108 gold_block
setblock ~154 ~15 ~111 glowstone
fill ~164 ~9 ~109 ~177 ~9 ~114 orange_wool
fill ~163 ~9 ~108 ~178 ~15 ~108 quartz_block
fill ~163 ~9 ~115 ~178 ~15 ~115 quartz_block
fill ~178 ~9 ~108 ~178 ~15 ~115 quartz_block
fill ~164 ~10 ~109 ~177 ~15 ~114 air
fill ~169 ~9 ~112 ~171 ~9 ~113 white_wool
fill ~169 ~9 ~114 ~171 ~10 ~114 gold_block
fill ~169 ~9 ~113 ~171 ~9 ~113 red_wool
setblock ~168 ~9 ~113 dark_oak_planks
setblock ~172 ~9 ~113 dark_oak_planks
setblock ~168 ~10 ~113 sea_lantern
setblock ~172 ~10 ~113 sea_lantern
fill ~176 ~9 ~110 ~176 ~9 ~112 dark_oak_planks
setblock ~165 ~9 ~110 spruce_planks
fill ~165 ~10 ~108 ~166 ~11 ~108 air
fill ~165 ~12 ~108 ~166 ~12 ~108 gold_block
setblock ~170 ~15 ~111 glowstone
fill ~148 ~9 ~118 ~161 ~9 ~123 red_wool
fill ~147 ~9 ~117 ~162 ~15 ~117 quartz_block
fill ~147 ~9 ~124 ~162 ~15 ~124 quartz_block
fill ~162 ~9 ~117 ~162 ~15 ~124 quartz_block
fill ~148 ~10 ~118 ~161 ~15 ~123 air
fill ~153 ~9 ~121 ~155 ~9 ~122 white_wool
fill ~153 ~9 ~123 ~155 ~10 ~123 gold_block
fill ~153 ~9 ~122 ~155 ~9 ~122 red_wool
setblock ~152 ~9 ~122 dark_oak_planks
setblock ~156 ~9 ~122 dark_oak_planks
setblock ~152 ~10 ~122 sea_lantern
setblock ~156 ~10 ~122 sea_lantern
fill ~160 ~9 ~119 ~160 ~9 ~121 dark_oak_planks
setblock ~149 ~9 ~119 spruce_planks
fill ~149 ~10 ~117 ~150 ~11 ~117 air
fill ~149 ~12 ~117 ~150 ~12 ~117 gold_block
setblock ~154 ~15 ~120 glowstone
fill ~164 ~9 ~118 ~177 ~9 ~123 lime_wool
fill ~163 ~9 ~117 ~178 ~15 ~117 quartz_block
fill ~163 ~9 ~124 ~178 ~15 ~124 quartz_block
fill ~178 ~9 ~117 ~178 ~15 ~124 quartz_block
fill ~164 ~10 ~118 ~177 ~15 ~123 air
fill ~169 ~9 ~121 ~171 ~9 ~122 white_wool
fill ~169 ~9 ~123 ~171 ~10 ~123 gold_block
fill ~169 ~9 ~122 ~171 ~9 ~122 red_wool
setblock ~168 ~9 ~122 dark_oak_planks
setblock ~172 ~9 ~122 dark_oak_planks
setblock ~168 ~10 ~122 sea_lantern
setblock ~172 ~10 ~122 sea_lantern
fill ~176 ~9 ~119 ~176 ~9 ~121 dark_oak_planks
setblock ~165 ~9 ~119 spruce_planks
fill ~165 ~10 ~117 ~166 ~11 ~117 air
fill ~165 ~12 ~117 ~166 ~12 ~117 gold_block
setblock ~170 ~15 ~120 glowstone
fill ~148 ~9 ~127 ~161 ~9 ~132 blue_wool
fill ~147 ~9 ~126 ~162 ~15 ~126 quartz_block
fill ~147 ~9 ~133 ~162 ~15 ~133 quartz_block
fill ~162 ~9 ~126 ~162 ~15 ~133 quartz_block
fill ~148 ~10 ~127 ~161 ~15 ~132 air
fill ~153 ~9 ~130 ~155 ~9 ~131 white_wool
fill ~153 ~9 ~132 ~155 ~10 ~132 gold_block
fill ~153 ~9 ~131 ~155 ~9 ~131 red_wool
setblock ~152 ~9 ~131 dark_oak_planks
setblock ~156 ~9 ~131 dark_oak_planks
setblock ~152 ~10 ~131 sea_lantern
setblock ~156 ~10 ~131 sea_lantern
fill ~160 ~9 ~128 ~160 ~9 ~130 dark_oak_planks
setblock ~149 ~9 ~128 spruce_planks
fill ~149 ~10 ~126 ~150 ~11 ~126 air
fill ~149 ~12 ~126 ~150 ~12 ~126 gold_block
setblock ~154 ~15 ~129 glowstone
fill ~164 ~9 ~127 ~177 ~9 ~132 yellow_wool
fill ~163 ~9 ~126 ~178 ~15 ~126 quartz_block
fill ~163 ~9 ~133 ~178 ~15 ~133 quartz_block
fill ~178 ~9 ~126 ~178 ~15 ~133 quartz_block
fill ~164 ~10 ~127 ~177 ~15 ~132 air
fill ~169 ~9 ~130 ~171 ~9 ~131 white_wool
fill ~169 ~9 ~132 ~171 ~10 ~132 gold_block
fill ~169 ~9 ~131 ~171 ~9 ~131 red_wool
setblock ~168 ~9 ~131 dark_oak_planks
setblock ~172 ~9 ~131 dark_oak_planks
setblock ~168 ~10 ~131 sea_lantern
setblock ~172 ~10 ~131 sea_lantern
fill ~176 ~9 ~128 ~176 ~9 ~130 dark_oak_planks
setblock ~165 ~9 ~128 spruce_planks
fill ~165 ~10 ~126 ~166 ~11 ~126 air
fill ~165 ~12 ~126 ~166 ~12 ~126 gold_block
setblock ~170 ~15 ~129 glowstone
fill ~148 ~9 ~136 ~161 ~9 ~141 cyan_wool
fill ~147 ~9 ~135 ~162 ~15 ~135 quartz_block
fill ~147 ~9 ~142 ~162 ~15 ~142 quartz_block
fill ~162 ~9 ~135 ~162 ~15 ~142 quartz_block
fill ~148 ~10 ~136 ~161 ~15 ~141 air
fill ~153 ~9 ~139 ~155 ~9 ~140 white_wool
fill ~153 ~9 ~141 ~155 ~10 ~141 gold_block
fill ~153 ~9 ~140 ~155 ~9 ~140 red_wool
setblock ~152 ~9 ~140 dark_oak_planks
setblock ~156 ~9 ~140 dark_oak_planks
setblock ~152 ~10 ~140 sea_lantern
setblock ~156 ~10 ~140 sea_lantern
fill ~160 ~9 ~137 ~160 ~9 ~139 dark_oak_planks
setblock ~149 ~9 ~137 spruce_planks
fill ~149 ~10 ~135 ~150 ~11 ~135 air
fill ~149 ~12 ~135 ~150 ~12 ~135 gold_block
setblock ~154 ~15 ~138 glowstone
fill ~164 ~9 ~136 ~177 ~9 ~141 purple_wool
fill ~163 ~9 ~135 ~178 ~15 ~135 quartz_block
fill ~163 ~9 ~142 ~178 ~15 ~142 quartz_block
fill ~178 ~9 ~135 ~178 ~15 ~142 quartz_block
fill ~164 ~10 ~136 ~177 ~15 ~141 air
fill ~169 ~9 ~139 ~171 ~9 ~140 white_wool
fill ~169 ~9 ~141 ~171 ~10 ~141 gold_block
fill ~169 ~9 ~140 ~171 ~9 ~140 red_wool
setblock ~168 ~9 ~140 dark_oak_planks
setblock ~172 ~9 ~140 dark_oak_planks
setblock ~168 ~10 ~140 sea_lantern
setblock ~172 ~10 ~140 sea_lantern
fill ~176 ~9 ~137 ~176 ~9 ~139 dark_oak_planks
setblock ~165 ~9 ~137 spruce_planks
fill ~165 ~10 ~135 ~166 ~11 ~135 air
fill ~165 ~12 ~135 ~166 ~12 ~135 gold_block
setblock ~170 ~15 ~138 glowstone
fill ~148 ~9 ~145 ~161 ~9 ~150 pink_wool
fill ~147 ~9 ~144 ~162 ~15 ~144 quartz_block
fill ~147 ~9 ~151 ~162 ~15 ~151 quartz_block
fill ~162 ~9 ~144 ~162 ~15 ~151 quartz_block
fill ~148 ~10 ~145 ~161 ~15 ~150 air
fill ~153 ~9 ~148 ~155 ~9 ~149 white_wool
fill ~153 ~9 ~150 ~155 ~10 ~150 gold_block
fill ~153 ~9 ~149 ~155 ~9 ~149 red_wool
setblock ~152 ~9 ~149 dark_oak_planks
setblock ~156 ~9 ~149 dark_oak_planks
setblock ~152 ~10 ~149 sea_lantern
setblock ~156 ~10 ~149 sea_lantern
fill ~160 ~9 ~146 ~160 ~9 ~148 dark_oak_planks
setblock ~149 ~9 ~146 spruce_planks
fill ~149 ~10 ~144 ~150 ~11 ~144 air
fill ~149 ~12 ~144 ~150 ~12 ~144 gold_block
setblock ~154 ~15 ~147 glowstone
fill ~164 ~9 ~145 ~177 ~9 ~150 magenta_wool
fill ~163 ~9 ~144 ~178 ~15 ~144 quartz_block
fill ~163 ~9 ~151 ~178 ~15 ~151 quartz_block
fill ~178 ~9 ~144 ~178 ~15 ~151 quartz_block
fill ~164 ~10 ~145 ~177 ~15 ~150 air
fill ~169 ~9 ~148 ~171 ~9 ~149 white_wool
fill ~169 ~9 ~150 ~171 ~10 ~150 gold_block
fill ~169 ~9 ~149 ~171 ~9 ~149 red_wool
setblock ~168 ~9 ~149 dark_oak_planks
setblock ~172 ~9 ~149 dark_oak_planks
setblock ~168 ~10 ~149 sea_lantern
setblock ~172 ~10 ~149 sea_lantern
fill ~176 ~9 ~146 ~176 ~9 ~148 dark_oak_planks
setblock ~165 ~9 ~146 spruce_planks
fill ~165 ~10 ~144 ~166 ~11 ~144 air
fill ~165 ~12 ~144 ~166 ~12 ~144 gold_block
setblock ~170 ~15 ~147 glowstone
fill ~145 ~16 ~105 ~175 ~16 ~135 quartz_block
fill ~145 ~16 ~136 ~175 ~16 ~155 quartz_block
fill ~176 ~16 ~105 ~180 ~16 ~135 quartz_block
fill ~176 ~16 ~136 ~180 ~16 ~155 quartz_block
fill ~160 ~1 ~105 ~164 ~4 ~105 air
fill ~160 ~5 ~105 ~164 ~5 ~105 gold_block
function bezos_gardens
