# Phase 11b: East guest house
# --- East Guest House (10 bedrooms) ---
fill ~145 ~-1 ~105 ~175 ~-1 ~135 quartz_block
fill ~145 ~-1 ~136 ~175 ~-1 ~155 quartz_block
fill ~176 ~-1 ~105 ~180 ~-1 ~135 quartz_block
fill ~176 ~-1 ~136 ~180 ~-1 ~155 quartz_block
fill ~145 ~0 ~105 ~175 ~0 ~135 dark_oak_planks
fill ~145 ~0 ~136 ~175 ~0 ~155 dark_oak_planks
fill ~176 ~0 ~105 ~180 ~0 ~135 dark_oak_planks
fill ~176 ~0 ~136 ~180 ~0 ~155 dark_oak_planks
fill ~145 ~1 ~105 ~175 ~8 ~135 quartz_block
fill ~145 ~1 ~136 ~175 ~8 ~155 quartz_block
fill ~176 ~1 ~105 ~180 ~8 ~135 quartz_block
fill ~176 ~1 ~136 ~180 ~8 ~155 quartz_block
fill ~147 ~1 ~107 ~177 ~7 ~137 air
fill ~147 ~1 ~138 ~177 ~7 ~153 air
fill ~178 ~1 ~107 ~178 ~7 ~137 air
fill ~178 ~1 ~138 ~178 ~7 ~153 air
fill ~145 ~1 ~105 ~175 ~1 ~105 gold_block
fill ~176 ~1 ~105 ~180 ~1 ~105 gold_block
fill ~145 ~1 ~155 ~175 ~1 ~155 gold_block
fill ~176 ~1 ~155 ~180 ~1 ~155 gold_block
fill ~145 ~2 ~109 ~145 ~6 ~113 glass
fill ~180 ~2 ~109 ~180 ~6 ~113 glass
fill ~145 ~2 ~117 ~145 ~6 ~121 glass
fill ~180 ~2 ~117 ~180 ~6 ~121 glass
fill ~145 ~2 ~125 ~145 ~6 ~129 glass
fill ~180 ~2 ~125 ~180 ~6 ~129 glass
fill ~145 ~2 ~133 ~145 ~6 ~137 glass
fill ~180 ~2 ~133 ~180 ~6 ~137 glass
fill ~145 ~2 ~141 ~145 ~6 ~145 glass
fill ~180 ~2 ~141 ~180 ~6 ~145 glass
fill ~145 ~2 ~149 ~145 ~6 ~153 glass
fill ~180 ~2 ~149 ~180 ~6 ~153 glass
fill ~147 ~0 ~108 ~162 ~8 ~115 quartz_block
fill ~148 ~1 ~109 ~161 ~7 ~114 air
fill ~148 ~0 ~109 ~161 ~0 ~114 white_wool
fill ~153 ~1 ~112 ~155 ~1 ~113 white_wool
fill ~153 ~1 ~114 ~155 ~2 ~114 gold_block
fill ~153 ~1 ~113 ~155 ~1 ~113 red_wool
setblock ~152 ~1 ~113 dark_oak_planks
setblock ~156 ~1 ~113 dark_oak_planks
setblock ~152 ~2 ~113 sea_lantern
setblock ~156 ~2 ~113 sea_lantern
fill ~160 ~1 ~110 ~160 ~1 ~112 dark_oak_planks
setblock ~149 ~1 ~110 spruce_planks
fill ~152 ~0 ~111 ~156 ~0 ~112 white_wool
fill ~150 ~2 ~108 ~159 ~5 ~108 glass
setblock ~154 ~7 ~111 glowstone
fill ~147 ~1 ~111 ~147 ~3 ~112 air
fill ~147 ~4 ~111 ~147 ~4 ~112 gold_block
fill ~163 ~0 ~108 ~178 ~8 ~115 quartz_block
fill ~164 ~1 ~109 ~177 ~7 ~114 air
fill ~164 ~0 ~109 ~177 ~0 ~114 orange_wool
fill ~169 ~1 ~112 ~171 ~1 ~113 white_wool
fill ~169 ~1 ~114 ~171 ~2 ~114 gold_block
fill ~169 ~1 ~113 ~171 ~1 ~113 red_wool
setblock ~168 ~1 ~113 dark_oak_planks
setblock ~172 ~1 ~113 dark_oak_planks
setblock ~168 ~2 ~113 sea_lantern
setblock ~172 ~2 ~113 sea_lantern
fill ~176 ~1 ~110 ~176 ~1 ~112 dark_oak_planks
setblock ~165 ~1 ~110 spruce_planks
fill ~168 ~0 ~111 ~172 ~0 ~112 orange_wool
fill ~166 ~2 ~108 ~175 ~5 ~108 glass
setblock ~170 ~7 ~111 glowstone
fill ~163 ~1 ~111 ~163 ~3 ~112 air
fill ~163 ~4 ~111 ~163 ~4 ~112 gold_block
fill ~147 ~0 ~117 ~162 ~8 ~124 quartz_block
fill ~148 ~1 ~118 ~161 ~7 ~123 air
fill ~148 ~0 ~118 ~161 ~0 ~123 red_wool
fill ~153 ~1 ~121 ~155 ~1 ~122 white_wool
fill ~153 ~1 ~123 ~155 ~2 ~123 gold_block
fill ~153 ~1 ~122 ~155 ~1 ~122 red_wool
setblock ~152 ~1 ~122 dark_oak_planks
setblock ~156 ~1 ~122 dark_oak_planks
setblock ~152 ~2 ~122 sea_lantern
setblock ~156 ~2 ~122 sea_lantern
fill ~160 ~1 ~119 ~160 ~1 ~121 dark_oak_planks
setblock ~149 ~1 ~119 spruce_planks
fill ~152 ~0 ~120 ~156 ~0 ~121 red_wool
fill ~150 ~2 ~117 ~159 ~5 ~117 glass
setblock ~154 ~7 ~120 glowstone
fill ~147 ~1 ~120 ~147 ~3 ~121 air
fill ~147 ~4 ~120 ~147 ~4 ~121 gold_block
fill ~163 ~0 ~117 ~178 ~8 ~124 quartz_block
fill ~164 ~1 ~118 ~177 ~7 ~123 air
fill ~164 ~0 ~118 ~177 ~0 ~123 lime_wool
fill ~169 ~1 ~121 ~171 ~1 ~122 white_wool
fill ~169 ~1 ~123 ~171 ~2 ~123 gold_block
fill ~169 ~1 ~122 ~171 ~1 ~122 red_wool
setblock ~168 ~1 ~122 dark_oak_planks
setblock ~172 ~1 ~122 dark_oak_planks
setblock ~168 ~2 ~122 sea_lantern
setblock ~172 ~2 ~122 sea_lantern
fill ~176 ~1 ~119 ~176 ~1 ~121 dark_oak_planks
setblock ~165 ~1 ~119 spruce_planks
fill ~168 ~0 ~120 ~172 ~0 ~121 lime_wool
fill ~166 ~2 ~117 ~175 ~5 ~117 glass
setblock ~170 ~7 ~120 glowstone
fill ~163 ~1 ~120 ~163 ~3 ~121 air
fill ~163 ~4 ~120 ~163 ~4 ~121 gold_block
fill ~147 ~0 ~126 ~162 ~8 ~133 quartz_block
fill ~148 ~1 ~127 ~161 ~7 ~132 air
fill ~148 ~0 ~127 ~161 ~0 ~132 blue_wool
fill ~153 ~1 ~130 ~155 ~1 ~131 white_wool
fill ~153 ~1 ~132 ~155 ~2 ~132 gold_block
fill ~153 ~1 ~131 ~155 ~1 ~131 red_wool
setblock ~152 ~1 ~131 dark_oak_planks
setblock ~156 ~1 ~131 dark_oak_planks
setblock ~152 ~2 ~131 sea_lantern
setblock ~156 ~2 ~131 sea_lantern
fill ~160 ~1 ~128 ~160 ~1 ~130 dark_oak_planks
setblock ~149 ~1 ~128 spruce_planks
fill ~152 ~0 ~129 ~156 ~0 ~130 blue_wool
fill ~150 ~2 ~126 ~159 ~5 ~126 glass
setblock ~154 ~7 ~129 glowstone
fill ~147 ~1 ~129 ~147 ~3 ~130 air
fill ~147 ~4 ~129 ~147 ~4 ~130 gold_block
fill ~163 ~0 ~126 ~178 ~8 ~133 quartz_block
fill ~164 ~1 ~127 ~177 ~7 ~132 air
fill ~164 ~0 ~127 ~177 ~0 ~132 yellow_wool
fill ~169 ~1 ~130 ~171 ~1 ~131 white_wool
fill ~169 ~1 ~132 ~171 ~2 ~132 gold_block
fill ~169 ~1 ~131 ~171 ~1 ~131 red_wool
setblock ~168 ~1 ~131 dark_oak_planks
setblock ~172 ~1 ~131 dark_oak_planks
setblock ~168 ~2 ~131 sea_lantern
setblock ~172 ~2 ~131 sea_lantern
fill ~176 ~1 ~128 ~176 ~1 ~130 dark_oak_planks
setblock ~165 ~1 ~128 spruce_planks
fill ~168 ~0 ~129 ~172 ~0 ~130 yellow_wool
fill ~166 ~2 ~126 ~175 ~5 ~126 glass
setblock ~170 ~7 ~129 glowstone
fill ~163 ~1 ~129 ~163 ~3 ~130 air
fill ~163 ~4 ~129 ~163 ~4 ~130 gold_block
fill ~147 ~0 ~135 ~162 ~8 ~142 quartz_block
fill ~148 ~1 ~136 ~161 ~7 ~141 air
fill ~148 ~0 ~136 ~161 ~0 ~141 cyan_wool
fill ~153 ~1 ~139 ~155 ~1 ~140 white_wool
fill ~153 ~1 ~141 ~155 ~2 ~141 gold_block
fill ~153 ~1 ~140 ~155 ~1 ~140 red_wool
setblock ~152 ~1 ~140 dark_oak_planks
setblock ~156 ~1 ~140 dark_oak_planks
setblock ~152 ~2 ~140 sea_lantern
setblock ~156 ~2 ~140 sea_lantern
fill ~160 ~1 ~137 ~160 ~1 ~139 dark_oak_planks
setblock ~149 ~1 ~137 spruce_planks
fill ~152 ~0 ~138 ~156 ~0 ~139 cyan_wool
fill ~150 ~2 ~135 ~159 ~5 ~135 glass
setblock ~154 ~7 ~138 glowstone
fill ~147 ~1 ~138 ~147 ~3 ~139 air
fill ~147 ~4 ~138 ~147 ~4 ~139 gold_block
fill ~163 ~0 ~135 ~178 ~8 ~142 quartz_block
fill ~164 ~1 ~136 ~177 ~7 ~141 air
fill ~164 ~0 ~136 ~177 ~0 ~141 purple_wool
fill ~169 ~1 ~139 ~171 ~1 ~140 white_wool
fill ~169 ~1 ~141 ~171 ~2 ~141 gold_block
fill ~169 ~1 ~140 ~171 ~1 ~140 red_wool
setblock ~168 ~1 ~140 dark_oak_planks
setblock ~172 ~1 ~140 dark_oak_planks
setblock ~168 ~2 ~140 sea_lantern
setblock ~172 ~2 ~140 sea_lantern
fill ~176 ~1 ~137 ~176 ~1 ~139 dark_oak_planks
setblock ~165 ~1 ~137 spruce_planks
fill ~168 ~0 ~138 ~172 ~0 ~139 purple_wool
fill ~166 ~2 ~135 ~175 ~5 ~135 glass
setblock ~170 ~7 ~138 glowstone
fill ~163 ~1 ~138 ~163 ~3 ~139 air
fill ~163 ~4 ~138 ~163 ~4 ~139 gold_block
fill ~147 ~0 ~144 ~162 ~8 ~151 quartz_block
fill ~148 ~1 ~145 ~161 ~7 ~150 air
fill ~148 ~0 ~145 ~161 ~0 ~150 pink_wool
fill ~153 ~1 ~148 ~155 ~1 ~149 white_wool
fill ~153 ~1 ~150 ~155 ~2 ~150 gold_block
fill ~153 ~1 ~149 ~155 ~1 ~149 red_wool
setblock ~152 ~1 ~149 dark_oak_planks
setblock ~156 ~1 ~149 dark_oak_planks
setblock ~152 ~2 ~149 sea_lantern
setblock ~156 ~2 ~149 sea_lantern
fill ~160 ~1 ~146 ~160 ~1 ~148 dark_oak_planks
setblock ~149 ~1 ~146 spruce_planks
fill ~152 ~0 ~147 ~156 ~0 ~148 pink_wool
fill ~150 ~2 ~144 ~159 ~5 ~144 glass
setblock ~154 ~7 ~147 glowstone
fill ~147 ~1 ~147 ~147 ~3 ~148 air
fill ~147 ~4 ~147 ~147 ~4 ~148 gold_block
fill ~163 ~0 ~144 ~178 ~8 ~151 quartz_block
fill ~164 ~1 ~145 ~177 ~7 ~150 air
fill ~164 ~0 ~145 ~177 ~0 ~150 magenta_wool
fill ~169 ~1 ~148 ~171 ~1 ~149 white_wool
fill ~169 ~1 ~150 ~171 ~2 ~150 gold_block
fill ~169 ~1 ~149 ~171 ~1 ~149 red_wool
setblock ~168 ~1 ~149 dark_oak_planks
setblock ~172 ~1 ~149 dark_oak_planks
setblock ~168 ~2 ~149 sea_lantern
setblock ~172 ~2 ~149 sea_lantern
fill ~176 ~1 ~146 ~176 ~1 ~148 dark_oak_planks
setblock ~165 ~1 ~146 spruce_planks
fill ~168 ~0 ~147 ~172 ~0 ~148 magenta_wool
fill ~166 ~2 ~144 ~175 ~5 ~144 glass
setblock ~170 ~7 ~147 glowstone
fill ~163 ~1 ~147 ~163 ~3 ~148 air
fill ~163 ~4 ~147 ~163 ~4 ~148 gold_block
fill ~145 ~8 ~105 ~175 ~8 ~135 dark_oak_planks
fill ~145 ~8 ~136 ~175 ~8 ~155 dark_oak_planks
fill ~176 ~8 ~105 ~180 ~8 ~135 dark_oak_planks
fill ~176 ~8 ~136 ~180 ~8 ~155 dark_oak_planks
fill ~145 ~9 ~105 ~175 ~16 ~135 quartz_block
fill ~145 ~9 ~136 ~175 ~16 ~155 quartz_block
fill ~176 ~9 ~105 ~180 ~16 ~135 quartz_block
fill ~176 ~9 ~136 ~180 ~16 ~155 quartz_block
fill ~147 ~9 ~107 ~177 ~15 ~137 air
fill ~147 ~9 ~138 ~177 ~15 ~153 air
fill ~178 ~9 ~107 ~178 ~15 ~137 air
fill ~178 ~9 ~138 ~178 ~15 ~153 air
fill ~145 ~9 ~105 ~175 ~9 ~105 gold_block
fill ~176 ~9 ~105 ~180 ~9 ~105 gold_block
fill ~145 ~9 ~155 ~175 ~9 ~155 gold_block
fill ~176 ~9 ~155 ~180 ~9 ~155 gold_block
fill ~145 ~10 ~109 ~145 ~14 ~113 glass
fill ~180 ~10 ~109 ~180 ~14 ~113 glass
fill ~145 ~10 ~117 ~145 ~14 ~121 glass
fill ~180 ~10 ~117 ~180 ~14 ~121 glass
fill ~145 ~10 ~125 ~145 ~14 ~129 glass
fill ~180 ~10 ~125 ~180 ~14 ~129 glass
fill ~145 ~10 ~133 ~145 ~14 ~137 glass
fill ~180 ~10 ~133 ~180 ~14 ~137 glass
fill ~145 ~10 ~141 ~145 ~14 ~145 glass
fill ~180 ~10 ~141 ~180 ~14 ~145 glass
fill ~145 ~10 ~149 ~145 ~14 ~153 glass
fill ~180 ~10 ~149 ~180 ~14 ~153 glass
fill ~147 ~8 ~108 ~162 ~16 ~115 quartz_block
fill ~148 ~9 ~109 ~161 ~15 ~114 air
fill ~148 ~8 ~109 ~161 ~8 ~114 white_wool
fill ~153 ~9 ~112 ~155 ~9 ~113 white_wool
fill ~153 ~9 ~114 ~155 ~10 ~114 gold_block
fill ~153 ~9 ~113 ~155 ~9 ~113 red_wool
setblock ~152 ~9 ~113 dark_oak_planks
setblock ~156 ~9 ~113 dark_oak_planks
setblock ~152 ~10 ~113 sea_lantern
setblock ~156 ~10 ~113 sea_lantern
fill ~160 ~9 ~110 ~160 ~9 ~112 dark_oak_planks
setblock ~149 ~9 ~110 spruce_planks
fill ~152 ~8 ~111 ~156 ~8 ~112 white_wool
fill ~150 ~10 ~108 ~159 ~13 ~108 glass
setblock ~154 ~15 ~111 glowstone
fill ~147 ~9 ~111 ~147 ~11 ~112 air
fill ~147 ~12 ~111 ~147 ~12 ~112 gold_block
fill ~163 ~8 ~108 ~178 ~16 ~115 quartz_block
fill ~164 ~9 ~109 ~177 ~15 ~114 air
fill ~164 ~8 ~109 ~177 ~8 ~114 orange_wool
fill ~169 ~9 ~112 ~171 ~9 ~113 white_wool
fill ~169 ~9 ~114 ~171 ~10 ~114 gold_block
fill ~169 ~9 ~113 ~171 ~9 ~113 red_wool
setblock ~168 ~9 ~113 dark_oak_planks
setblock ~172 ~9 ~113 dark_oak_planks
setblock ~168 ~10 ~113 sea_lantern
setblock ~172 ~10 ~113 sea_lantern
fill ~176 ~9 ~110 ~176 ~9 ~112 dark_oak_planks
setblock ~165 ~9 ~110 spruce_planks
fill ~168 ~8 ~111 ~172 ~8 ~112 orange_wool
fill ~166 ~10 ~108 ~175 ~13 ~108 glass
setblock ~170 ~15 ~111 glowstone
fill ~163 ~9 ~111 ~163 ~11 ~112 air
fill ~163 ~12 ~111 ~163 ~12 ~112 gold_block
fill ~147 ~8 ~117 ~162 ~16 ~124 quartz_block
fill ~148 ~9 ~118 ~161 ~15 ~123 air
fill ~148 ~8 ~118 ~161 ~8 ~123 red_wool
fill ~153 ~9 ~121 ~155 ~9 ~122 white_wool
fill ~153 ~9 ~123 ~155 ~10 ~123 gold_block
fill ~153 ~9 ~122 ~155 ~9 ~122 red_wool
setblock ~152 ~9 ~122 dark_oak_planks
setblock ~156 ~9 ~122 dark_oak_planks
setblock ~152 ~10 ~122 sea_lantern
setblock ~156 ~10 ~122 sea_lantern
fill ~160 ~9 ~119 ~160 ~9 ~121 dark_oak_planks
setblock ~149 ~9 ~119 spruce_planks
fill ~152 ~8 ~120 ~156 ~8 ~121 red_wool
fill ~150 ~10 ~117 ~159 ~13 ~117 glass
setblock ~154 ~15 ~120 glowstone
fill ~147 ~9 ~120 ~147 ~11 ~121 air
fill ~147 ~12 ~120 ~147 ~12 ~121 gold_block
fill ~163 ~8 ~117 ~178 ~16 ~124 quartz_block
fill ~164 ~9 ~118 ~177 ~15 ~123 air
fill ~164 ~8 ~118 ~177 ~8 ~123 lime_wool
fill ~169 ~9 ~121 ~171 ~9 ~122 white_wool
fill ~169 ~9 ~123 ~171 ~10 ~123 gold_block
fill ~169 ~9 ~122 ~171 ~9 ~122 red_wool
setblock ~168 ~9 ~122 dark_oak_planks
setblock ~172 ~9 ~122 dark_oak_planks
setblock ~168 ~10 ~122 sea_lantern
setblock ~172 ~10 ~122 sea_lantern
fill ~176 ~9 ~119 ~176 ~9 ~121 dark_oak_planks
setblock ~165 ~9 ~119 spruce_planks
fill ~168 ~8 ~120 ~172 ~8 ~121 lime_wool
fill ~166 ~10 ~117 ~175 ~13 ~117 glass
setblock ~170 ~15 ~120 glowstone
fill ~163 ~9 ~120 ~163 ~11 ~121 air
fill ~163 ~12 ~120 ~163 ~12 ~121 gold_block
fill ~147 ~8 ~126 ~162 ~16 ~133 quartz_block
fill ~148 ~9 ~127 ~161 ~15 ~132 air
fill ~148 ~8 ~127 ~161 ~8 ~132 blue_wool
fill ~153 ~9 ~130 ~155 ~9 ~131 white_wool
fill ~153 ~9 ~132 ~155 ~10 ~132 gold_block
fill ~153 ~9 ~131 ~155 ~9 ~131 red_wool
setblock ~152 ~9 ~131 dark_oak_planks
setblock ~156 ~9 ~131 dark_oak_planks
setblock ~152 ~10 ~131 sea_lantern
setblock ~156 ~10 ~131 sea_lantern
fill ~160 ~9 ~128 ~160 ~9 ~130 dark_oak_planks
setblock ~149 ~9 ~128 spruce_planks
fill ~152 ~8 ~129 ~156 ~8 ~130 blue_wool
fill ~150 ~10 ~126 ~159 ~13 ~126 glass
setblock ~154 ~15 ~129 glowstone
fill ~147 ~9 ~129 ~147 ~11 ~130 air
fill ~147 ~12 ~129 ~147 ~12 ~130 gold_block
fill ~163 ~8 ~126 ~178 ~16 ~133 quartz_block
fill ~164 ~9 ~127 ~177 ~15 ~132 air
fill ~164 ~8 ~127 ~177 ~8 ~132 yellow_wool
fill ~169 ~9 ~130 ~171 ~9 ~131 white_wool
fill ~169 ~9 ~132 ~171 ~10 ~132 gold_block
fill ~169 ~9 ~131 ~171 ~9 ~131 red_wool
setblock ~168 ~9 ~131 dark_oak_planks
setblock ~172 ~9 ~131 dark_oak_planks
setblock ~168 ~10 ~131 sea_lantern
setblock ~172 ~10 ~131 sea_lantern
fill ~176 ~9 ~128 ~176 ~9 ~130 dark_oak_planks
setblock ~165 ~9 ~128 spruce_planks
fill ~168 ~8 ~129 ~172 ~8 ~130 yellow_wool
fill ~166 ~10 ~126 ~175 ~13 ~126 glass
setblock ~170 ~15 ~129 glowstone
fill ~163 ~9 ~129 ~163 ~11 ~130 air
fill ~163 ~12 ~129 ~163 ~12 ~130 gold_block
fill ~147 ~8 ~135 ~162 ~16 ~142 quartz_block
fill ~148 ~9 ~136 ~161 ~15 ~141 air
fill ~148 ~8 ~136 ~161 ~8 ~141 cyan_wool
fill ~153 ~9 ~139 ~155 ~9 ~140 white_wool
fill ~153 ~9 ~141 ~155 ~10 ~141 gold_block
fill ~153 ~9 ~140 ~155 ~9 ~140 red_wool
setblock ~152 ~9 ~140 dark_oak_planks
setblock ~156 ~9 ~140 dark_oak_planks
setblock ~152 ~10 ~140 sea_lantern
setblock ~156 ~10 ~140 sea_lantern
fill ~160 ~9 ~137 ~160 ~9 ~139 dark_oak_planks
setblock ~149 ~9 ~137 spruce_planks
fill ~152 ~8 ~138 ~156 ~8 ~139 cyan_wool
fill ~150 ~10 ~135 ~159 ~13 ~135 glass
setblock ~154 ~15 ~138 glowstone
fill ~147 ~9 ~138 ~147 ~11 ~139 air
fill ~147 ~12 ~138 ~147 ~12 ~139 gold_block
fill ~163 ~8 ~135 ~178 ~16 ~142 quartz_block
fill ~164 ~9 ~136 ~177 ~15 ~141 air
fill ~164 ~8 ~136 ~177 ~8 ~141 purple_wool
fill ~169 ~9 ~139 ~171 ~9 ~140 white_wool
fill ~169 ~9 ~141 ~171 ~10 ~141 gold_block
fill ~169 ~9 ~140 ~171 ~9 ~140 red_wool
setblock ~168 ~9 ~140 dark_oak_planks
setblock ~172 ~9 ~140 dark_oak_planks
setblock ~168 ~10 ~140 sea_lantern
setblock ~172 ~10 ~140 sea_lantern
fill ~176 ~9 ~137 ~176 ~9 ~139 dark_oak_planks
setblock ~165 ~9 ~137 spruce_planks
fill ~168 ~8 ~138 ~172 ~8 ~139 purple_wool
fill ~166 ~10 ~135 ~175 ~13 ~135 glass
setblock ~170 ~15 ~138 glowstone
fill ~163 ~9 ~138 ~163 ~11 ~139 air
fill ~163 ~12 ~138 ~163 ~12 ~139 gold_block
fill ~147 ~8 ~144 ~162 ~16 ~151 quartz_block
fill ~148 ~9 ~145 ~161 ~15 ~150 air
fill ~148 ~8 ~145 ~161 ~8 ~150 pink_wool
fill ~153 ~9 ~148 ~155 ~9 ~149 white_wool
fill ~153 ~9 ~150 ~155 ~10 ~150 gold_block
fill ~153 ~9 ~149 ~155 ~9 ~149 red_wool
setblock ~152 ~9 ~149 dark_oak_planks
setblock ~156 ~9 ~149 dark_oak_planks
setblock ~152 ~10 ~149 sea_lantern
setblock ~156 ~10 ~149 sea_lantern
fill ~160 ~9 ~146 ~160 ~9 ~148 dark_oak_planks
setblock ~149 ~9 ~146 spruce_planks
fill ~152 ~8 ~147 ~156 ~8 ~148 pink_wool
fill ~150 ~10 ~144 ~159 ~13 ~144 glass
setblock ~154 ~15 ~147 glowstone
fill ~147 ~9 ~147 ~147 ~11 ~148 air
fill ~147 ~12 ~147 ~147 ~12 ~148 gold_block
fill ~163 ~8 ~144 ~178 ~16 ~151 quartz_block
fill ~164 ~9 ~145 ~177 ~15 ~150 air
fill ~164 ~8 ~145 ~177 ~8 ~150 magenta_wool
fill ~169 ~9 ~148 ~171 ~9 ~149 white_wool
fill ~169 ~9 ~150 ~171 ~10 ~150 gold_block
fill ~169 ~9 ~149 ~171 ~9 ~149 red_wool
setblock ~168 ~9 ~149 dark_oak_planks
setblock ~172 ~9 ~149 dark_oak_planks
setblock ~168 ~10 ~149 sea_lantern
setblock ~172 ~10 ~149 sea_lantern
fill ~176 ~9 ~146 ~176 ~9 ~148 dark_oak_planks
setblock ~165 ~9 ~146 spruce_planks
fill ~168 ~8 ~147 ~172 ~8 ~148 magenta_wool
fill ~166 ~10 ~144 ~175 ~13 ~144 glass
setblock ~170 ~15 ~147 glowstone
fill ~163 ~9 ~147 ~163 ~11 ~148 air
fill ~163 ~12 ~147 ~163 ~12 ~148 gold_block
fill ~145 ~16 ~105 ~175 ~16 ~135 quartz_block
fill ~145 ~16 ~136 ~175 ~16 ~155 quartz_block
fill ~176 ~16 ~105 ~180 ~16 ~135 quartz_block
fill ~176 ~16 ~136 ~180 ~16 ~155 quartz_block
fill ~160 ~1 ~105 ~164 ~4 ~105 air
fill ~160 ~5 ~105 ~164 ~5 ~105 gold_block
function bezos_gardens
