# Phase 11a: West guest house
# --- West Guest House (10 bedrooms) ---
fill ~-40 ~-1 ~105 ~-10 ~-1 ~135 quartz_block
fill ~-40 ~-1 ~136 ~-10 ~-1 ~155 quartz_block
fill ~-9 ~-1 ~105 ~-5 ~-1 ~135 quartz_block
fill ~-9 ~-1 ~136 ~-5 ~-1 ~155 quartz_block
fill ~-40 ~0 ~105 ~-10 ~0 ~135 dark_oak_planks
fill ~-40 ~0 ~136 ~-10 ~0 ~155 dark_oak_planks
fill ~-9 ~0 ~105 ~-5 ~0 ~135 dark_oak_planks
fill ~-9 ~0 ~136 ~-5 ~0 ~155 dark_oak_planks
fill ~-40 ~1 ~105 ~-10 ~8 ~135 quartz_block
fill ~-40 ~1 ~136 ~-10 ~8 ~155 quartz_block
fill ~-9 ~1 ~105 ~-5 ~8 ~135 quartz_block
fill ~-9 ~1 ~136 ~-5 ~8 ~155 quartz_block
fill ~-38 ~1 ~107 ~-8 ~7 ~137 air
fill ~-38 ~1 ~138 ~-8 ~7 ~153 air
fill ~-7 ~1 ~107 ~-7 ~7 ~137 air
fill ~-7 ~1 ~138 ~-7 ~7 ~153 air
fill ~-40 ~1 ~105 ~-10 ~1 ~105 gold_block
fill ~-9 ~1 ~105 ~-5 ~1 ~105 gold_block
fill ~-40 ~1 ~155 ~-10 ~1 ~155 gold_block
fill ~-9 ~1 ~155 ~-5 ~1 ~155 gold_block
fill ~-40 ~2 ~109 ~-40 ~6 ~113 glass
fill ~-5 ~2 ~109 ~-5 ~6 ~113 glass
fill ~-40 ~2 ~117 ~-40 ~6 ~121 glass
fill ~-5 ~2 ~117 ~-5 ~6 ~121 glass
fill ~-40 ~2 ~125 ~-40 ~6 ~129 glass
fill ~-5 ~2 ~125 ~-5 ~6 ~129 glass
fill ~-40 ~2 ~133 ~-40 ~6 ~137 glass
fill ~-5 ~2 ~133 ~-5 ~6 ~137 glass
fill ~-40 ~2 ~141 ~-40 ~6 ~145 glass
fill ~-5 ~2 ~141 ~-5 ~6 ~145 glass
fill ~-40 ~2 ~149 ~-40 ~6 ~153 glass
fill ~-5 ~2 ~149 ~-5 ~6 ~153 glass
fill ~-38 ~0 ~108 ~-23 ~8 ~115 quartz_block
fill ~-37 ~1 ~109 ~-24 ~7 ~114 air
fill ~-37 ~0 ~109 ~-24 ~0 ~114 white_wool
fill ~-32 ~1 ~112 ~-30 ~1 ~113 white_wool
fill ~-32 ~1 ~114 ~-30 ~2 ~114 gold_block
fill ~-32 ~1 ~113 ~-30 ~1 ~113 red_wool
setblock ~-33 ~1 ~113 dark_oak_planks
setblock ~-29 ~1 ~113 dark_oak_planks
setblock ~-33 ~2 ~113 sea_lantern
setblock ~-29 ~2 ~113 sea_lantern
fill ~-25 ~1 ~110 ~-25 ~1 ~112 dark_oak_planks
setblock ~-36 ~1 ~110 spruce_planks
fill ~-33 ~0 ~111 ~-29 ~0 ~112 white_wool
fill ~-35 ~2 ~108 ~-26 ~5 ~108 glass
setblock ~-31 ~7 ~111 glowstone
fill ~-38 ~1 ~111 ~-38 ~3 ~112 air
fill ~-38 ~4 ~111 ~-38 ~4 ~112 gold_block
fill ~-22 ~0 ~108 ~-7 ~8 ~115 quartz_block
fill ~-21 ~1 ~109 ~-8 ~7 ~114 air
fill ~-21 ~0 ~109 ~-8 ~0 ~114 orange_wool
fill ~-16 ~1 ~112 ~-14 ~1 ~113 white_wool
fill ~-16 ~1 ~114 ~-14 ~2 ~114 gold_block
fill ~-16 ~1 ~113 ~-14 ~1 ~113 red_wool
setblock ~-17 ~1 ~113 dark_oak_planks
setblock ~-13 ~1 ~113 dark_oak_planks
setblock ~-17 ~2 ~113 sea_lantern
setblock ~-13 ~2 ~113 sea_lantern
fill ~-9 ~1 ~110 ~-9 ~1 ~112 dark_oak_planks
setblock ~-20 ~1 ~110 spruce_planks
fill ~-17 ~0 ~111 ~-13 ~0 ~112 orange_wool
fill ~-19 ~2 ~108 ~-10 ~5 ~108 glass
setblock ~-15 ~7 ~111 glowstone
fill ~-22 ~1 ~111 ~-22 ~3 ~112 air
fill ~-22 ~4 ~111 ~-22 ~4 ~112 gold_block
fill ~-38 ~0 ~117 ~-23 ~8 ~124 quartz_block
fill ~-37 ~1 ~118 ~-24 ~7 ~123 air
fill ~-37 ~0 ~118 ~-24 ~0 ~123 red_wool
fill ~-32 ~1 ~121 ~-30 ~1 ~122 white_wool
fill ~-32 ~1 ~123 ~-30 ~2 ~123 gold_block
fill ~-32 ~1 ~122 ~-30 ~1 ~122 red_wool
setblock ~-33 ~1 ~122 dark_oak_planks
setblock ~-29 ~1 ~122 dark_oak_planks
setblock ~-33 ~2 ~122 sea_lantern
setblock ~-29 ~2 ~122 sea_lantern
fill ~-25 ~1 ~119 ~-25 ~1 ~121 dark_oak_planks
setblock ~-36 ~1 ~119 spruce_planks
fill ~-33 ~0 ~120 ~-29 ~0 ~121 red_wool
fill ~-35 ~2 ~117 ~-26 ~5 ~117 glass
setblock ~-31 ~7 ~120 glowstone
fill ~-38 ~1 ~120 ~-38 ~3 ~121 air
fill ~-38 ~4 ~120 ~-38 ~4 ~121 gold_block
fill ~-22 ~0 ~117 ~-7 ~8 ~124 quartz_block
fill ~-21 ~1 ~118 ~-8 ~7 ~123 air
fill ~-21 ~0 ~118 ~-8 ~0 ~123 lime_wool
fill ~-16 ~1 ~121 ~-14 ~1 ~122 white_wool
fill ~-16 ~1 ~123 ~-14 ~2 ~123 gold_block
fill ~-16 ~1 ~122 ~-14 ~1 ~122 red_wool
setblock ~-17 ~1 ~122 dark_oak_planks
setblock ~-13 ~1 ~122 dark_oak_planks
setblock ~-17 ~2 ~122 sea_lantern
setblock ~-13 ~2 ~122 sea_lantern
fill ~-9 ~1 ~119 ~-9 ~1 ~121 dark_oak_planks
setblock ~-20 ~1 ~119 spruce_planks
fill ~-17 ~0 ~120 ~-13 ~0 ~121 lime_wool
fill ~-19 ~2 ~117 ~-10 ~5 ~117 glass
setblock ~-15 ~7 ~120 glowstone
fill ~-22 ~1 ~120 ~-22 ~3 ~121 air
fill ~-22 ~4 ~120 ~-22 ~4 ~121 gold_block
fill ~-38 ~0 ~126 ~-23 ~8 ~133 quartz_block
fill ~-37 ~1 ~127 ~-24 ~7 ~132 air
fill ~-37 ~0 ~127 ~-24 ~0 ~132 blue_wool
fill ~-32 ~1 ~130 ~-30 ~1 ~131 white_wool
fill ~-32 ~1 ~132 ~-30 ~2 ~132 gold_block
fill ~-32 ~1 ~131 ~-30 ~1 ~131 red_wool
setblock ~-33 ~1 ~131 dark_oak_planks
setblock ~-29 ~1 ~131 dark_oak_planks
setblock ~-33 ~2 ~131 sea_lantern
setblock ~-29 ~2 ~131 sea_lantern
fill ~-25 ~1 ~128 ~-25 ~1 ~130 dark_oak_planks
setblock ~-36 ~1 ~128 spruce_planks
fill ~-33 ~0 ~129 ~-29 ~0 ~130 blue_wool
fill ~-35 ~2 ~126 ~-26 ~5 ~126 glass
setblock ~-31 ~7 ~129 glowstone
fill ~-38 ~1 ~129 ~-38 ~3 ~130 air
fill ~-38 ~4 ~129 ~-38 ~4 ~130 gold_block
fill ~-22 ~0 ~126 ~-7 ~8 ~133 quartz_block
fill ~-21 ~1 ~127 ~-8 ~7 ~132 air
fill ~-21 ~0 ~127 ~-8 ~0 ~132 yellow_wool
fill ~-16 ~1 ~130 ~-14 ~1 ~131 white_wool
fill ~-16 ~1 ~132 ~-14 ~2 ~132 gold_block
fill ~-16 ~1 ~131 ~-14 ~1 ~131 red_wool
setblock ~-17 ~1 ~131 dark_oak_planks
setblock ~-13 ~1 ~131 dark_oak_planks
setblock ~-17 ~2 ~131 sea_lantern
setblock ~-13 ~2 ~131 sea_lantern
fill ~-9 ~1 ~128 ~-9 ~1 ~130 dark_oak_planks
setblock ~-20 ~1 ~128 spruce_planks
fill ~-17 ~0 ~129 ~-13 ~0 ~130 yellow_wool
fill ~-19 ~2 ~126 ~-10 ~5 ~126 glass
setblock ~-15 ~7 ~129 glowstone
fill ~-22 ~1 ~129 ~-22 ~3 ~130 air
fill ~-22 ~4 ~129 ~-22 ~4 ~130 gold_block
fill ~-38 ~0 ~135 ~-23 ~8 ~142 quartz_block
fill ~-37 ~1 ~136 ~-24 ~7 ~141 air
fill ~-37 ~0 ~136 ~-24 ~0 ~141 cyan_wool
fill ~-32 ~1 ~139 ~-30 ~1 ~140 white_wool
fill ~-32 ~1 ~141 ~-30 ~2 ~141 gold_block
fill ~-32 ~1 ~140 ~-30 ~1 ~140 red_wool
setblock ~-33 ~1 ~140 dark_oak_planks
setblock ~-29 ~1 ~140 dark_oak_planks
setblock ~-33 ~2 ~140 sea_lantern
setblock ~-29 ~2 ~140 sea_lantern
fill ~-25 ~1 ~137 ~-25 ~1 ~139 dark_oak_planks
setblock ~-36 ~1 ~137 spruce_planks
fill ~-33 ~0 ~138 ~-29 ~0 ~139 cyan_wool
fill ~-35 ~2 ~135 ~-26 ~5 ~135 glass
setblock ~-31 ~7 ~138 glowstone
fill ~-38 ~1 ~138 ~-38 ~3 ~139 air
fill ~-38 ~4 ~138 ~-38 ~4 ~139 gold_block
fill ~-22 ~0 ~135 ~-7 ~8 ~142 quartz_block
fill ~-21 ~1 ~136 ~-8 ~7 ~141 air
fill ~-21 ~0 ~136 ~-8 ~0 ~141 purple_wool
fill ~-16 ~1 ~139 ~-14 ~1 ~140 white_wool
fill ~-16 ~1 ~141 ~-14 ~2 ~141 gold_block
fill ~-16 ~1 ~140 ~-14 ~1 ~140 red_wool
setblock ~-17 ~1 ~140 dark_oak_planks
setblock ~-13 ~1 ~140 dark_oak_planks
setblock ~-17 ~2 ~140 sea_lantern
setblock ~-13 ~2 ~140 sea_lantern
fill ~-9 ~1 ~137 ~-9 ~1 ~139 dark_oak_planks
setblock ~-20 ~1 ~137 spruce_planks
fill ~-17 ~0 ~138 ~-13 ~0 ~139 purple_wool
fill ~-19 ~2 ~135 ~-10 ~5 ~135 glass
setblock ~-15 ~7 ~138 glowstone
fill ~-22 ~1 ~138 ~-22 ~3 ~139 air
fill ~-22 ~4 ~138 ~-22 ~4 ~139 gold_block
fill ~-38 ~0 ~144 ~-23 ~8 ~151 quartz_block
fill ~-37 ~1 ~145 ~-24 ~7 ~150 air
fill ~-37 ~0 ~145 ~-24 ~0 ~150 pink_wool
fill ~-32 ~1 ~148 ~-30 ~1 ~149 white_wool
fill ~-32 ~1 ~150 ~-30 ~2 ~150 gold_block
fill ~-32 ~1 ~149 ~-30 ~1 ~149 red_wool
setblock ~-33 ~1 ~149 dark_oak_planks
setblock ~-29 ~1 ~149 dark_oak_planks
setblock ~-33 ~2 ~149 sea_lantern
setblock ~-29 ~2 ~149 sea_lantern
fill ~-25 ~1 ~146 ~-25 ~1 ~148 dark_oak_planks
setblock ~-36 ~1 ~146 spruce_planks
fill ~-33 ~0 ~147 ~-29 ~0 ~148 pink_wool
fill ~-35 ~2 ~144 ~-26 ~5 ~144 glass
setblock ~-31 ~7 ~147 glowstone
fill ~-38 ~1 ~147 ~-38 ~3 ~148 air
fill ~-38 ~4 ~147 ~-38 ~4 ~148 gold_block
fill ~-22 ~0 ~144 ~-7 ~8 ~151 quartz_block
fill ~-21 ~1 ~145 ~-8 ~7 ~150 air
fill ~-21 ~0 ~145 ~-8 ~0 ~150 magenta_wool
fill ~-16 ~1 ~148 ~-14 ~1 ~149 white_wool
fill ~-16 ~1 ~150 ~-14 ~2 ~150 gold_block
fill ~-16 ~1 ~149 ~-14 ~1 ~149 red_wool
setblock ~-17 ~1 ~149 dark_oak_planks
setblock ~-13 ~1 ~149 dark_oak_planks
setblock ~-17 ~2 ~149 sea_lantern
setblock ~-13 ~2 ~149 sea_lantern
fill ~-9 ~1 ~146 ~-9 ~1 ~148 dark_oak_planks
setblock ~-20 ~1 ~146 spruce_planks
fill ~-17 ~0 ~147 ~-13 ~0 ~148 magenta_wool
fill ~-19 ~2 ~144 ~-10 ~5 ~144 glass
setblock ~-15 ~7 ~147 glowstone
fill ~-22 ~1 ~147 ~-22 ~3 ~148 air
fill ~-22 ~4 ~147 ~-22 ~4 ~148 gold_block
fill ~-40 ~8 ~105 ~-10 ~8 ~135 dark_oak_planks
fill ~-40 ~8 ~136 ~-10 ~8 ~155 dark_oak_planks
fill ~-9 ~8 ~105 ~-5 ~8 ~135 dark_oak_planks
fill ~-9 ~8 ~136 ~-5 ~8 ~155 dark_oak_planks
fill ~-40 ~9 ~105 ~-10 ~16 ~135 quartz_block
fill ~-40 ~9 ~136 ~-10 ~16 ~155 quartz_block
fill ~-9 ~9 ~105 ~-5 ~16 ~135 quartz_block
fill ~-9 ~9 ~136 ~-5 ~16 ~155 quartz_block
fill ~-38 ~9 ~107 ~-8 ~15 ~137 air
fill ~-38 ~9 ~138 ~-8 ~15 ~153 air
fill ~-7 ~9 ~107 ~-7 ~15 ~137 air
fill ~-7 ~9 ~138 ~-7 ~15 ~153 air
fill ~-40 ~9 ~105 ~-10 ~9 ~105 gold_block
fill ~-9 ~9 ~105 ~-5 ~9 ~105 gold_block
fill ~-40 ~9 ~155 ~-10 ~9 ~155 gold_block
fill ~-9 ~9 ~155 ~-5 ~9 ~155 gold_block
fill ~-40 ~10 ~109 ~-40 ~14 ~113 glass
fill ~-5 ~10 ~109 ~-5 ~14 ~113 glass
fill ~-40 ~10 ~117 ~-40 ~14 ~121 glass
fill ~-5 ~10 ~117 ~-5 ~14 ~121 glass
fill ~-40 ~10 ~125 ~-40 ~14 ~129 glass
fill ~-5 ~10 ~125 ~-5 ~14 ~129 glass
fill ~-40 ~10 ~133 ~-40 ~14 ~137 glass
fill ~-5 ~10 ~133 ~-5 ~14 ~137 glass
fill ~-40 ~10 ~141 ~-40 ~14 ~145 glass
fill ~-5 ~10 ~141 ~-5 ~14 ~145 glass
fill ~-40 ~10 ~149 ~-40 ~14 ~153 glass
fill ~-5 ~10 ~149 ~-5 ~14 ~153 glass
fill ~-38 ~8 ~108 ~-23 ~16 ~115 quartz_block
fill ~-37 ~9 ~109 ~-24 ~15 ~114 air
fill ~-37 ~8 ~109 ~-24 ~8 ~114 white_wool
fill ~-32 ~9 ~112 ~-30 ~9 ~113 white_wool
fill ~-32 ~9 ~114 ~-30 ~10 ~114 gold_block
fill ~-32 ~9 ~113 ~-30 ~9 ~113 red_wool
setblock ~-33 ~9 ~113 dark_oak_planks
setblock ~-29 ~9 ~113 dark_oak_planks
setblock ~-33 ~10 ~113 sea_lantern
setblock ~-29 ~10 ~113 sea_lantern
fill ~-25 ~9 ~110 ~-25 ~9 ~112 dark_oak_planks
setblock ~-36 ~9 ~110 spruce_planks
fill ~-33 ~8 ~111 ~-29 ~8 ~112 white_wool
fill ~-35 ~10 ~108 ~-26 ~13 ~108 glass
setblock ~-31 ~15 ~111 glowstone
fill ~-38 ~9 ~111 ~-38 ~11 ~112 air
fill ~-38 ~12 ~111 ~-38 ~12 ~112 gold_block
fill ~-22 ~8 ~108 ~-7 ~16 ~115 quartz_block
fill ~-21 ~9 ~109 ~-8 ~15 ~114 air
fill ~-21 ~8 ~109 ~-8 ~8 ~114 orange_wool
fill ~-16 ~9 ~112 ~-14 ~9 ~113 white_wool
fill ~-16 ~9 ~114 ~-14 ~10 ~114 gold_block
fill ~-16 ~9 ~113 ~-14 ~9 ~113 red_wool
setblock ~-17 ~9 ~113 dark_oak_planks
setblock ~-13 ~9 ~113 dark_oak_planks
setblock ~-17 ~10 ~113 sea_lantern
setblock ~-13 ~10 ~113 sea_lantern
fill ~-9 ~9 ~110 ~-9 ~9 ~112 dark_oak_planks
setblock ~-20 ~9 ~110 spruce_planks
fill ~-17 ~8 ~111 ~-13 ~8 ~112 orange_wool
fill ~-19 ~10 ~108 ~-10 ~13 ~108 glass
setblock ~-15 ~15 ~111 glowstone
fill ~-22 ~9 ~111 ~-22 ~11 ~112 air
fill ~-22 ~12 ~111 ~-22 ~12 ~112 gold_block
fill ~-38 ~8 ~117 ~-23 ~16 ~124 quartz_block
fill ~-37 ~9 ~118 ~-24 ~15 ~123 air
fill ~-37 ~8 ~118 ~-24 ~8 ~123 red_wool
fill ~-32 ~9 ~121 ~-30 ~9 ~122 white_wool
fill ~-32 ~9 ~123 ~-30 ~10 ~123 gold_block
fill ~-32 ~9 ~122 ~-30 ~9 ~122 red_wool
setblock ~-33 ~9 ~122 dark_oak_planks
setblock ~-29 ~9 ~122 dark_oak_planks
setblock ~-33 ~10 ~122 sea_lantern
setblock ~-29 ~10 ~122 sea_lantern
fill ~-25 ~9 ~119 ~-25 ~9 ~121 dark_oak_planks
setblock ~-36 ~9 ~119 spruce_planks
fill ~-33 ~8 ~120 ~-29 ~8 ~121 red_wool
fill ~-35 ~10 ~117 ~-26 ~13 ~117 glass
setblock ~-31 ~15 ~120 glowstone
fill ~-38 ~9 ~120 ~-38 ~11 ~121 air
fill ~-38 ~12 ~120 ~-38 ~12 ~121 gold_block
fill ~-22 ~8 ~117 ~-7 ~16 ~124 quartz_block
fill ~-21 ~9 ~118 ~-8 ~15 ~123 air
fill ~-21 ~8 ~118 ~-8 ~8 ~123 lime_wool
fill ~-16 ~9 ~121 ~-14 ~9 ~122 white_wool
fill ~-16 ~9 ~123 ~-14 ~10 ~123 gold_block
fill ~-16 ~9 ~122 ~-14 ~9 ~122 red_wool
setblock ~-17 ~9 ~122 dark_oak_planks
setblock ~-13 ~9 ~122 dark_oak_planks
setblock ~-17 ~10 ~122 sea_lantern
setblock ~-13 ~10 ~122 sea_lantern
fill ~-9 ~9 ~119 ~-9 ~9 ~121 dark_oak_planks
setblock ~-20 ~9 ~119 spruce_planks
fill ~-17 ~8 ~120 ~-13 ~8 ~121 lime_wool
fill ~-19 ~10 ~117 ~-10 ~13 ~117 glass
setblock ~-15 ~15 ~120 glowstone
fill ~-22 ~9 ~120 ~-22 ~11 ~121 air
fill ~-22 ~12 ~120 ~-22 ~12 ~121 gold_block
fill ~-38 ~8 ~126 ~-23 ~16 ~133 quartz_block
fill ~-37 ~9 ~127 ~-24 ~15 ~132 air
fill ~-37 ~8 ~127 ~-24 ~8 ~132 blue_wool
fill ~-32 ~9 ~130 ~-30 ~9 ~131 white_wool
fill ~-32 ~9 ~132 ~-30 ~10 ~132 gold_block
fill ~-32 ~9 ~131 ~-30 ~9 ~131 red_wool
setblock ~-33 ~9 ~131 dark_oak_planks
setblock ~-29 ~9 ~131 dark_oak_planks
setblock ~-33 ~10 ~131 sea_lantern
setblock ~-29 ~10 ~131 sea_lantern
fill ~-25 ~9 ~128 ~-25 ~9 ~130 dark_oak_planks
setblock ~-36 ~9 ~128 spruce_planks
fill ~-33 ~8 ~129 ~-29 ~8 ~130 blue_wool
fill ~-35 ~10 ~126 ~-26 ~13 ~126 glass
setblock ~-31 ~15 ~129 glowstone
fill ~-38 ~9 ~129 ~-38 ~11 ~130 air
fill ~-38 ~12 ~129 ~-38 ~12 ~130 gold_block
fill ~-22 ~8 ~126 ~-7 ~16 ~133 quartz_block
fill ~-21 ~9 ~127 ~-8 ~15 ~132 air
fill ~-21 ~8 ~127 ~-8 ~8 ~132 yellow_wool
fill ~-16 ~9 ~130 ~-14 ~9 ~131 white_wool
fill ~-16 ~9 ~132 ~-14 ~10 ~132 gold_block
fill ~-16 ~9 ~131 ~-14 ~9 ~131 red_wool
setblock ~-17 ~9 ~131 dark_oak_planks
setblock ~-13 ~9 ~131 dark_oak_planks
setblock ~-17 ~10 ~131 sea_lantern
setblock ~-13 ~10 ~131 sea_lantern
fill ~-9 ~9 ~128 ~-9 ~9 ~130 dark_oak_planks
setblock ~-20 ~9 ~128 spruce_planks
fill ~-17 ~8 ~129 ~-13 ~8 ~130 yellow_wool
fill ~-19 ~10 ~126 ~-10 ~13 ~126 glass
setblock ~-15 ~15 ~129 glowstone
fill ~-22 ~9 ~129 ~-22 ~11 ~130 air
fill ~-22 ~12 ~129 ~-22 ~12 ~130 gold_block
fill ~-38 ~8 ~135 ~-23 ~16 ~142 quartz_block
fill ~-37 ~9 ~136 ~-24 ~15 ~141 air
fill ~-37 ~8 ~136 ~-24 ~8 ~141 cyan_wool
fill ~-32 ~9 ~139 ~-30 ~9 ~140 white_wool
fill ~-32 ~9 ~141 ~-30 ~10 ~141 gold_block
fill ~-32 ~9 ~140 ~-30 ~9 ~140 red_wool
setblock ~-33 ~9 ~140 dark_oak_planks
setblock ~-29 ~9 ~140 dark_oak_planks
setblock ~-33 ~10 ~140 sea_lantern
setblock ~-29 ~10 ~140 sea_lantern
fill ~-25 ~9 ~137 ~-25 ~9 ~139 dark_oak_planks
setblock ~-36 ~9 ~137 spruce_planks
fill ~-33 ~8 ~138 ~-29 ~8 ~139 cyan_wool
fill ~-35 ~10 ~135 ~-26 ~13 ~135 glass
setblock ~-31 ~15 ~138 glowstone
fill ~-38 ~9 ~138 ~-38 ~11 ~139 air
fill ~-38 ~12 ~138 ~-38 ~12 ~139 gold_block
fill ~-22 ~8 ~135 ~-7 ~16 ~142 quartz_block
fill ~-21 ~9 ~136 ~-8 ~15 ~141 air
fill ~-21 ~8 ~136 ~-8 ~8 ~141 purple_wool
fill ~-16 ~9 ~139 ~-14 ~9 ~140 white_wool
fill ~-16 ~9 ~141 ~-14 ~10 ~141 gold_block
fill ~-16 ~9 ~140 ~-14 ~9 ~140 red_wool
setblock ~-17 ~9 ~140 dark_oak_planks
setblock ~-13 ~9 ~140 dark_oak_planks
setblock ~-17 ~10 ~140 sea_lantern
setblock ~-13 ~10 ~140 sea_lantern
fill ~-9 ~9 ~137 ~-9 ~9 ~139 dark_oak_planks
setblock ~-20 ~9 ~137 spruce_planks
fill ~-17 ~8 ~138 ~-13 ~8 ~139 purple_wool
fill ~-19 ~10 ~135 ~-10 ~13 ~135 glass
setblock ~-15 ~15 ~138 glowstone
fill ~-22 ~9 ~138 ~-22 ~11 ~139 air
fill ~-22 ~12 ~138 ~-22 ~12 ~139 gold_block
fill ~-38 ~8 ~144 ~-23 ~16 ~151 quartz_block
fill ~-37 ~9 ~145 ~-24 ~15 ~150 air
fill ~-37 ~8 ~145 ~-24 ~8 ~150 pink_wool
fill ~-32 ~9 ~148 ~-30 ~9 ~149 white_wool
fill ~-32 ~9 ~150 ~-30 ~10 ~150 gold_block
fill ~-32 ~9 ~149 ~-30 ~9 ~149 red_wool
setblock ~-33 ~9 ~149 dark_oak_planks
setblock ~-29 ~9 ~149 dark_oak_planks
setblock ~-33 ~10 ~149 sea_lantern
setblock ~-29 ~10 ~149 sea_lantern
fill ~-25 ~9 ~146 ~-25 ~9 ~148 dark_oak_planks
setblock ~-36 ~9 ~146 spruce_planks
fill ~-33 ~8 ~147 ~-29 ~8 ~148 pink_wool
fill ~-35 ~10 ~144 ~-26 ~13 ~144 glass
setblock ~-31 ~15 ~147 glowstone
fill ~-38 ~9 ~147 ~-38 ~11 ~148 air
fill ~-38 ~12 ~147 ~-38 ~12 ~148 gold_block
fill ~-22 ~8 ~144 ~-7 ~16 ~151 quartz_block
fill ~-21 ~9 ~145 ~-8 ~15 ~150 air
fill ~-21 ~8 ~145 ~-8 ~8 ~150 magenta_wool
fill ~-16 ~9 ~148 ~-14 ~9 ~149 white_wool
fill ~-16 ~9 ~150 ~-14 ~10 ~150 gold_block
fill ~-16 ~9 ~149 ~-14 ~9 ~149 red_wool
setblock ~-17 ~9 ~149 dark_oak_planks
setblock ~-13 ~9 ~149 dark_oak_planks
setblock ~-17 ~10 ~149 sea_lantern
setblock ~-13 ~10 ~149 sea_lantern
fill ~-9 ~9 ~146 ~-9 ~9 ~148 dark_oak_planks
setblock ~-20 ~9 ~146 spruce_planks
fill ~-17 ~8 ~147 ~-13 ~8 ~148 magenta_wool
fill ~-19 ~10 ~144 ~-10 ~13 ~144 glass
setblock ~-15 ~15 ~147 glowstone
fill ~-22 ~9 ~147 ~-22 ~11 ~148 air
fill ~-22 ~12 ~147 ~-22 ~12 ~148 gold_block
fill ~-40 ~16 ~105 ~-10 ~16 ~135 quartz_block
fill ~-40 ~16 ~136 ~-10 ~16 ~155 quartz_block
fill ~-9 ~16 ~105 ~-5 ~16 ~135 quartz_block
fill ~-9 ~16 ~136 ~-5 ~16 ~155 quartz_block
fill ~-25 ~1 ~105 ~-21 ~4 ~105 air
fill ~-25 ~5 ~105 ~-21 ~5 ~105 gold_block
function bezos_guesthouse2
