# Phase 11: Two guest houses with 10 bedrooms each
# --- West Guest House (10 bedrooms) ---
fill ~-40 ~-1 ~105 ~-5 ~-1 ~155 quartz_block
fill ~-40 ~0 ~105 ~-5 ~0 ~155 dark_oak_planks
fill ~-40 ~1 ~105 ~-5 ~8 ~155 quartz_block
fill ~-38 ~1 ~107 ~-7 ~7 ~153 air
fill ~-40 ~1 ~105 ~-5 ~1 ~105 gold_block
fill ~-40 ~1 ~155 ~-5 ~1 ~155 gold_block
fill ~-40 ~2 ~109 ~-40 ~6 ~113 glass
fill ~-5 ~2 ~109 ~-5 ~6 ~113 glass
fill ~-40 ~2 ~117 ~-40 ~6 ~121 glass
fill ~-5 ~2 ~117 ~-5 ~6 ~121 glass
fill ~-40 ~2 ~125 ~-40 ~6 ~129 glass
fill ~-5 ~2 ~125 ~-5 ~6 ~129 glass
fill ~-40 ~2 ~133 ~-40 ~6 ~137 glass
fill ~-5 ~2 ~133 ~-5 ~6 ~137 glass
fill ~-40 ~2 ~141 ~-40 ~6 ~145 glass
fill ~-5 ~2 ~141 ~-5 ~6 ~145 glass
fill ~-40 ~2 ~149 ~-40 ~6 ~153 glass
fill ~-5 ~2 ~149 ~-5 ~6 ~153 glass
fill ~-38 ~0 ~108 ~-23 ~8 ~115 quartz_block
fill ~-37 ~1 ~109 ~-24 ~7 ~114 air
fill ~-37 ~0 ~109 ~-24 ~0 ~114 white_wool
fill ~-32 ~1 ~113 ~-30 ~1 ~114 white_wool
fill ~-32 ~1 ~114 ~-30 ~2 ~114 gold_block
fill ~-35 ~2 ~108 ~-26 ~5 ~108 glass
setblock ~-31 ~7 ~111 glowstone
fill ~-38 ~1 ~111 ~-38 ~3 ~112 air
fill ~-38 ~4 ~111 ~-38 ~4 ~112 gold_block
fill ~-22 ~0 ~108 ~-7 ~8 ~115 quartz_block
fill ~-21 ~1 ~109 ~-8 ~7 ~114 air
fill ~-21 ~0 ~109 ~-8 ~0 ~114 orange_wool
fill ~-16 ~1 ~113 ~-14 ~1 ~114 white_wool
fill ~-16 ~1 ~114 ~-14 ~2 ~114 gold_block
fill ~-19 ~2 ~108 ~-10 ~5 ~108 glass
setblock ~-15 ~7 ~111 glowstone
fill ~-22 ~1 ~111 ~-22 ~3 ~112 air
fill ~-22 ~4 ~111 ~-22 ~4 ~112 gold_block
fill ~-38 ~0 ~117 ~-23 ~8 ~124 quartz_block
fill ~-37 ~1 ~118 ~-24 ~7 ~123 air
fill ~-37 ~0 ~118 ~-24 ~0 ~123 red_wool
fill ~-32 ~1 ~122 ~-30 ~1 ~123 white_wool
fill ~-32 ~1 ~123 ~-30 ~2 ~123 gold_block
fill ~-35 ~2 ~117 ~-26 ~5 ~117 glass
setblock ~-31 ~7 ~120 glowstone
fill ~-38 ~1 ~120 ~-38 ~3 ~121 air
fill ~-38 ~4 ~120 ~-38 ~4 ~121 gold_block
fill ~-22 ~0 ~117 ~-7 ~8 ~124 quartz_block
fill ~-21 ~1 ~118 ~-8 ~7 ~123 air
fill ~-21 ~0 ~118 ~-8 ~0 ~123 lime_wool
fill ~-16 ~1 ~122 ~-14 ~1 ~123 white_wool
fill ~-16 ~1 ~123 ~-14 ~2 ~123 gold_block
fill ~-19 ~2 ~117 ~-10 ~5 ~117 glass
setblock ~-15 ~7 ~120 glowstone
fill ~-22 ~1 ~120 ~-22 ~3 ~121 air
fill ~-22 ~4 ~120 ~-22 ~4 ~121 gold_block
fill ~-38 ~0 ~126 ~-23 ~8 ~133 quartz_block
fill ~-37 ~1 ~127 ~-24 ~7 ~132 air
fill ~-37 ~0 ~127 ~-24 ~0 ~132 blue_wool
fill ~-32 ~1 ~131 ~-30 ~1 ~132 white_wool
fill ~-32 ~1 ~132 ~-30 ~2 ~132 gold_block
fill ~-35 ~2 ~126 ~-26 ~5 ~126 glass
setblock ~-31 ~7 ~129 glowstone
fill ~-38 ~1 ~129 ~-38 ~3 ~130 air
fill ~-38 ~4 ~129 ~-38 ~4 ~130 gold_block
fill ~-22 ~0 ~126 ~-7 ~8 ~133 quartz_block
fill ~-21 ~1 ~127 ~-8 ~7 ~132 air
fill ~-21 ~0 ~127 ~-8 ~0 ~132 yellow_wool
fill ~-16 ~1 ~131 ~-14 ~1 ~132 white_wool
fill ~-16 ~1 ~132 ~-14 ~2 ~132 gold_block
fill ~-19 ~2 ~126 ~-10 ~5 ~126 glass
setblock ~-15 ~7 ~129 glowstone
fill ~-22 ~1 ~129 ~-22 ~3 ~130 air
fill ~-22 ~4 ~129 ~-22 ~4 ~130 gold_block
fill ~-38 ~0 ~135 ~-23 ~8 ~142 quartz_block
fill ~-37 ~1 ~136 ~-24 ~7 ~141 air
fill ~-37 ~0 ~136 ~-24 ~0 ~141 cyan_wool
fill ~-32 ~1 ~140 ~-30 ~1 ~141 white_wool
fill ~-32 ~1 ~141 ~-30 ~2 ~141 gold_block
fill ~-35 ~2 ~135 ~-26 ~5 ~135 glass
setblock ~-31 ~7 ~138 glowstone
fill ~-38 ~1 ~138 ~-38 ~3 ~139 air
fill ~-38 ~4 ~138 ~-38 ~4 ~139 gold_block
fill ~-22 ~0 ~135 ~-7 ~8 ~142 quartz_block
fill ~-21 ~1 ~136 ~-8 ~7 ~141 air
fill ~-21 ~0 ~136 ~-8 ~0 ~141 purple_wool
fill ~-16 ~1 ~140 ~-14 ~1 ~141 white_wool
fill ~-16 ~1 ~141 ~-14 ~2 ~141 gold_block
fill ~-19 ~2 ~135 ~-10 ~5 ~135 glass
setblock ~-15 ~7 ~138 glowstone
fill ~-22 ~1 ~138 ~-22 ~3 ~139 air
fill ~-22 ~4 ~138 ~-22 ~4 ~139 gold_block
fill ~-38 ~0 ~144 ~-23 ~8 ~151 quartz_block
fill ~-37 ~1 ~145 ~-24 ~7 ~150 air
fill ~-37 ~0 ~145 ~-24 ~0 ~150 pink_wool
fill ~-32 ~1 ~149 ~-30 ~1 ~150 white_wool
fill ~-32 ~1 ~150 ~-30 ~2 ~150 gold_block
fill ~-35 ~2 ~144 ~-26 ~5 ~144 glass
setblock ~-31 ~7 ~147 glowstone
fill ~-38 ~1 ~147 ~-38 ~3 ~148 air
fill ~-38 ~4 ~147 ~-38 ~4 ~148 gold_block
fill ~-22 ~0 ~144 ~-7 ~8 ~151 quartz_block
fill ~-21 ~1 ~145 ~-8 ~7 ~150 air
fill ~-21 ~0 ~145 ~-8 ~0 ~150 magenta_wool
fill ~-16 ~1 ~149 ~-14 ~1 ~150 white_wool
fill ~-16 ~1 ~150 ~-14 ~2 ~150 gold_block
fill ~-19 ~2 ~144 ~-10 ~5 ~144 glass
setblock ~-15 ~7 ~147 glowstone
fill ~-22 ~1 ~147 ~-22 ~3 ~148 air
fill ~-22 ~4 ~147 ~-22 ~4 ~148 gold_block
fill ~-40 ~8 ~105 ~-5 ~8 ~155 dark_oak_planks
fill ~-40 ~9 ~105 ~-5 ~16 ~155 quartz_block
fill ~-38 ~9 ~107 ~-7 ~15 ~153 air
fill ~-40 ~9 ~105 ~-5 ~9 ~105 gold_block
fill ~-40 ~9 ~155 ~-5 ~9 ~155 gold_block
fill ~-40 ~10 ~109 ~-40 ~14 ~113 glass
fill ~-5 ~10 ~109 ~-5 ~14 ~113 glass
fill ~-40 ~10 ~117 ~-40 ~14 ~121 glass
fill ~-5 ~10 ~117 ~-5 ~14 ~121 glass
fill ~-40 ~10 ~125 ~-40 ~14 ~129 glass
fill ~-5 ~10 ~125 ~-5 ~14 ~129 glass
fill ~-40 ~10 ~133 ~-40 ~14 ~137 glass
fill ~-5 ~10 ~133 ~-5 ~14 ~137 glass
fill ~-40 ~10 ~141 ~-40 ~14 ~145 glass
fill ~-5 ~10 ~141 ~-5 ~14 ~145 glass
fill ~-40 ~10 ~149 ~-40 ~14 ~153 glass
fill ~-5 ~10 ~149 ~-5 ~14 ~153 glass
fill ~-38 ~8 ~108 ~-23 ~16 ~115 quartz_block
fill ~-37 ~9 ~109 ~-24 ~15 ~114 air
fill ~-37 ~8 ~109 ~-24 ~8 ~114 white_wool
fill ~-32 ~9 ~113 ~-30 ~9 ~114 white_wool
fill ~-32 ~9 ~114 ~-30 ~10 ~114 gold_block
fill ~-35 ~10 ~108 ~-26 ~13 ~108 glass
setblock ~-31 ~15 ~111 glowstone
fill ~-38 ~9 ~111 ~-38 ~11 ~112 air
fill ~-38 ~12 ~111 ~-38 ~12 ~112 gold_block
fill ~-22 ~8 ~108 ~-7 ~16 ~115 quartz_block
fill ~-21 ~9 ~109 ~-8 ~15 ~114 air
fill ~-21 ~8 ~109 ~-8 ~8 ~114 orange_wool
fill ~-16 ~9 ~113 ~-14 ~9 ~114 white_wool
fill ~-16 ~9 ~114 ~-14 ~10 ~114 gold_block
fill ~-19 ~10 ~108 ~-10 ~13 ~108 glass
setblock ~-15 ~15 ~111 glowstone
fill ~-22 ~9 ~111 ~-22 ~11 ~112 air
fill ~-22 ~12 ~111 ~-22 ~12 ~112 gold_block
fill ~-38 ~8 ~117 ~-23 ~16 ~124 quartz_block
fill ~-37 ~9 ~118 ~-24 ~15 ~123 air
fill ~-37 ~8 ~118 ~-24 ~8 ~123 red_wool
fill ~-32 ~9 ~122 ~-30 ~9 ~123 white_wool
fill ~-32 ~9 ~123 ~-30 ~10 ~123 gold_block
fill ~-35 ~10 ~117 ~-26 ~13 ~117 glass
setblock ~-31 ~15 ~120 glowstone
fill ~-38 ~9 ~120 ~-38 ~11 ~121 air
fill ~-38 ~12 ~120 ~-38 ~12 ~121 gold_block
fill ~-22 ~8 ~117 ~-7 ~16 ~124 quartz_block
fill ~-21 ~9 ~118 ~-8 ~15 ~123 air
fill ~-21 ~8 ~118 ~-8 ~8 ~123 lime_wool
fill ~-16 ~9 ~122 ~-14 ~9 ~123 white_wool
fill ~-16 ~9 ~123 ~-14 ~10 ~123 gold_block
fill ~-19 ~10 ~117 ~-10 ~13 ~117 glass
setblock ~-15 ~15 ~120 glowstone
fill ~-22 ~9 ~120 ~-22 ~11 ~121 air
fill ~-22 ~12 ~120 ~-22 ~12 ~121 gold_block
fill ~-38 ~8 ~126 ~-23 ~16 ~133 quartz_block
fill ~-37 ~9 ~127 ~-24 ~15 ~132 air
fill ~-37 ~8 ~127 ~-24 ~8 ~132 blue_wool
fill ~-32 ~9 ~131 ~-30 ~9 ~132 white_wool
fill ~-32 ~9 ~132 ~-30 ~10 ~132 gold_block
fill ~-35 ~10 ~126 ~-26 ~13 ~126 glass
setblock ~-31 ~15 ~129 glowstone
fill ~-38 ~9 ~129 ~-38 ~11 ~130 air
fill ~-38 ~12 ~129 ~-38 ~12 ~130 gold_block
fill ~-22 ~8 ~126 ~-7 ~16 ~133 quartz_block
fill ~-21 ~9 ~127 ~-8 ~15 ~132 air
fill ~-21 ~8 ~127 ~-8 ~8 ~132 yellow_wool
fill ~-16 ~9 ~131 ~-14 ~9 ~132 white_wool
fill ~-16 ~9 ~132 ~-14 ~10 ~132 gold_block
fill ~-19 ~10 ~126 ~-10 ~13 ~126 glass
setblock ~-15 ~15 ~129 glowstone
fill ~-22 ~9 ~129 ~-22 ~11 ~130 air
fill ~-22 ~12 ~129 ~-22 ~12 ~130 gold_block
fill ~-38 ~8 ~135 ~-23 ~16 ~142 quartz_block
fill ~-37 ~9 ~136 ~-24 ~15 ~141 air
fill ~-37 ~8 ~136 ~-24 ~8 ~141 cyan_wool
fill ~-32 ~9 ~140 ~-30 ~9 ~141 white_wool
fill ~-32 ~9 ~141 ~-30 ~10 ~141 gold_block
fill ~-35 ~10 ~135 ~-26 ~13 ~135 glass
setblock ~-31 ~15 ~138 glowstone
fill ~-38 ~9 ~138 ~-38 ~11 ~139 air
fill ~-38 ~12 ~138 ~-38 ~12 ~139 gold_block
fill ~-22 ~8 ~135 ~-7 ~16 ~142 quartz_block
fill ~-21 ~9 ~136 ~-8 ~15 ~141 air
fill ~-21 ~8 ~136 ~-8 ~8 ~141 purple_wool
fill ~-16 ~9 ~140 ~-14 ~9 ~141 white_wool
fill ~-16 ~9 ~141 ~-14 ~10 ~141 gold_block
fill ~-19 ~10 ~135 ~-10 ~13 ~135 glass
setblock ~-15 ~15 ~138 glowstone
fill ~-22 ~9 ~138 ~-22 ~11 ~139 air
fill ~-22 ~12 ~138 ~-22 ~12 ~139 gold_block
fill ~-38 ~8 ~144 ~-23 ~16 ~151 quartz_block
fill ~-37 ~9 ~145 ~-24 ~15 ~150 air
fill ~-37 ~8 ~145 ~-24 ~8 ~150 pink_wool
fill ~-32 ~9 ~149 ~-30 ~9 ~150 white_wool
fill ~-32 ~9 ~150 ~-30 ~10 ~150 gold_block
fill ~-35 ~10 ~144 ~-26 ~13 ~144 glass
setblock ~-31 ~15 ~147 glowstone
fill ~-38 ~9 ~147 ~-38 ~11 ~148 air
fill ~-38 ~12 ~147 ~-38 ~12 ~148 gold_block
fill ~-22 ~8 ~144 ~-7 ~16 ~151 quartz_block
fill ~-21 ~9 ~145 ~-8 ~15 ~150 air
fill ~-21 ~8 ~145 ~-8 ~8 ~150 magenta_wool
fill ~-16 ~9 ~149 ~-14 ~9 ~150 white_wool
fill ~-16 ~9 ~150 ~-14 ~10 ~150 gold_block
fill ~-19 ~10 ~144 ~-10 ~13 ~144 glass
setblock ~-15 ~15 ~147 glowstone
fill ~-22 ~9 ~147 ~-22 ~11 ~148 air
fill ~-22 ~12 ~147 ~-22 ~12 ~148 gold_block
fill ~-40 ~16 ~105 ~-5 ~16 ~155 quartz_block
fill ~-25 ~1 ~105 ~-21 ~4 ~105 air
fill ~-25 ~5 ~105 ~-21 ~5 ~105 gold_block
# --- East Guest House (10 bedrooms) ---
fill ~145 ~-1 ~105 ~180 ~-1 ~155 quartz_block
fill ~145 ~0 ~105 ~180 ~0 ~155 dark_oak_planks
fill ~145 ~1 ~105 ~180 ~8 ~155 quartz_block
fill ~147 ~1 ~107 ~178 ~7 ~153 air
fill ~145 ~1 ~105 ~180 ~1 ~105 gold_block
fill ~145 ~1 ~155 ~180 ~1 ~155 gold_block
fill ~145 ~2 ~109 ~145 ~6 ~113 glass
fill ~180 ~2 ~109 ~180 ~6 ~113 glass
fill ~145 ~2 ~117 ~145 ~6 ~121 glass
fill ~180 ~2 ~117 ~180 ~6 ~121 glass
fill ~145 ~2 ~125 ~145 ~6 ~129 glass
fill ~180 ~2 ~125 ~180 ~6 ~129 glass
fill ~145 ~2 ~133 ~145 ~6 ~137 glass
fill ~180 ~2 ~133 ~180 ~6 ~137 glass
fill ~145 ~2 ~141 ~145 ~6 ~145 glass
fill ~180 ~2 ~141 ~180 ~6 ~145 glass
fill ~145 ~2 ~149 ~145 ~6 ~153 glass
fill ~180 ~2 ~149 ~180 ~6 ~153 glass
fill ~147 ~0 ~108 ~162 ~8 ~115 quartz_block
fill ~148 ~1 ~109 ~161 ~7 ~114 air
fill ~148 ~0 ~109 ~161 ~0 ~114 white_wool
fill ~153 ~1 ~113 ~155 ~1 ~114 white_wool
fill ~153 ~1 ~114 ~155 ~2 ~114 gold_block
fill ~150 ~2 ~108 ~159 ~5 ~108 glass
setblock ~154 ~7 ~111 glowstone
fill ~147 ~1 ~111 ~147 ~3 ~112 air
fill ~147 ~4 ~111 ~147 ~4 ~112 gold_block
fill ~163 ~0 ~108 ~178 ~8 ~115 quartz_block
fill ~164 ~1 ~109 ~177 ~7 ~114 air
fill ~164 ~0 ~109 ~177 ~0 ~114 orange_wool
fill ~169 ~1 ~113 ~171 ~1 ~114 white_wool
fill ~169 ~1 ~114 ~171 ~2 ~114 gold_block
fill ~166 ~2 ~108 ~175 ~5 ~108 glass
setblock ~170 ~7 ~111 glowstone
fill ~163 ~1 ~111 ~163 ~3 ~112 air
fill ~163 ~4 ~111 ~163 ~4 ~112 gold_block
fill ~147 ~0 ~117 ~162 ~8 ~124 quartz_block
fill ~148 ~1 ~118 ~161 ~7 ~123 air
fill ~148 ~0 ~118 ~161 ~0 ~123 red_wool
fill ~153 ~1 ~122 ~155 ~1 ~123 white_wool
fill ~153 ~1 ~123 ~155 ~2 ~123 gold_block
fill ~150 ~2 ~117 ~159 ~5 ~117 glass
setblock ~154 ~7 ~120 glowstone
fill ~147 ~1 ~120 ~147 ~3 ~121 air
fill ~147 ~4 ~120 ~147 ~4 ~121 gold_block
fill ~163 ~0 ~117 ~178 ~8 ~124 quartz_block
fill ~164 ~1 ~118 ~177 ~7 ~123 air
fill ~164 ~0 ~118 ~177 ~0 ~123 lime_wool
fill ~169 ~1 ~122 ~171 ~1 ~123 white_wool
fill ~169 ~1 ~123 ~171 ~2 ~123 gold_block
fill ~166 ~2 ~117 ~175 ~5 ~117 glass
setblock ~170 ~7 ~120 glowstone
fill ~163 ~1 ~120 ~163 ~3 ~121 air
fill ~163 ~4 ~120 ~163 ~4 ~121 gold_block
fill ~147 ~0 ~126 ~162 ~8 ~133 quartz_block
fill ~148 ~1 ~127 ~161 ~7 ~132 air
fill ~148 ~0 ~127 ~161 ~0 ~132 blue_wool
fill ~153 ~1 ~131 ~155 ~1 ~132 white_wool
fill ~153 ~1 ~132 ~155 ~2 ~132 gold_block
fill ~150 ~2 ~126 ~159 ~5 ~126 glass
setblock ~154 ~7 ~129 glowstone
fill ~147 ~1 ~129 ~147 ~3 ~130 air
fill ~147 ~4 ~129 ~147 ~4 ~130 gold_block
fill ~163 ~0 ~126 ~178 ~8 ~133 quartz_block
fill ~164 ~1 ~127 ~177 ~7 ~132 air
fill ~164 ~0 ~127 ~177 ~0 ~132 yellow_wool
fill ~169 ~1 ~131 ~171 ~1 ~132 white_wool
fill ~169 ~1 ~132 ~171 ~2 ~132 gold_block
fill ~166 ~2 ~126 ~175 ~5 ~126 glass
setblock ~170 ~7 ~129 glowstone
fill ~163 ~1 ~129 ~163 ~3 ~130 air
fill ~163 ~4 ~129 ~163 ~4 ~130 gold_block
fill ~147 ~0 ~135 ~162 ~8 ~142 quartz_block
fill ~148 ~1 ~136 ~161 ~7 ~141 air
fill ~148 ~0 ~136 ~161 ~0 ~141 cyan_wool
fill ~153 ~1 ~140 ~155 ~1 ~141 white_wool
fill ~153 ~1 ~141 ~155 ~2 ~141 gold_block
fill ~150 ~2 ~135 ~159 ~5 ~135 glass
setblock ~154 ~7 ~138 glowstone
fill ~147 ~1 ~138 ~147 ~3 ~139 air
fill ~147 ~4 ~138 ~147 ~4 ~139 gold_block
fill ~163 ~0 ~135 ~178 ~8 ~142 quartz_block
fill ~164 ~1 ~136 ~177 ~7 ~141 air
fill ~164 ~0 ~136 ~177 ~0 ~141 purple_wool
fill ~169 ~1 ~140 ~171 ~1 ~141 white_wool
fill ~169 ~1 ~141 ~171 ~2 ~141 gold_block
fill ~166 ~2 ~135 ~175 ~5 ~135 glass
setblock ~170 ~7 ~138 glowstone
fill ~163 ~1 ~138 ~163 ~3 ~139 air
fill ~163 ~4 ~138 ~163 ~4 ~139 gold_block
fill ~147 ~0 ~144 ~162 ~8 ~151 quartz_block
fill ~148 ~1 ~145 ~161 ~7 ~150 air
fill ~148 ~0 ~145 ~161 ~0 ~150 pink_wool
fill ~153 ~1 ~149 ~155 ~1 ~150 white_wool
fill ~153 ~1 ~150 ~155 ~2 ~150 gold_block
fill ~150 ~2 ~144 ~159 ~5 ~144 glass
setblock ~154 ~7 ~147 glowstone
fill ~147 ~1 ~147 ~147 ~3 ~148 air
fill ~147 ~4 ~147 ~147 ~4 ~148 gold_block
fill ~163 ~0 ~144 ~178 ~8 ~151 quartz_block
fill ~164 ~1 ~145 ~177 ~7 ~150 air
fill ~164 ~0 ~145 ~177 ~0 ~150 magenta_wool
fill ~169 ~1 ~149 ~171 ~1 ~150 white_wool
fill ~169 ~1 ~150 ~171 ~2 ~150 gold_block
fill ~166 ~2 ~144 ~175 ~5 ~144 glass
setblock ~170 ~7 ~147 glowstone
fill ~163 ~1 ~147 ~163 ~3 ~148 air
fill ~163 ~4 ~147 ~163 ~4 ~148 gold_block
fill ~145 ~8 ~105 ~180 ~8 ~155 dark_oak_planks
fill ~145 ~9 ~105 ~180 ~16 ~155 quartz_block
fill ~147 ~9 ~107 ~178 ~15 ~153 air
fill ~145 ~9 ~105 ~180 ~9 ~105 gold_block
fill ~145 ~9 ~155 ~180 ~9 ~155 gold_block
fill ~145 ~10 ~109 ~145 ~14 ~113 glass
fill ~180 ~10 ~109 ~180 ~14 ~113 glass
fill ~145 ~10 ~117 ~145 ~14 ~121 glass
fill ~180 ~10 ~117 ~180 ~14 ~121 glass
fill ~145 ~10 ~125 ~145 ~14 ~129 glass
fill ~180 ~10 ~125 ~180 ~14 ~129 glass
fill ~145 ~10 ~133 ~145 ~14 ~137 glass
fill ~180 ~10 ~133 ~180 ~14 ~137 glass
fill ~145 ~10 ~141 ~145 ~14 ~145 glass
fill ~180 ~10 ~141 ~180 ~14 ~145 glass
fill ~145 ~10 ~149 ~145 ~14 ~153 glass
fill ~180 ~10 ~149 ~180 ~14 ~153 glass
fill ~147 ~8 ~108 ~162 ~16 ~115 quartz_block
fill ~148 ~9 ~109 ~161 ~15 ~114 air
fill ~148 ~8 ~109 ~161 ~8 ~114 white_wool
fill ~153 ~9 ~113 ~155 ~9 ~114 white_wool
fill ~153 ~9 ~114 ~155 ~10 ~114 gold_block
fill ~150 ~10 ~108 ~159 ~13 ~108 glass
setblock ~154 ~15 ~111 glowstone
fill ~147 ~9 ~111 ~147 ~11 ~112 air
fill ~147 ~12 ~111 ~147 ~12 ~112 gold_block
fill ~163 ~8 ~108 ~178 ~16 ~115 quartz_block
fill ~164 ~9 ~109 ~177 ~15 ~114 air
fill ~164 ~8 ~109 ~177 ~8 ~114 orange_wool
fill ~169 ~9 ~113 ~171 ~9 ~114 white_wool
fill ~169 ~9 ~114 ~171 ~10 ~114 gold_block
fill ~166 ~10 ~108 ~175 ~13 ~108 glass
setblock ~170 ~15 ~111 glowstone
fill ~163 ~9 ~111 ~163 ~11 ~112 air
fill ~163 ~12 ~111 ~163 ~12 ~112 gold_block
fill ~147 ~8 ~117 ~162 ~16 ~124 quartz_block
fill ~148 ~9 ~118 ~161 ~15 ~123 air
fill ~148 ~8 ~118 ~161 ~8 ~123 red_wool
fill ~153 ~9 ~122 ~155 ~9 ~123 white_wool
fill ~153 ~9 ~123 ~155 ~10 ~123 gold_block
fill ~150 ~10 ~117 ~159 ~13 ~117 glass
setblock ~154 ~15 ~120 glowstone
fill ~147 ~9 ~120 ~147 ~11 ~121 air
fill ~147 ~12 ~120 ~147 ~12 ~121 gold_block
fill ~163 ~8 ~117 ~178 ~16 ~124 quartz_block
fill ~164 ~9 ~118 ~177 ~15 ~123 air
fill ~164 ~8 ~118 ~177 ~8 ~123 lime_wool
fill ~169 ~9 ~122 ~171 ~9 ~123 white_wool
fill ~169 ~9 ~123 ~171 ~10 ~123 gold_block
fill ~166 ~10 ~117 ~175 ~13 ~117 glass
setblock ~170 ~15 ~120 glowstone
fill ~163 ~9 ~120 ~163 ~11 ~121 air
fill ~163 ~12 ~120 ~163 ~12 ~121 gold_block
fill ~147 ~8 ~126 ~162 ~16 ~133 quartz_block
fill ~148 ~9 ~127 ~161 ~15 ~132 air
fill ~148 ~8 ~127 ~161 ~8 ~132 blue_wool
fill ~153 ~9 ~131 ~155 ~9 ~132 white_wool
fill ~153 ~9 ~132 ~155 ~10 ~132 gold_block
fill ~150 ~10 ~126 ~159 ~13 ~126 glass
setblock ~154 ~15 ~129 glowstone
fill ~147 ~9 ~129 ~147 ~11 ~130 air
fill ~147 ~12 ~129 ~147 ~12 ~130 gold_block
fill ~163 ~8 ~126 ~178 ~16 ~133 quartz_block
fill ~164 ~9 ~127 ~177 ~15 ~132 air
fill ~164 ~8 ~127 ~177 ~8 ~132 yellow_wool
fill ~169 ~9 ~131 ~171 ~9 ~132 white_wool
fill ~169 ~9 ~132 ~171 ~10 ~132 gold_block
fill ~166 ~10 ~126 ~175 ~13 ~126 glass
setblock ~170 ~15 ~129 glowstone
fill ~163 ~9 ~129 ~163 ~11 ~130 air
fill ~163 ~12 ~129 ~163 ~12 ~130 gold_block
fill ~147 ~8 ~135 ~162 ~16 ~142 quartz_block
fill ~148 ~9 ~136 ~161 ~15 ~141 air
fill ~148 ~8 ~136 ~161 ~8 ~141 cyan_wool
fill ~153 ~9 ~140 ~155 ~9 ~141 white_wool
fill ~153 ~9 ~141 ~155 ~10 ~141 gold_block
fill ~150 ~10 ~135 ~159 ~13 ~135 glass
setblock ~154 ~15 ~138 glowstone
fill ~147 ~9 ~138 ~147 ~11 ~139 air
fill ~147 ~12 ~138 ~147 ~12 ~139 gold_block
fill ~163 ~8 ~135 ~178 ~16 ~142 quartz_block
fill ~164 ~9 ~136 ~177 ~15 ~141 air
fill ~164 ~8 ~136 ~177 ~8 ~141 purple_wool
fill ~169 ~9 ~140 ~171 ~9 ~141 white_wool
fill ~169 ~9 ~141 ~171 ~10 ~141 gold_block
fill ~166 ~10 ~135 ~175 ~13 ~135 glass
setblock ~170 ~15 ~138 glowstone
fill ~163 ~9 ~138 ~163 ~11 ~139 air
fill ~163 ~12 ~138 ~163 ~12 ~139 gold_block
fill ~147 ~8 ~144 ~162 ~16 ~151 quartz_block
fill ~148 ~9 ~145 ~161 ~15 ~150 air
fill ~148 ~8 ~145 ~161 ~8 ~150 pink_wool
fill ~153 ~9 ~149 ~155 ~9 ~150 white_wool
fill ~153 ~9 ~150 ~155 ~10 ~150 gold_block
fill ~150 ~10 ~144 ~159 ~13 ~144 glass
setblock ~154 ~15 ~147 glowstone
fill ~147 ~9 ~147 ~147 ~11 ~148 air
fill ~147 ~12 ~147 ~147 ~12 ~148 gold_block
fill ~163 ~8 ~144 ~178 ~16 ~151 quartz_block
fill ~164 ~9 ~145 ~177 ~15 ~150 air
fill ~164 ~8 ~145 ~177 ~8 ~150 magenta_wool
fill ~169 ~9 ~149 ~171 ~9 ~150 white_wool
fill ~169 ~9 ~150 ~171 ~10 ~150 gold_block
fill ~166 ~10 ~144 ~175 ~13 ~144 glass
setblock ~170 ~15 ~147 glowstone
fill ~163 ~9 ~147 ~163 ~11 ~148 air
fill ~163 ~12 ~147 ~163 ~12 ~148 gold_block
fill ~145 ~16 ~105 ~180 ~16 ~155 quartz_block
fill ~160 ~1 ~105 ~164 ~4 ~105 air
fill ~160 ~5 ~105 ~164 ~5 ~105 gold_block
function bezos_gardens
