# Phase 5a: City ground + Towers 1-3
fill ~90 ~0 ~-50 ~120 ~0 ~-20 gray_concrete
fill ~90 ~0 ~-19 ~120 ~0 ~11 gray_concrete
fill ~90 ~0 ~12 ~120 ~0 ~15 gray_concrete
fill ~121 ~0 ~-50 ~151 ~0 ~-20 gray_concrete
fill ~121 ~0 ~-19 ~151 ~0 ~11 gray_concrete
fill ~121 ~0 ~12 ~151 ~0 ~15 gray_concrete
fill ~152 ~0 ~-50 ~170 ~0 ~-20 gray_concrete
fill ~152 ~0 ~-19 ~170 ~0 ~11 gray_concrete
fill ~152 ~0 ~12 ~170 ~0 ~15 gray_concrete
fill ~90 ~0 ~-32 ~120 ~0 ~-28 black_concrete
fill ~121 ~0 ~-32 ~151 ~0 ~-28 black_concrete
fill ~152 ~0 ~-32 ~170 ~0 ~-28 black_concrete
fill ~130 ~0 ~-50 ~134 ~0 ~-20 black_concrete
fill ~130 ~0 ~-19 ~134 ~0 ~11 black_concrete
fill ~130 ~0 ~12 ~134 ~0 ~15 black_concrete
fill ~90 ~0 ~-30 ~92 ~0 ~-30 yellow_concrete
fill ~96 ~0 ~-30 ~98 ~0 ~-30 yellow_concrete
fill ~102 ~0 ~-30 ~104 ~0 ~-30 yellow_concrete
fill ~108 ~0 ~-30 ~110 ~0 ~-30 yellow_concrete
fill ~114 ~0 ~-30 ~116 ~0 ~-30 yellow_concrete
fill ~120 ~0 ~-30 ~122 ~0 ~-30 yellow_concrete
fill ~126 ~0 ~-30 ~128 ~0 ~-30 yellow_concrete
fill ~132 ~0 ~-30 ~134 ~0 ~-30 yellow_concrete
fill ~138 ~0 ~-30 ~140 ~0 ~-30 yellow_concrete
fill ~144 ~0 ~-30 ~146 ~0 ~-30 yellow_concrete
fill ~150 ~0 ~-30 ~152 ~0 ~-30 yellow_concrete
fill ~156 ~0 ~-30 ~158 ~0 ~-30 yellow_concrete
fill ~162 ~0 ~-30 ~164 ~0 ~-30 yellow_concrete
fill ~168 ~0 ~-30 ~170 ~0 ~-30 yellow_concrete
# --- Tower Alpha (14x14, 70 tall) ---
fill ~100 ~-1 ~-30 ~114 ~-1 ~-16 stone_bricks
fill ~100 ~0 ~-30 ~114 ~0 ~-16 polished_deepslate
fill ~100 ~1 ~-30 ~114 ~4 ~-30 iron_block
fill ~100 ~1 ~-16 ~114 ~4 ~-16 iron_block
fill ~100 ~1 ~-30 ~100 ~4 ~-16 iron_block
fill ~114 ~1 ~-30 ~114 ~4 ~-16 iron_block
fill ~101 ~1 ~-29 ~113 ~4 ~-17 air
fill ~102 ~2 ~-30 ~104 ~3 ~-30 glass
fill ~102 ~2 ~-16 ~104 ~3 ~-16 glass
fill ~106 ~2 ~-30 ~108 ~3 ~-30 glass
fill ~106 ~2 ~-16 ~108 ~3 ~-16 glass
fill ~110 ~2 ~-30 ~112 ~3 ~-30 glass
fill ~110 ~2 ~-16 ~112 ~3 ~-16 glass
fill ~100 ~2 ~-28 ~100 ~3 ~-26 glass
fill ~114 ~2 ~-28 ~114 ~3 ~-26 glass
fill ~100 ~2 ~-24 ~100 ~3 ~-22 glass
fill ~114 ~2 ~-24 ~114 ~3 ~-22 glass
fill ~100 ~2 ~-20 ~100 ~3 ~-18 glass
fill ~114 ~2 ~-20 ~114 ~3 ~-18 glass
fill ~100 ~5 ~-30 ~114 ~5 ~-30 iron_block
fill ~100 ~5 ~-16 ~114 ~5 ~-16 iron_block
fill ~100 ~5 ~-29 ~100 ~5 ~-17 iron_block
fill ~114 ~5 ~-29 ~114 ~5 ~-17 iron_block
setblock ~107 ~0 ~-23 glowstone
fill ~100 ~5 ~-30 ~114 ~5 ~-16 polished_deepslate
fill ~100 ~6 ~-30 ~114 ~9 ~-30 iron_block
fill ~100 ~6 ~-16 ~114 ~9 ~-16 iron_block
fill ~100 ~6 ~-30 ~100 ~9 ~-16 iron_block
fill ~114 ~6 ~-30 ~114 ~9 ~-16 iron_block
fill ~101 ~6 ~-29 ~113 ~9 ~-17 air
fill ~102 ~7 ~-30 ~104 ~8 ~-30 glass
fill ~102 ~7 ~-16 ~104 ~8 ~-16 glass
fill ~106 ~7 ~-30 ~108 ~8 ~-30 glass
fill ~106 ~7 ~-16 ~108 ~8 ~-16 glass
fill ~110 ~7 ~-30 ~112 ~8 ~-30 glass
fill ~110 ~7 ~-16 ~112 ~8 ~-16 glass
fill ~100 ~7 ~-28 ~100 ~8 ~-26 glass
fill ~114 ~7 ~-28 ~114 ~8 ~-26 glass
fill ~100 ~7 ~-24 ~100 ~8 ~-22 glass
fill ~114 ~7 ~-24 ~114 ~8 ~-22 glass
fill ~100 ~7 ~-20 ~100 ~8 ~-18 glass
fill ~114 ~7 ~-20 ~114 ~8 ~-18 glass
fill ~100 ~10 ~-30 ~114 ~10 ~-30 iron_block
fill ~100 ~10 ~-16 ~114 ~10 ~-16 iron_block
fill ~100 ~10 ~-29 ~100 ~10 ~-17 iron_block
fill ~114 ~10 ~-29 ~114 ~10 ~-17 iron_block
setblock ~107 ~5 ~-23 glowstone
fill ~100 ~10 ~-30 ~114 ~10 ~-16 polished_deepslate
fill ~100 ~11 ~-30 ~114 ~14 ~-30 iron_block
fill ~100 ~11 ~-16 ~114 ~14 ~-16 iron_block
fill ~100 ~11 ~-30 ~100 ~14 ~-16 iron_block
fill ~114 ~11 ~-30 ~114 ~14 ~-16 iron_block
fill ~101 ~11 ~-29 ~113 ~14 ~-17 air
fill ~102 ~12 ~-30 ~104 ~13 ~-30 glass
fill ~102 ~12 ~-16 ~104 ~13 ~-16 glass
fill ~106 ~12 ~-30 ~108 ~13 ~-30 glass
fill ~106 ~12 ~-16 ~108 ~13 ~-16 glass
fill ~110 ~12 ~-30 ~112 ~13 ~-30 glass
fill ~110 ~12 ~-16 ~112 ~13 ~-16 glass
fill ~100 ~12 ~-28 ~100 ~13 ~-26 glass
fill ~114 ~12 ~-28 ~114 ~13 ~-26 glass
fill ~100 ~12 ~-24 ~100 ~13 ~-22 glass
fill ~114 ~12 ~-24 ~114 ~13 ~-22 glass
fill ~100 ~12 ~-20 ~100 ~13 ~-18 glass
fill ~114 ~12 ~-20 ~114 ~13 ~-18 glass
fill ~100 ~15 ~-30 ~114 ~15 ~-30 iron_block
fill ~100 ~15 ~-16 ~114 ~15 ~-16 iron_block
fill ~100 ~15 ~-29 ~100 ~15 ~-17 iron_block
fill ~114 ~15 ~-29 ~114 ~15 ~-17 iron_block
setblock ~107 ~10 ~-23 glowstone
fill ~100 ~15 ~-30 ~114 ~15 ~-16 polished_deepslate
fill ~100 ~16 ~-30 ~114 ~19 ~-30 iron_block
fill ~100 ~16 ~-16 ~114 ~19 ~-16 iron_block
fill ~100 ~16 ~-30 ~100 ~19 ~-16 iron_block
fill ~114 ~16 ~-30 ~114 ~19 ~-16 iron_block
fill ~101 ~16 ~-29 ~113 ~19 ~-17 air
fill ~102 ~17 ~-30 ~104 ~18 ~-30 glass
fill ~102 ~17 ~-16 ~104 ~18 ~-16 glass
fill ~106 ~17 ~-30 ~108 ~18 ~-30 glass
fill ~106 ~17 ~-16 ~108 ~18 ~-16 glass
fill ~110 ~17 ~-30 ~112 ~18 ~-30 glass
fill ~110 ~17 ~-16 ~112 ~18 ~-16 glass
fill ~100 ~17 ~-28 ~100 ~18 ~-26 glass
fill ~114 ~17 ~-28 ~114 ~18 ~-26 glass
fill ~100 ~17 ~-24 ~100 ~18 ~-22 glass
fill ~114 ~17 ~-24 ~114 ~18 ~-22 glass
fill ~100 ~17 ~-20 ~100 ~18 ~-18 glass
fill ~114 ~17 ~-20 ~114 ~18 ~-18 glass
fill ~100 ~20 ~-30 ~114 ~20 ~-30 iron_block
fill ~100 ~20 ~-16 ~114 ~20 ~-16 iron_block
fill ~100 ~20 ~-29 ~100 ~20 ~-17 iron_block
fill ~114 ~20 ~-29 ~114 ~20 ~-17 iron_block
setblock ~107 ~15 ~-23 glowstone
fill ~100 ~20 ~-30 ~114 ~20 ~-16 polished_deepslate
fill ~100 ~21 ~-30 ~114 ~24 ~-30 iron_block
fill ~100 ~21 ~-16 ~114 ~24 ~-16 iron_block
fill ~100 ~21 ~-30 ~100 ~24 ~-16 iron_block
fill ~114 ~21 ~-30 ~114 ~24 ~-16 iron_block
fill ~101 ~21 ~-29 ~113 ~24 ~-17 air
fill ~102 ~22 ~-30 ~104 ~23 ~-30 glass
fill ~102 ~22 ~-16 ~104 ~23 ~-16 glass
fill ~106 ~22 ~-30 ~108 ~23 ~-30 glass
fill ~106 ~22 ~-16 ~108 ~23 ~-16 glass
fill ~110 ~22 ~-30 ~112 ~23 ~-30 glass
fill ~110 ~22 ~-16 ~112 ~23 ~-16 glass
fill ~100 ~22 ~-28 ~100 ~23 ~-26 glass
fill ~114 ~22 ~-28 ~114 ~23 ~-26 glass
fill ~100 ~22 ~-24 ~100 ~23 ~-22 glass
fill ~114 ~22 ~-24 ~114 ~23 ~-22 glass
fill ~100 ~22 ~-20 ~100 ~23 ~-18 glass
fill ~114 ~22 ~-20 ~114 ~23 ~-18 glass
fill ~100 ~25 ~-30 ~114 ~25 ~-30 iron_block
fill ~100 ~25 ~-16 ~114 ~25 ~-16 iron_block
fill ~100 ~25 ~-29 ~100 ~25 ~-17 iron_block
fill ~114 ~25 ~-29 ~114 ~25 ~-17 iron_block
setblock ~107 ~20 ~-23 glowstone
fill ~100 ~25 ~-30 ~114 ~25 ~-16 polished_deepslate
fill ~100 ~26 ~-30 ~114 ~29 ~-30 iron_block
fill ~100 ~26 ~-16 ~114 ~29 ~-16 iron_block
fill ~100 ~26 ~-30 ~100 ~29 ~-16 iron_block
fill ~114 ~26 ~-30 ~114 ~29 ~-16 iron_block
fill ~101 ~26 ~-29 ~113 ~29 ~-17 air
fill ~102 ~27 ~-30 ~104 ~28 ~-30 glass
fill ~102 ~27 ~-16 ~104 ~28 ~-16 glass
fill ~106 ~27 ~-30 ~108 ~28 ~-30 glass
fill ~106 ~27 ~-16 ~108 ~28 ~-16 glass
fill ~110 ~27 ~-30 ~112 ~28 ~-30 glass
fill ~110 ~27 ~-16 ~112 ~28 ~-16 glass
fill ~100 ~27 ~-28 ~100 ~28 ~-26 glass
fill ~114 ~27 ~-28 ~114 ~28 ~-26 glass
fill ~100 ~27 ~-24 ~100 ~28 ~-22 glass
fill ~114 ~27 ~-24 ~114 ~28 ~-22 glass
fill ~100 ~27 ~-20 ~100 ~28 ~-18 glass
fill ~114 ~27 ~-20 ~114 ~28 ~-18 glass
fill ~100 ~30 ~-30 ~114 ~30 ~-30 iron_block
fill ~100 ~30 ~-16 ~114 ~30 ~-16 iron_block
fill ~100 ~30 ~-29 ~100 ~30 ~-17 iron_block
fill ~114 ~30 ~-29 ~114 ~30 ~-17 iron_block
setblock ~107 ~25 ~-23 glowstone
fill ~100 ~30 ~-30 ~114 ~30 ~-16 polished_deepslate
fill ~100 ~31 ~-30 ~114 ~34 ~-30 iron_block
fill ~100 ~31 ~-16 ~114 ~34 ~-16 iron_block
fill ~100 ~31 ~-30 ~100 ~34 ~-16 iron_block
fill ~114 ~31 ~-30 ~114 ~34 ~-16 iron_block
fill ~101 ~31 ~-29 ~113 ~34 ~-17 air
fill ~102 ~32 ~-30 ~104 ~33 ~-30 glass
fill ~102 ~32 ~-16 ~104 ~33 ~-16 glass
fill ~106 ~32 ~-30 ~108 ~33 ~-30 glass
fill ~106 ~32 ~-16 ~108 ~33 ~-16 glass
fill ~110 ~32 ~-30 ~112 ~33 ~-30 glass
fill ~110 ~32 ~-16 ~112 ~33 ~-16 glass
fill ~100 ~32 ~-28 ~100 ~33 ~-26 glass
fill ~114 ~32 ~-28 ~114 ~33 ~-26 glass
fill ~100 ~32 ~-24 ~100 ~33 ~-22 glass
fill ~114 ~32 ~-24 ~114 ~33 ~-22 glass
fill ~100 ~32 ~-20 ~100 ~33 ~-18 glass
fill ~114 ~32 ~-20 ~114 ~33 ~-18 glass
fill ~100 ~35 ~-30 ~114 ~35 ~-30 iron_block
fill ~100 ~35 ~-16 ~114 ~35 ~-16 iron_block
fill ~100 ~35 ~-29 ~100 ~35 ~-17 iron_block
fill ~114 ~35 ~-29 ~114 ~35 ~-17 iron_block
setblock ~107 ~30 ~-23 glowstone
fill ~100 ~35 ~-30 ~114 ~35 ~-16 polished_deepslate
fill ~100 ~36 ~-30 ~114 ~39 ~-30 iron_block
fill ~100 ~36 ~-16 ~114 ~39 ~-16 iron_block
fill ~100 ~36 ~-30 ~100 ~39 ~-16 iron_block
fill ~114 ~36 ~-30 ~114 ~39 ~-16 iron_block
fill ~101 ~36 ~-29 ~113 ~39 ~-17 air
fill ~102 ~37 ~-30 ~104 ~38 ~-30 glass
fill ~102 ~37 ~-16 ~104 ~38 ~-16 glass
fill ~106 ~37 ~-30 ~108 ~38 ~-30 glass
fill ~106 ~37 ~-16 ~108 ~38 ~-16 glass
fill ~110 ~37 ~-30 ~112 ~38 ~-30 glass
fill ~110 ~37 ~-16 ~112 ~38 ~-16 glass
fill ~100 ~37 ~-28 ~100 ~38 ~-26 glass
fill ~114 ~37 ~-28 ~114 ~38 ~-26 glass
fill ~100 ~37 ~-24 ~100 ~38 ~-22 glass
fill ~114 ~37 ~-24 ~114 ~38 ~-22 glass
fill ~100 ~37 ~-20 ~100 ~38 ~-18 glass
fill ~114 ~37 ~-20 ~114 ~38 ~-18 glass
fill ~100 ~40 ~-30 ~114 ~40 ~-30 iron_block
fill ~100 ~40 ~-16 ~114 ~40 ~-16 iron_block
fill ~100 ~40 ~-29 ~100 ~40 ~-17 iron_block
fill ~114 ~40 ~-29 ~114 ~40 ~-17 iron_block
setblock ~107 ~35 ~-23 glowstone
fill ~100 ~40 ~-30 ~114 ~40 ~-16 polished_deepslate
fill ~100 ~41 ~-30 ~114 ~44 ~-30 iron_block
fill ~100 ~41 ~-16 ~114 ~44 ~-16 iron_block
fill ~100 ~41 ~-30 ~100 ~44 ~-16 iron_block
fill ~114 ~41 ~-30 ~114 ~44 ~-16 iron_block
fill ~101 ~41 ~-29 ~113 ~44 ~-17 air
fill ~102 ~42 ~-30 ~104 ~43 ~-30 glass
fill ~102 ~42 ~-16 ~104 ~43 ~-16 glass
fill ~106 ~42 ~-30 ~108 ~43 ~-30 glass
fill ~106 ~42 ~-16 ~108 ~43 ~-16 glass
fill ~110 ~42 ~-30 ~112 ~43 ~-30 glass
fill ~110 ~42 ~-16 ~112 ~43 ~-16 glass
fill ~100 ~42 ~-28 ~100 ~43 ~-26 glass
fill ~114 ~42 ~-28 ~114 ~43 ~-26 glass
fill ~100 ~42 ~-24 ~100 ~43 ~-22 glass
fill ~114 ~42 ~-24 ~114 ~43 ~-22 glass
fill ~100 ~42 ~-20 ~100 ~43 ~-18 glass
fill ~114 ~42 ~-20 ~114 ~43 ~-18 glass
fill ~100 ~45 ~-30 ~114 ~45 ~-30 iron_block
fill ~100 ~45 ~-16 ~114 ~45 ~-16 iron_block
fill ~100 ~45 ~-29 ~100 ~45 ~-17 iron_block
fill ~114 ~45 ~-29 ~114 ~45 ~-17 iron_block
setblock ~107 ~40 ~-23 glowstone
fill ~100 ~45 ~-30 ~114 ~45 ~-16 polished_deepslate
fill ~100 ~46 ~-30 ~114 ~49 ~-30 iron_block
fill ~100 ~46 ~-16 ~114 ~49 ~-16 iron_block
fill ~100 ~46 ~-30 ~100 ~49 ~-16 iron_block
fill ~114 ~46 ~-30 ~114 ~49 ~-16 iron_block
fill ~101 ~46 ~-29 ~113 ~49 ~-17 air
fill ~102 ~47 ~-30 ~104 ~48 ~-30 glass
fill ~102 ~47 ~-16 ~104 ~48 ~-16 glass
fill ~106 ~47 ~-30 ~108 ~48 ~-30 glass
fill ~106 ~47 ~-16 ~108 ~48 ~-16 glass
fill ~110 ~47 ~-30 ~112 ~48 ~-30 glass
fill ~110 ~47 ~-16 ~112 ~48 ~-16 glass
fill ~100 ~47 ~-28 ~100 ~48 ~-26 glass
fill ~114 ~47 ~-28 ~114 ~48 ~-26 glass
fill ~100 ~47 ~-24 ~100 ~48 ~-22 glass
fill ~114 ~47 ~-24 ~114 ~48 ~-22 glass
fill ~100 ~47 ~-20 ~100 ~48 ~-18 glass
fill ~114 ~47 ~-20 ~114 ~48 ~-18 glass
fill ~100 ~50 ~-30 ~114 ~50 ~-30 iron_block
fill ~100 ~50 ~-16 ~114 ~50 ~-16 iron_block
fill ~100 ~50 ~-29 ~100 ~50 ~-17 iron_block
fill ~114 ~50 ~-29 ~114 ~50 ~-17 iron_block
setblock ~107 ~45 ~-23 glowstone
fill ~100 ~50 ~-30 ~114 ~50 ~-16 polished_deepslate
fill ~100 ~51 ~-30 ~114 ~54 ~-30 iron_block
fill ~100 ~51 ~-16 ~114 ~54 ~-16 iron_block
fill ~100 ~51 ~-30 ~100 ~54 ~-16 iron_block
fill ~114 ~51 ~-30 ~114 ~54 ~-16 iron_block
fill ~101 ~51 ~-29 ~113 ~54 ~-17 air
fill ~102 ~52 ~-30 ~104 ~53 ~-30 glass
fill ~102 ~52 ~-16 ~104 ~53 ~-16 glass
fill ~106 ~52 ~-30 ~108 ~53 ~-30 glass
fill ~106 ~52 ~-16 ~108 ~53 ~-16 glass
fill ~110 ~52 ~-30 ~112 ~53 ~-30 glass
fill ~110 ~52 ~-16 ~112 ~53 ~-16 glass
fill ~100 ~52 ~-28 ~100 ~53 ~-26 glass
fill ~114 ~52 ~-28 ~114 ~53 ~-26 glass
fill ~100 ~52 ~-24 ~100 ~53 ~-22 glass
fill ~114 ~52 ~-24 ~114 ~53 ~-22 glass
fill ~100 ~52 ~-20 ~100 ~53 ~-18 glass
fill ~114 ~52 ~-20 ~114 ~53 ~-18 glass
fill ~100 ~55 ~-30 ~114 ~55 ~-30 iron_block
fill ~100 ~55 ~-16 ~114 ~55 ~-16 iron_block
fill ~100 ~55 ~-29 ~100 ~55 ~-17 iron_block
fill ~114 ~55 ~-29 ~114 ~55 ~-17 iron_block
setblock ~107 ~50 ~-23 glowstone
fill ~100 ~55 ~-30 ~114 ~55 ~-16 polished_deepslate
fill ~100 ~56 ~-30 ~114 ~59 ~-30 iron_block
fill ~100 ~56 ~-16 ~114 ~59 ~-16 iron_block
fill ~100 ~56 ~-30 ~100 ~59 ~-16 iron_block
fill ~114 ~56 ~-30 ~114 ~59 ~-16 iron_block
fill ~101 ~56 ~-29 ~113 ~59 ~-17 air
fill ~102 ~57 ~-30 ~104 ~58 ~-30 glass
fill ~102 ~57 ~-16 ~104 ~58 ~-16 glass
fill ~106 ~57 ~-30 ~108 ~58 ~-30 glass
fill ~106 ~57 ~-16 ~108 ~58 ~-16 glass
fill ~110 ~57 ~-30 ~112 ~58 ~-30 glass
fill ~110 ~57 ~-16 ~112 ~58 ~-16 glass
fill ~100 ~57 ~-28 ~100 ~58 ~-26 glass
fill ~114 ~57 ~-28 ~114 ~58 ~-26 glass
fill ~100 ~57 ~-24 ~100 ~58 ~-22 glass
fill ~114 ~57 ~-24 ~114 ~58 ~-22 glass
fill ~100 ~57 ~-20 ~100 ~58 ~-18 glass
fill ~114 ~57 ~-20 ~114 ~58 ~-18 glass
fill ~100 ~60 ~-30 ~114 ~60 ~-30 iron_block
fill ~100 ~60 ~-16 ~114 ~60 ~-16 iron_block
fill ~100 ~60 ~-29 ~100 ~60 ~-17 iron_block
fill ~114 ~60 ~-29 ~114 ~60 ~-17 iron_block
setblock ~107 ~55 ~-23 glowstone
fill ~100 ~60 ~-30 ~114 ~60 ~-16 polished_deepslate
fill ~100 ~61 ~-30 ~114 ~64 ~-30 iron_block
fill ~100 ~61 ~-16 ~114 ~64 ~-16 iron_block
fill ~100 ~61 ~-30 ~100 ~64 ~-16 iron_block
fill ~114 ~61 ~-30 ~114 ~64 ~-16 iron_block
fill ~101 ~61 ~-29 ~113 ~64 ~-17 air
fill ~102 ~62 ~-30 ~104 ~63 ~-30 glass
fill ~102 ~62 ~-16 ~104 ~63 ~-16 glass
fill ~106 ~62 ~-30 ~108 ~63 ~-30 glass
fill ~106 ~62 ~-16 ~108 ~63 ~-16 glass
fill ~110 ~62 ~-30 ~112 ~63 ~-30 glass
fill ~110 ~62 ~-16 ~112 ~63 ~-16 glass
fill ~100 ~62 ~-28 ~100 ~63 ~-26 glass
fill ~114 ~62 ~-28 ~114 ~63 ~-26 glass
fill ~100 ~62 ~-24 ~100 ~63 ~-22 glass
fill ~114 ~62 ~-24 ~114 ~63 ~-22 glass
fill ~100 ~62 ~-20 ~100 ~63 ~-18 glass
fill ~114 ~62 ~-20 ~114 ~63 ~-18 glass
fill ~100 ~65 ~-30 ~114 ~65 ~-30 iron_block
fill ~100 ~65 ~-16 ~114 ~65 ~-16 iron_block
fill ~100 ~65 ~-29 ~100 ~65 ~-17 iron_block
fill ~114 ~65 ~-29 ~114 ~65 ~-17 iron_block
setblock ~107 ~60 ~-23 glowstone
fill ~100 ~65 ~-30 ~114 ~65 ~-16 polished_deepslate
fill ~100 ~66 ~-30 ~114 ~69 ~-30 iron_block
fill ~100 ~66 ~-16 ~114 ~69 ~-16 iron_block
fill ~100 ~66 ~-30 ~100 ~69 ~-16 iron_block
fill ~114 ~66 ~-30 ~114 ~69 ~-16 iron_block
fill ~101 ~66 ~-29 ~113 ~69 ~-17 air
fill ~102 ~67 ~-30 ~104 ~68 ~-30 glass
fill ~102 ~67 ~-16 ~104 ~68 ~-16 glass
fill ~106 ~67 ~-30 ~108 ~68 ~-30 glass
fill ~106 ~67 ~-16 ~108 ~68 ~-16 glass
fill ~110 ~67 ~-30 ~112 ~68 ~-30 glass
fill ~110 ~67 ~-16 ~112 ~68 ~-16 glass
fill ~100 ~67 ~-28 ~100 ~68 ~-26 glass
fill ~114 ~67 ~-28 ~114 ~68 ~-26 glass
fill ~100 ~67 ~-24 ~100 ~68 ~-22 glass
fill ~114 ~67 ~-24 ~114 ~68 ~-22 glass
fill ~100 ~67 ~-20 ~100 ~68 ~-18 glass
fill ~114 ~67 ~-20 ~114 ~68 ~-18 glass
fill ~100 ~70 ~-30 ~114 ~70 ~-30 iron_block
fill ~100 ~70 ~-16 ~114 ~70 ~-16 iron_block
fill ~100 ~70 ~-29 ~100 ~70 ~-17 iron_block
fill ~114 ~70 ~-29 ~114 ~70 ~-17 iron_block
setblock ~107 ~65 ~-23 glowstone
fill ~100 ~70 ~-30 ~114 ~70 ~-16 polished_deepslate
fill ~103 ~71 ~-27 ~111 ~71 ~-19 gray_concrete
fill ~105 ~71 ~-25 ~106 ~71 ~-21 yellow_concrete
fill ~108 ~71 ~-25 ~109 ~71 ~-21 yellow_concrete
fill ~105 ~1 ~-30 ~109 ~4 ~-30 air
fill ~105 ~5 ~-30 ~109 ~5 ~-30 iron_block
# --- Tower Beta (10x10, 50 tall) ---
fill ~120 ~-1 ~-25 ~130 ~-1 ~-15 stone_bricks
fill ~120 ~0 ~-25 ~130 ~0 ~-15 polished_deepslate
fill ~120 ~1 ~-25 ~130 ~4 ~-25 iron_block
fill ~120 ~1 ~-15 ~130 ~4 ~-15 iron_block
fill ~120 ~1 ~-25 ~120 ~4 ~-15 iron_block
fill ~130 ~1 ~-25 ~130 ~4 ~-15 iron_block
fill ~121 ~1 ~-24 ~129 ~4 ~-16 air
fill ~122 ~2 ~-25 ~124 ~3 ~-25 glass
fill ~122 ~2 ~-15 ~124 ~3 ~-15 glass
fill ~126 ~2 ~-25 ~128 ~3 ~-25 glass
fill ~126 ~2 ~-15 ~128 ~3 ~-15 glass
fill ~120 ~2 ~-23 ~120 ~3 ~-21 glass
fill ~130 ~2 ~-23 ~130 ~3 ~-21 glass
fill ~120 ~2 ~-19 ~120 ~3 ~-17 glass
fill ~130 ~2 ~-19 ~130 ~3 ~-17 glass
fill ~120 ~5 ~-25 ~130 ~5 ~-25 iron_block
fill ~120 ~5 ~-15 ~130 ~5 ~-15 iron_block
fill ~120 ~5 ~-24 ~120 ~5 ~-16 iron_block
fill ~130 ~5 ~-24 ~130 ~5 ~-16 iron_block
setblock ~125 ~0 ~-20 glowstone
fill ~120 ~5 ~-25 ~130 ~5 ~-15 polished_deepslate
fill ~120 ~6 ~-25 ~130 ~9 ~-25 iron_block
fill ~120 ~6 ~-15 ~130 ~9 ~-15 iron_block
fill ~120 ~6 ~-25 ~120 ~9 ~-15 iron_block
fill ~130 ~6 ~-25 ~130 ~9 ~-15 iron_block
fill ~121 ~6 ~-24 ~129 ~9 ~-16 air
fill ~122 ~7 ~-25 ~124 ~8 ~-25 glass
fill ~122 ~7 ~-15 ~124 ~8 ~-15 glass
fill ~126 ~7 ~-25 ~128 ~8 ~-25 glass
fill ~126 ~7 ~-15 ~128 ~8 ~-15 glass
fill ~120 ~7 ~-23 ~120 ~8 ~-21 glass
fill ~130 ~7 ~-23 ~130 ~8 ~-21 glass
fill ~120 ~7 ~-19 ~120 ~8 ~-17 glass
fill ~130 ~7 ~-19 ~130 ~8 ~-17 glass
fill ~120 ~10 ~-25 ~130 ~10 ~-25 iron_block
fill ~120 ~10 ~-15 ~130 ~10 ~-15 iron_block
fill ~120 ~10 ~-24 ~120 ~10 ~-16 iron_block
fill ~130 ~10 ~-24 ~130 ~10 ~-16 iron_block
setblock ~125 ~5 ~-20 glowstone
fill ~120 ~10 ~-25 ~130 ~10 ~-15 polished_deepslate
fill ~120 ~11 ~-25 ~130 ~14 ~-25 iron_block
fill ~120 ~11 ~-15 ~130 ~14 ~-15 iron_block
fill ~120 ~11 ~-25 ~120 ~14 ~-15 iron_block
fill ~130 ~11 ~-25 ~130 ~14 ~-15 iron_block
fill ~121 ~11 ~-24 ~129 ~14 ~-16 air
fill ~122 ~12 ~-25 ~124 ~13 ~-25 glass
fill ~122 ~12 ~-15 ~124 ~13 ~-15 glass
fill ~126 ~12 ~-25 ~128 ~13 ~-25 glass
fill ~126 ~12 ~-15 ~128 ~13 ~-15 glass
fill ~120 ~12 ~-23 ~120 ~13 ~-21 glass
fill ~130 ~12 ~-23 ~130 ~13 ~-21 glass
fill ~120 ~12 ~-19 ~120 ~13 ~-17 glass
fill ~130 ~12 ~-19 ~130 ~13 ~-17 glass
fill ~120 ~15 ~-25 ~130 ~15 ~-25 iron_block
fill ~120 ~15 ~-15 ~130 ~15 ~-15 iron_block
fill ~120 ~15 ~-24 ~120 ~15 ~-16 iron_block
fill ~130 ~15 ~-24 ~130 ~15 ~-16 iron_block
setblock ~125 ~10 ~-20 glowstone
fill ~120 ~15 ~-25 ~130 ~15 ~-15 polished_deepslate
fill ~120 ~16 ~-25 ~130 ~19 ~-25 iron_block
fill ~120 ~16 ~-15 ~130 ~19 ~-15 iron_block
fill ~120 ~16 ~-25 ~120 ~19 ~-15 iron_block
fill ~130 ~16 ~-25 ~130 ~19 ~-15 iron_block
fill ~121 ~16 ~-24 ~129 ~19 ~-16 air
fill ~122 ~17 ~-25 ~124 ~18 ~-25 glass
fill ~122 ~17 ~-15 ~124 ~18 ~-15 glass
fill ~126 ~17 ~-25 ~128 ~18 ~-25 glass
fill ~126 ~17 ~-15 ~128 ~18 ~-15 glass
fill ~120 ~17 ~-23 ~120 ~18 ~-21 glass
fill ~130 ~17 ~-23 ~130 ~18 ~-21 glass
fill ~120 ~17 ~-19 ~120 ~18 ~-17 glass
fill ~130 ~17 ~-19 ~130 ~18 ~-17 glass
fill ~120 ~20 ~-25 ~130 ~20 ~-25 iron_block
fill ~120 ~20 ~-15 ~130 ~20 ~-15 iron_block
fill ~120 ~20 ~-24 ~120 ~20 ~-16 iron_block
fill ~130 ~20 ~-24 ~130 ~20 ~-16 iron_block
setblock ~125 ~15 ~-20 glowstone
fill ~120 ~20 ~-25 ~130 ~20 ~-15 polished_deepslate
fill ~120 ~21 ~-25 ~130 ~24 ~-25 iron_block
fill ~120 ~21 ~-15 ~130 ~24 ~-15 iron_block
fill ~120 ~21 ~-25 ~120 ~24 ~-15 iron_block
fill ~130 ~21 ~-25 ~130 ~24 ~-15 iron_block
fill ~121 ~21 ~-24 ~129 ~24 ~-16 air
fill ~122 ~22 ~-25 ~124 ~23 ~-25 glass
fill ~122 ~22 ~-15 ~124 ~23 ~-15 glass
fill ~126 ~22 ~-25 ~128 ~23 ~-25 glass
fill ~126 ~22 ~-15 ~128 ~23 ~-15 glass
fill ~120 ~22 ~-23 ~120 ~23 ~-21 glass
fill ~130 ~22 ~-23 ~130 ~23 ~-21 glass
fill ~120 ~22 ~-19 ~120 ~23 ~-17 glass
fill ~130 ~22 ~-19 ~130 ~23 ~-17 glass
fill ~120 ~25 ~-25 ~130 ~25 ~-25 iron_block
fill ~120 ~25 ~-15 ~130 ~25 ~-15 iron_block
fill ~120 ~25 ~-24 ~120 ~25 ~-16 iron_block
fill ~130 ~25 ~-24 ~130 ~25 ~-16 iron_block
setblock ~125 ~20 ~-20 glowstone
fill ~120 ~25 ~-25 ~130 ~25 ~-15 polished_deepslate
fill ~120 ~26 ~-25 ~130 ~29 ~-25 iron_block
fill ~120 ~26 ~-15 ~130 ~29 ~-15 iron_block
fill ~120 ~26 ~-25 ~120 ~29 ~-15 iron_block
fill ~130 ~26 ~-25 ~130 ~29 ~-15 iron_block
fill ~121 ~26 ~-24 ~129 ~29 ~-16 air
fill ~122 ~27 ~-25 ~124 ~28 ~-25 glass
fill ~122 ~27 ~-15 ~124 ~28 ~-15 glass
fill ~126 ~27 ~-25 ~128 ~28 ~-25 glass
fill ~126 ~27 ~-15 ~128 ~28 ~-15 glass
fill ~120 ~27 ~-23 ~120 ~28 ~-21 glass
fill ~130 ~27 ~-23 ~130 ~28 ~-21 glass
fill ~120 ~27 ~-19 ~120 ~28 ~-17 glass
fill ~130 ~27 ~-19 ~130 ~28 ~-17 glass
fill ~120 ~30 ~-25 ~130 ~30 ~-25 iron_block
fill ~120 ~30 ~-15 ~130 ~30 ~-15 iron_block
fill ~120 ~30 ~-24 ~120 ~30 ~-16 iron_block
fill ~130 ~30 ~-24 ~130 ~30 ~-16 iron_block
setblock ~125 ~25 ~-20 glowstone
fill ~120 ~30 ~-25 ~130 ~30 ~-15 polished_deepslate
fill ~120 ~31 ~-25 ~130 ~34 ~-25 iron_block
fill ~120 ~31 ~-15 ~130 ~34 ~-15 iron_block
fill ~120 ~31 ~-25 ~120 ~34 ~-15 iron_block
fill ~130 ~31 ~-25 ~130 ~34 ~-15 iron_block
fill ~121 ~31 ~-24 ~129 ~34 ~-16 air
fill ~122 ~32 ~-25 ~124 ~33 ~-25 glass
fill ~122 ~32 ~-15 ~124 ~33 ~-15 glass
fill ~126 ~32 ~-25 ~128 ~33 ~-25 glass
fill ~126 ~32 ~-15 ~128 ~33 ~-15 glass
fill ~120 ~32 ~-23 ~120 ~33 ~-21 glass
fill ~130 ~32 ~-23 ~130 ~33 ~-21 glass
fill ~120 ~32 ~-19 ~120 ~33 ~-17 glass
fill ~130 ~32 ~-19 ~130 ~33 ~-17 glass
fill ~120 ~35 ~-25 ~130 ~35 ~-25 iron_block
fill ~120 ~35 ~-15 ~130 ~35 ~-15 iron_block
fill ~120 ~35 ~-24 ~120 ~35 ~-16 iron_block
fill ~130 ~35 ~-24 ~130 ~35 ~-16 iron_block
setblock ~125 ~30 ~-20 glowstone
fill ~120 ~35 ~-25 ~130 ~35 ~-15 polished_deepslate
fill ~120 ~36 ~-25 ~130 ~39 ~-25 iron_block
fill ~120 ~36 ~-15 ~130 ~39 ~-15 iron_block
fill ~120 ~36 ~-25 ~120 ~39 ~-15 iron_block
fill ~130 ~36 ~-25 ~130 ~39 ~-15 iron_block
fill ~121 ~36 ~-24 ~129 ~39 ~-16 air
fill ~122 ~37 ~-25 ~124 ~38 ~-25 glass
fill ~122 ~37 ~-15 ~124 ~38 ~-15 glass
fill ~126 ~37 ~-25 ~128 ~38 ~-25 glass
fill ~126 ~37 ~-15 ~128 ~38 ~-15 glass
fill ~120 ~37 ~-23 ~120 ~38 ~-21 glass
fill ~130 ~37 ~-23 ~130 ~38 ~-21 glass
fill ~120 ~37 ~-19 ~120 ~38 ~-17 glass
fill ~130 ~37 ~-19 ~130 ~38 ~-17 glass
fill ~120 ~40 ~-25 ~130 ~40 ~-25 iron_block
fill ~120 ~40 ~-15 ~130 ~40 ~-15 iron_block
fill ~120 ~40 ~-24 ~120 ~40 ~-16 iron_block
fill ~130 ~40 ~-24 ~130 ~40 ~-16 iron_block
setblock ~125 ~35 ~-20 glowstone
fill ~120 ~40 ~-25 ~130 ~40 ~-15 polished_deepslate
fill ~120 ~41 ~-25 ~130 ~44 ~-25 iron_block
fill ~120 ~41 ~-15 ~130 ~44 ~-15 iron_block
fill ~120 ~41 ~-25 ~120 ~44 ~-15 iron_block
fill ~130 ~41 ~-25 ~130 ~44 ~-15 iron_block
fill ~121 ~41 ~-24 ~129 ~44 ~-16 air
fill ~122 ~42 ~-25 ~124 ~43 ~-25 glass
fill ~122 ~42 ~-15 ~124 ~43 ~-15 glass
fill ~126 ~42 ~-25 ~128 ~43 ~-25 glass
fill ~126 ~42 ~-15 ~128 ~43 ~-15 glass
fill ~120 ~42 ~-23 ~120 ~43 ~-21 glass
fill ~130 ~42 ~-23 ~130 ~43 ~-21 glass
fill ~120 ~42 ~-19 ~120 ~43 ~-17 glass
fill ~130 ~42 ~-19 ~130 ~43 ~-17 glass
fill ~120 ~45 ~-25 ~130 ~45 ~-25 iron_block
fill ~120 ~45 ~-15 ~130 ~45 ~-15 iron_block
fill ~120 ~45 ~-24 ~120 ~45 ~-16 iron_block
fill ~130 ~45 ~-24 ~130 ~45 ~-16 iron_block
setblock ~125 ~40 ~-20 glowstone
fill ~120 ~45 ~-25 ~130 ~45 ~-15 polished_deepslate
fill ~120 ~46 ~-25 ~130 ~49 ~-25 iron_block
fill ~120 ~46 ~-15 ~130 ~49 ~-15 iron_block
fill ~120 ~46 ~-25 ~120 ~49 ~-15 iron_block
fill ~130 ~46 ~-25 ~130 ~49 ~-15 iron_block
fill ~121 ~46 ~-24 ~129 ~49 ~-16 air
fill ~122 ~47 ~-25 ~124 ~48 ~-25 glass
fill ~122 ~47 ~-15 ~124 ~48 ~-15 glass
fill ~126 ~47 ~-25 ~128 ~48 ~-25 glass
fill ~126 ~47 ~-15 ~128 ~48 ~-15 glass
fill ~120 ~47 ~-23 ~120 ~48 ~-21 glass
fill ~130 ~47 ~-23 ~130 ~48 ~-21 glass
fill ~120 ~47 ~-19 ~120 ~48 ~-17 glass
fill ~130 ~47 ~-19 ~130 ~48 ~-17 glass
fill ~120 ~50 ~-25 ~130 ~50 ~-25 iron_block
fill ~120 ~50 ~-15 ~130 ~50 ~-15 iron_block
fill ~120 ~50 ~-24 ~120 ~50 ~-16 iron_block
fill ~130 ~50 ~-24 ~130 ~50 ~-16 iron_block
setblock ~125 ~45 ~-20 glowstone
fill ~120 ~50 ~-25 ~130 ~50 ~-15 polished_deepslate
fill ~122 ~51 ~-23 ~124 ~52 ~-21 iron_block
fill ~123 ~1 ~-25 ~127 ~4 ~-25 air
fill ~123 ~5 ~-25 ~127 ~5 ~-25 iron_block
# --- Tower Gamma (12x12, 90 tall) ---
fill ~134 ~-1 ~-35 ~146 ~-1 ~-23 stone_bricks
fill ~134 ~0 ~-35 ~146 ~0 ~-23 polished_deepslate
fill ~134 ~1 ~-35 ~146 ~4 ~-35 iron_block
fill ~134 ~1 ~-23 ~146 ~4 ~-23 iron_block
fill ~134 ~1 ~-35 ~134 ~4 ~-23 iron_block
fill ~146 ~1 ~-35 ~146 ~4 ~-23 iron_block
fill ~135 ~1 ~-34 ~145 ~4 ~-24 air
fill ~136 ~2 ~-35 ~138 ~3 ~-35 glass
fill ~136 ~2 ~-23 ~138 ~3 ~-23 glass
fill ~140 ~2 ~-35 ~142 ~3 ~-35 glass
fill ~140 ~2 ~-23 ~142 ~3 ~-23 glass
fill ~134 ~2 ~-33 ~134 ~3 ~-31 glass
fill ~146 ~2 ~-33 ~146 ~3 ~-31 glass
fill ~134 ~2 ~-29 ~134 ~3 ~-27 glass
fill ~146 ~2 ~-29 ~146 ~3 ~-27 glass
fill ~134 ~5 ~-35 ~146 ~5 ~-35 iron_block
fill ~134 ~5 ~-23 ~146 ~5 ~-23 iron_block
fill ~134 ~5 ~-34 ~134 ~5 ~-24 iron_block
fill ~146 ~5 ~-34 ~146 ~5 ~-24 iron_block
setblock ~140 ~0 ~-29 glowstone
fill ~134 ~5 ~-35 ~146 ~5 ~-23 polished_deepslate
fill ~134 ~6 ~-35 ~146 ~9 ~-35 iron_block
fill ~134 ~6 ~-23 ~146 ~9 ~-23 iron_block
fill ~134 ~6 ~-35 ~134 ~9 ~-23 iron_block
fill ~146 ~6 ~-35 ~146 ~9 ~-23 iron_block
fill ~135 ~6 ~-34 ~145 ~9 ~-24 air
fill ~136 ~7 ~-35 ~138 ~8 ~-35 glass
fill ~136 ~7 ~-23 ~138 ~8 ~-23 glass
fill ~140 ~7 ~-35 ~142 ~8 ~-35 glass
fill ~140 ~7 ~-23 ~142 ~8 ~-23 glass
fill ~134 ~7 ~-33 ~134 ~8 ~-31 glass
fill ~146 ~7 ~-33 ~146 ~8 ~-31 glass
fill ~134 ~7 ~-29 ~134 ~8 ~-27 glass
fill ~146 ~7 ~-29 ~146 ~8 ~-27 glass
fill ~134 ~10 ~-35 ~146 ~10 ~-35 iron_block
fill ~134 ~10 ~-23 ~146 ~10 ~-23 iron_block
fill ~134 ~10 ~-34 ~134 ~10 ~-24 iron_block
fill ~146 ~10 ~-34 ~146 ~10 ~-24 iron_block
setblock ~140 ~5 ~-29 glowstone
fill ~134 ~10 ~-35 ~146 ~10 ~-23 polished_deepslate
fill ~134 ~11 ~-35 ~146 ~14 ~-35 iron_block
fill ~134 ~11 ~-23 ~146 ~14 ~-23 iron_block
fill ~134 ~11 ~-35 ~134 ~14 ~-23 iron_block
fill ~146 ~11 ~-35 ~146 ~14 ~-23 iron_block
fill ~135 ~11 ~-34 ~145 ~14 ~-24 air
fill ~136 ~12 ~-35 ~138 ~13 ~-35 glass
fill ~136 ~12 ~-23 ~138 ~13 ~-23 glass
fill ~140 ~12 ~-35 ~142 ~13 ~-35 glass
fill ~140 ~12 ~-23 ~142 ~13 ~-23 glass
fill ~134 ~12 ~-33 ~134 ~13 ~-31 glass
fill ~146 ~12 ~-33 ~146 ~13 ~-31 glass
fill ~134 ~12 ~-29 ~134 ~13 ~-27 glass
fill ~146 ~12 ~-29 ~146 ~13 ~-27 glass
fill ~134 ~15 ~-35 ~146 ~15 ~-35 iron_block
fill ~134 ~15 ~-23 ~146 ~15 ~-23 iron_block
fill ~134 ~15 ~-34 ~134 ~15 ~-24 iron_block
fill ~146 ~15 ~-34 ~146 ~15 ~-24 iron_block
setblock ~140 ~10 ~-29 glowstone
fill ~134 ~15 ~-35 ~146 ~15 ~-23 polished_deepslate
fill ~134 ~16 ~-35 ~146 ~19 ~-35 iron_block
fill ~134 ~16 ~-23 ~146 ~19 ~-23 iron_block
fill ~134 ~16 ~-35 ~134 ~19 ~-23 iron_block
fill ~146 ~16 ~-35 ~146 ~19 ~-23 iron_block
fill ~135 ~16 ~-34 ~145 ~19 ~-24 air
fill ~136 ~17 ~-35 ~138 ~18 ~-35 glass
fill ~136 ~17 ~-23 ~138 ~18 ~-23 glass
fill ~140 ~17 ~-35 ~142 ~18 ~-35 glass
fill ~140 ~17 ~-23 ~142 ~18 ~-23 glass
fill ~134 ~17 ~-33 ~134 ~18 ~-31 glass
fill ~146 ~17 ~-33 ~146 ~18 ~-31 glass
fill ~134 ~17 ~-29 ~134 ~18 ~-27 glass
fill ~146 ~17 ~-29 ~146 ~18 ~-27 glass
fill ~134 ~20 ~-35 ~146 ~20 ~-35 iron_block
fill ~134 ~20 ~-23 ~146 ~20 ~-23 iron_block
fill ~134 ~20 ~-34 ~134 ~20 ~-24 iron_block
fill ~146 ~20 ~-34 ~146 ~20 ~-24 iron_block
setblock ~140 ~15 ~-29 glowstone
fill ~134 ~20 ~-35 ~146 ~20 ~-23 polished_deepslate
fill ~134 ~21 ~-35 ~146 ~24 ~-35 iron_block
fill ~134 ~21 ~-23 ~146 ~24 ~-23 iron_block
fill ~134 ~21 ~-35 ~134 ~24 ~-23 iron_block
fill ~146 ~21 ~-35 ~146 ~24 ~-23 iron_block
fill ~135 ~21 ~-34 ~145 ~24 ~-24 air
fill ~136 ~22 ~-35 ~138 ~23 ~-35 glass
fill ~136 ~22 ~-23 ~138 ~23 ~-23 glass
fill ~140 ~22 ~-35 ~142 ~23 ~-35 glass
fill ~140 ~22 ~-23 ~142 ~23 ~-23 glass
fill ~134 ~22 ~-33 ~134 ~23 ~-31 glass
fill ~146 ~22 ~-33 ~146 ~23 ~-31 glass
fill ~134 ~22 ~-29 ~134 ~23 ~-27 glass
fill ~146 ~22 ~-29 ~146 ~23 ~-27 glass
fill ~134 ~25 ~-35 ~146 ~25 ~-35 iron_block
fill ~134 ~25 ~-23 ~146 ~25 ~-23 iron_block
fill ~134 ~25 ~-34 ~134 ~25 ~-24 iron_block
fill ~146 ~25 ~-34 ~146 ~25 ~-24 iron_block
setblock ~140 ~20 ~-29 glowstone
fill ~134 ~25 ~-35 ~146 ~25 ~-23 polished_deepslate
fill ~134 ~26 ~-35 ~146 ~29 ~-35 iron_block
fill ~134 ~26 ~-23 ~146 ~29 ~-23 iron_block
fill ~134 ~26 ~-35 ~134 ~29 ~-23 iron_block
fill ~146 ~26 ~-35 ~146 ~29 ~-23 iron_block
fill ~135 ~26 ~-34 ~145 ~29 ~-24 air
fill ~136 ~27 ~-35 ~138 ~28 ~-35 glass
fill ~136 ~27 ~-23 ~138 ~28 ~-23 glass
fill ~140 ~27 ~-35 ~142 ~28 ~-35 glass
fill ~140 ~27 ~-23 ~142 ~28 ~-23 glass
fill ~134 ~27 ~-33 ~134 ~28 ~-31 glass
fill ~146 ~27 ~-33 ~146 ~28 ~-31 glass
fill ~134 ~27 ~-29 ~134 ~28 ~-27 glass
fill ~146 ~27 ~-29 ~146 ~28 ~-27 glass
fill ~134 ~30 ~-35 ~146 ~30 ~-35 iron_block
fill ~134 ~30 ~-23 ~146 ~30 ~-23 iron_block
fill ~134 ~30 ~-34 ~134 ~30 ~-24 iron_block
fill ~146 ~30 ~-34 ~146 ~30 ~-24 iron_block
setblock ~140 ~25 ~-29 glowstone
fill ~134 ~30 ~-35 ~146 ~30 ~-23 polished_deepslate
fill ~134 ~31 ~-35 ~146 ~34 ~-35 iron_block
fill ~134 ~31 ~-23 ~146 ~34 ~-23 iron_block
fill ~134 ~31 ~-35 ~134 ~34 ~-23 iron_block
fill ~146 ~31 ~-35 ~146 ~34 ~-23 iron_block
fill ~135 ~31 ~-34 ~145 ~34 ~-24 air
fill ~136 ~32 ~-35 ~138 ~33 ~-35 glass
fill ~136 ~32 ~-23 ~138 ~33 ~-23 glass
fill ~140 ~32 ~-35 ~142 ~33 ~-35 glass
fill ~140 ~32 ~-23 ~142 ~33 ~-23 glass
fill ~134 ~32 ~-33 ~134 ~33 ~-31 glass
fill ~146 ~32 ~-33 ~146 ~33 ~-31 glass
fill ~134 ~32 ~-29 ~134 ~33 ~-27 glass
fill ~146 ~32 ~-29 ~146 ~33 ~-27 glass
fill ~134 ~35 ~-35 ~146 ~35 ~-35 iron_block
fill ~134 ~35 ~-23 ~146 ~35 ~-23 iron_block
fill ~134 ~35 ~-34 ~134 ~35 ~-24 iron_block
fill ~146 ~35 ~-34 ~146 ~35 ~-24 iron_block
setblock ~140 ~30 ~-29 glowstone
fill ~134 ~35 ~-35 ~146 ~35 ~-23 polished_deepslate
fill ~134 ~36 ~-35 ~146 ~39 ~-35 iron_block
fill ~134 ~36 ~-23 ~146 ~39 ~-23 iron_block
fill ~134 ~36 ~-35 ~134 ~39 ~-23 iron_block
fill ~146 ~36 ~-35 ~146 ~39 ~-23 iron_block
fill ~135 ~36 ~-34 ~145 ~39 ~-24 air
fill ~136 ~37 ~-35 ~138 ~38 ~-35 glass
fill ~136 ~37 ~-23 ~138 ~38 ~-23 glass
fill ~140 ~37 ~-35 ~142 ~38 ~-35 glass
fill ~140 ~37 ~-23 ~142 ~38 ~-23 glass
fill ~134 ~37 ~-33 ~134 ~38 ~-31 glass
fill ~146 ~37 ~-33 ~146 ~38 ~-31 glass
fill ~134 ~37 ~-29 ~134 ~38 ~-27 glass
fill ~146 ~37 ~-29 ~146 ~38 ~-27 glass
fill ~134 ~40 ~-35 ~146 ~40 ~-35 iron_block
fill ~134 ~40 ~-23 ~146 ~40 ~-23 iron_block
fill ~134 ~40 ~-34 ~134 ~40 ~-24 iron_block
fill ~146 ~40 ~-34 ~146 ~40 ~-24 iron_block
setblock ~140 ~35 ~-29 glowstone
fill ~134 ~40 ~-35 ~146 ~40 ~-23 polished_deepslate
fill ~134 ~41 ~-35 ~146 ~44 ~-35 iron_block
fill ~134 ~41 ~-23 ~146 ~44 ~-23 iron_block
fill ~134 ~41 ~-35 ~134 ~44 ~-23 iron_block
fill ~146 ~41 ~-35 ~146 ~44 ~-23 iron_block
fill ~135 ~41 ~-34 ~145 ~44 ~-24 air
fill ~136 ~42 ~-35 ~138 ~43 ~-35 glass
fill ~136 ~42 ~-23 ~138 ~43 ~-23 glass
fill ~140 ~42 ~-35 ~142 ~43 ~-35 glass
fill ~140 ~42 ~-23 ~142 ~43 ~-23 glass
fill ~134 ~42 ~-33 ~134 ~43 ~-31 glass
fill ~146 ~42 ~-33 ~146 ~43 ~-31 glass
fill ~134 ~42 ~-29 ~134 ~43 ~-27 glass
fill ~146 ~42 ~-29 ~146 ~43 ~-27 glass
fill ~134 ~45 ~-35 ~146 ~45 ~-35 iron_block
fill ~134 ~45 ~-23 ~146 ~45 ~-23 iron_block
fill ~134 ~45 ~-34 ~134 ~45 ~-24 iron_block
fill ~146 ~45 ~-34 ~146 ~45 ~-24 iron_block
setblock ~140 ~40 ~-29 glowstone
fill ~134 ~45 ~-35 ~146 ~45 ~-23 polished_deepslate
fill ~134 ~46 ~-35 ~146 ~49 ~-35 iron_block
fill ~134 ~46 ~-23 ~146 ~49 ~-23 iron_block
fill ~134 ~46 ~-35 ~134 ~49 ~-23 iron_block
fill ~146 ~46 ~-35 ~146 ~49 ~-23 iron_block
fill ~135 ~46 ~-34 ~145 ~49 ~-24 air
fill ~136 ~47 ~-35 ~138 ~48 ~-35 glass
fill ~136 ~47 ~-23 ~138 ~48 ~-23 glass
fill ~140 ~47 ~-35 ~142 ~48 ~-35 glass
fill ~140 ~47 ~-23 ~142 ~48 ~-23 glass
fill ~134 ~47 ~-33 ~134 ~48 ~-31 glass
fill ~146 ~47 ~-33 ~146 ~48 ~-31 glass
fill ~134 ~47 ~-29 ~134 ~48 ~-27 glass
fill ~146 ~47 ~-29 ~146 ~48 ~-27 glass
fill ~134 ~50 ~-35 ~146 ~50 ~-35 iron_block
fill ~134 ~50 ~-23 ~146 ~50 ~-23 iron_block
fill ~134 ~50 ~-34 ~134 ~50 ~-24 iron_block
fill ~146 ~50 ~-34 ~146 ~50 ~-24 iron_block
setblock ~140 ~45 ~-29 glowstone
fill ~134 ~50 ~-35 ~146 ~50 ~-23 polished_deepslate
fill ~134 ~51 ~-35 ~146 ~54 ~-35 iron_block
fill ~134 ~51 ~-23 ~146 ~54 ~-23 iron_block
fill ~134 ~51 ~-35 ~134 ~54 ~-23 iron_block
fill ~146 ~51 ~-35 ~146 ~54 ~-23 iron_block
fill ~135 ~51 ~-34 ~145 ~54 ~-24 air
fill ~136 ~52 ~-35 ~138 ~53 ~-35 glass
fill ~136 ~52 ~-23 ~138 ~53 ~-23 glass
fill ~140 ~52 ~-35 ~142 ~53 ~-35 glass
fill ~140 ~52 ~-23 ~142 ~53 ~-23 glass
fill ~134 ~52 ~-33 ~134 ~53 ~-31 glass
fill ~146 ~52 ~-33 ~146 ~53 ~-31 glass
fill ~134 ~52 ~-29 ~134 ~53 ~-27 glass
fill ~146 ~52 ~-29 ~146 ~53 ~-27 glass
fill ~134 ~55 ~-35 ~146 ~55 ~-35 iron_block
fill ~134 ~55 ~-23 ~146 ~55 ~-23 iron_block
fill ~134 ~55 ~-34 ~134 ~55 ~-24 iron_block
fill ~146 ~55 ~-34 ~146 ~55 ~-24 iron_block
setblock ~140 ~50 ~-29 glowstone
fill ~134 ~55 ~-35 ~146 ~55 ~-23 polished_deepslate
fill ~134 ~56 ~-35 ~146 ~59 ~-35 iron_block
fill ~134 ~56 ~-23 ~146 ~59 ~-23 iron_block
fill ~134 ~56 ~-35 ~134 ~59 ~-23 iron_block
fill ~146 ~56 ~-35 ~146 ~59 ~-23 iron_block
fill ~135 ~56 ~-34 ~145 ~59 ~-24 air
fill ~136 ~57 ~-35 ~138 ~58 ~-35 glass
fill ~136 ~57 ~-23 ~138 ~58 ~-23 glass
fill ~140 ~57 ~-35 ~142 ~58 ~-35 glass
fill ~140 ~57 ~-23 ~142 ~58 ~-23 glass
fill ~134 ~57 ~-33 ~134 ~58 ~-31 glass
fill ~146 ~57 ~-33 ~146 ~58 ~-31 glass
fill ~134 ~57 ~-29 ~134 ~58 ~-27 glass
fill ~146 ~57 ~-29 ~146 ~58 ~-27 glass
fill ~134 ~60 ~-35 ~146 ~60 ~-35 iron_block
fill ~134 ~60 ~-23 ~146 ~60 ~-23 iron_block
fill ~134 ~60 ~-34 ~134 ~60 ~-24 iron_block
fill ~146 ~60 ~-34 ~146 ~60 ~-24 iron_block
setblock ~140 ~55 ~-29 glowstone
fill ~134 ~60 ~-35 ~146 ~60 ~-23 polished_deepslate
fill ~134 ~61 ~-35 ~146 ~64 ~-35 iron_block
fill ~134 ~61 ~-23 ~146 ~64 ~-23 iron_block
fill ~134 ~61 ~-35 ~134 ~64 ~-23 iron_block
fill ~146 ~61 ~-35 ~146 ~64 ~-23 iron_block
fill ~135 ~61 ~-34 ~145 ~64 ~-24 air
fill ~136 ~62 ~-35 ~138 ~63 ~-35 glass
fill ~136 ~62 ~-23 ~138 ~63 ~-23 glass
fill ~140 ~62 ~-35 ~142 ~63 ~-35 glass
fill ~140 ~62 ~-23 ~142 ~63 ~-23 glass
fill ~134 ~62 ~-33 ~134 ~63 ~-31 glass
fill ~146 ~62 ~-33 ~146 ~63 ~-31 glass
fill ~134 ~62 ~-29 ~134 ~63 ~-27 glass
fill ~146 ~62 ~-29 ~146 ~63 ~-27 glass
fill ~134 ~65 ~-35 ~146 ~65 ~-35 iron_block
fill ~134 ~65 ~-23 ~146 ~65 ~-23 iron_block
fill ~134 ~65 ~-34 ~134 ~65 ~-24 iron_block
fill ~146 ~65 ~-34 ~146 ~65 ~-24 iron_block
setblock ~140 ~60 ~-29 glowstone
fill ~134 ~65 ~-35 ~146 ~65 ~-23 polished_deepslate
fill ~134 ~66 ~-35 ~146 ~69 ~-35 iron_block
fill ~134 ~66 ~-23 ~146 ~69 ~-23 iron_block
fill ~134 ~66 ~-35 ~134 ~69 ~-23 iron_block
fill ~146 ~66 ~-35 ~146 ~69 ~-23 iron_block
fill ~135 ~66 ~-34 ~145 ~69 ~-24 air
fill ~136 ~67 ~-35 ~138 ~68 ~-35 glass
fill ~136 ~67 ~-23 ~138 ~68 ~-23 glass
fill ~140 ~67 ~-35 ~142 ~68 ~-35 glass
fill ~140 ~67 ~-23 ~142 ~68 ~-23 glass
fill ~134 ~67 ~-33 ~134 ~68 ~-31 glass
fill ~146 ~67 ~-33 ~146 ~68 ~-31 glass
fill ~134 ~67 ~-29 ~134 ~68 ~-27 glass
fill ~146 ~67 ~-29 ~146 ~68 ~-27 glass
fill ~134 ~70 ~-35 ~146 ~70 ~-35 iron_block
fill ~134 ~70 ~-23 ~146 ~70 ~-23 iron_block
fill ~134 ~70 ~-34 ~134 ~70 ~-24 iron_block
fill ~146 ~70 ~-34 ~146 ~70 ~-24 iron_block
setblock ~140 ~65 ~-29 glowstone
fill ~134 ~70 ~-35 ~146 ~70 ~-23 polished_deepslate
fill ~134 ~71 ~-35 ~146 ~74 ~-35 iron_block
fill ~134 ~71 ~-23 ~146 ~74 ~-23 iron_block
fill ~134 ~71 ~-35 ~134 ~74 ~-23 iron_block
fill ~146 ~71 ~-35 ~146 ~74 ~-23 iron_block
fill ~135 ~71 ~-34 ~145 ~74 ~-24 air
fill ~136 ~72 ~-35 ~138 ~73 ~-35 glass
fill ~136 ~72 ~-23 ~138 ~73 ~-23 glass
fill ~140 ~72 ~-35 ~142 ~73 ~-35 glass
fill ~140 ~72 ~-23 ~142 ~73 ~-23 glass
fill ~134 ~72 ~-33 ~134 ~73 ~-31 glass
fill ~146 ~72 ~-33 ~146 ~73 ~-31 glass
fill ~134 ~72 ~-29 ~134 ~73 ~-27 glass
fill ~146 ~72 ~-29 ~146 ~73 ~-27 glass
fill ~134 ~75 ~-35 ~146 ~75 ~-35 iron_block
fill ~134 ~75 ~-23 ~146 ~75 ~-23 iron_block
fill ~134 ~75 ~-34 ~134 ~75 ~-24 iron_block
fill ~146 ~75 ~-34 ~146 ~75 ~-24 iron_block
setblock ~140 ~70 ~-29 glowstone
fill ~134 ~75 ~-35 ~146 ~75 ~-23 polished_deepslate
fill ~134 ~76 ~-35 ~146 ~79 ~-35 iron_block
fill ~134 ~76 ~-23 ~146 ~79 ~-23 iron_block
fill ~134 ~76 ~-35 ~134 ~79 ~-23 iron_block
fill ~146 ~76 ~-35 ~146 ~79 ~-23 iron_block
fill ~135 ~76 ~-34 ~145 ~79 ~-24 air
fill ~136 ~77 ~-35 ~138 ~78 ~-35 glass
fill ~136 ~77 ~-23 ~138 ~78 ~-23 glass
fill ~140 ~77 ~-35 ~142 ~78 ~-35 glass
fill ~140 ~77 ~-23 ~142 ~78 ~-23 glass
fill ~134 ~77 ~-33 ~134 ~78 ~-31 glass
fill ~146 ~77 ~-33 ~146 ~78 ~-31 glass
fill ~134 ~77 ~-29 ~134 ~78 ~-27 glass
fill ~146 ~77 ~-29 ~146 ~78 ~-27 glass
fill ~134 ~80 ~-35 ~146 ~80 ~-35 iron_block
fill ~134 ~80 ~-23 ~146 ~80 ~-23 iron_block
fill ~134 ~80 ~-34 ~134 ~80 ~-24 iron_block
fill ~146 ~80 ~-34 ~146 ~80 ~-24 iron_block
setblock ~140 ~75 ~-29 glowstone
fill ~134 ~80 ~-35 ~146 ~80 ~-23 polished_deepslate
fill ~134 ~81 ~-35 ~146 ~84 ~-35 iron_block
fill ~134 ~81 ~-23 ~146 ~84 ~-23 iron_block
fill ~134 ~81 ~-35 ~134 ~84 ~-23 iron_block
fill ~146 ~81 ~-35 ~146 ~84 ~-23 iron_block
fill ~135 ~81 ~-34 ~145 ~84 ~-24 air
fill ~136 ~82 ~-35 ~138 ~83 ~-35 glass
fill ~136 ~82 ~-23 ~138 ~83 ~-23 glass
fill ~140 ~82 ~-35 ~142 ~83 ~-35 glass
fill ~140 ~82 ~-23 ~142 ~83 ~-23 glass
fill ~134 ~82 ~-33 ~134 ~83 ~-31 glass
fill ~146 ~82 ~-33 ~146 ~83 ~-31 glass
fill ~134 ~82 ~-29 ~134 ~83 ~-27 glass
fill ~146 ~82 ~-29 ~146 ~83 ~-27 glass
fill ~134 ~85 ~-35 ~146 ~85 ~-35 iron_block
fill ~134 ~85 ~-23 ~146 ~85 ~-23 iron_block
fill ~134 ~85 ~-34 ~134 ~85 ~-24 iron_block
fill ~146 ~85 ~-34 ~146 ~85 ~-24 iron_block
setblock ~140 ~80 ~-29 glowstone
fill ~134 ~85 ~-35 ~146 ~85 ~-23 polished_deepslate
fill ~134 ~86 ~-35 ~146 ~89 ~-35 iron_block
fill ~134 ~86 ~-23 ~146 ~89 ~-23 iron_block
fill ~134 ~86 ~-35 ~134 ~89 ~-23 iron_block
fill ~146 ~86 ~-35 ~146 ~89 ~-23 iron_block
fill ~135 ~86 ~-34 ~145 ~89 ~-24 air
fill ~136 ~87 ~-35 ~138 ~88 ~-35 glass
fill ~136 ~87 ~-23 ~138 ~88 ~-23 glass
fill ~140 ~87 ~-35 ~142 ~88 ~-35 glass
fill ~140 ~87 ~-23 ~142 ~88 ~-23 glass
fill ~134 ~87 ~-33 ~134 ~88 ~-31 glass
fill ~146 ~87 ~-33 ~146 ~88 ~-31 glass
fill ~134 ~87 ~-29 ~134 ~88 ~-27 glass
fill ~146 ~87 ~-29 ~146 ~88 ~-27 glass
fill ~134 ~90 ~-35 ~146 ~90 ~-35 iron_block
fill ~134 ~90 ~-23 ~146 ~90 ~-23 iron_block
fill ~134 ~90 ~-34 ~134 ~90 ~-24 iron_block
fill ~146 ~90 ~-34 ~146 ~90 ~-24 iron_block
setblock ~140 ~85 ~-29 glowstone
fill ~134 ~90 ~-35 ~146 ~90 ~-23 polished_deepslate
setblock ~140 ~91 ~-29 iron_block
setblock ~140 ~92 ~-29 iron_block
setblock ~140 ~93 ~-29 iron_block
setblock ~140 ~94 ~-29 iron_block
setblock ~140 ~95 ~-29 iron_block
setblock ~140 ~96 ~-29 iron_block
setblock ~140 ~97 ~-29 iron_block
setblock ~140 ~98 ~-29 iron_block
setblock ~140 ~99 ~-29 iron_block
setblock ~140 ~100 ~-29 iron_block
setblock ~140 ~101 ~-29 iron_block
setblock ~140 ~102 ~-29 iron_block
setblock ~140 ~103 ~-29 iron_block
setblock ~140 ~104 ~-29 iron_block
setblock ~140 ~105 ~-29 redstone_lamp
fill ~138 ~1 ~-35 ~142 ~4 ~-35 air
fill ~138 ~5 ~-35 ~142 ~5 ~-35 iron_block
function mtn_city2
