# Phase 5b: Towers 4-6 + street furniture
# --- Tower Delta (10x10, 40 tall) ---
fill ~150 ~-1 ~-22 ~160 ~-1 ~-12 stone_bricks
fill ~150 ~0 ~-22 ~160 ~0 ~-12 polished_deepslate
fill ~150 ~1 ~-22 ~160 ~4 ~-22 iron_block
fill ~150 ~1 ~-12 ~160 ~4 ~-12 iron_block
fill ~150 ~1 ~-22 ~150 ~4 ~-12 iron_block
fill ~160 ~1 ~-22 ~160 ~4 ~-12 iron_block
fill ~151 ~1 ~-21 ~159 ~4 ~-13 air
fill ~152 ~2 ~-22 ~154 ~3 ~-22 glass
fill ~152 ~2 ~-12 ~154 ~3 ~-12 glass
fill ~156 ~2 ~-22 ~158 ~3 ~-22 glass
fill ~156 ~2 ~-12 ~158 ~3 ~-12 glass
fill ~150 ~2 ~-20 ~150 ~3 ~-18 glass
fill ~160 ~2 ~-20 ~160 ~3 ~-18 glass
fill ~150 ~2 ~-16 ~150 ~3 ~-14 glass
fill ~160 ~2 ~-16 ~160 ~3 ~-14 glass
fill ~150 ~5 ~-22 ~160 ~5 ~-22 iron_block
fill ~150 ~5 ~-12 ~160 ~5 ~-12 iron_block
fill ~150 ~5 ~-21 ~150 ~5 ~-13 iron_block
fill ~160 ~5 ~-21 ~160 ~5 ~-13 iron_block
setblock ~155 ~0 ~-17 glowstone
fill ~150 ~5 ~-22 ~160 ~5 ~-12 polished_deepslate
fill ~150 ~6 ~-22 ~160 ~9 ~-22 iron_block
fill ~150 ~6 ~-12 ~160 ~9 ~-12 iron_block
fill ~150 ~6 ~-22 ~150 ~9 ~-12 iron_block
fill ~160 ~6 ~-22 ~160 ~9 ~-12 iron_block
fill ~151 ~6 ~-21 ~159 ~9 ~-13 air
fill ~152 ~7 ~-22 ~154 ~8 ~-22 glass
fill ~152 ~7 ~-12 ~154 ~8 ~-12 glass
fill ~156 ~7 ~-22 ~158 ~8 ~-22 glass
fill ~156 ~7 ~-12 ~158 ~8 ~-12 glass
fill ~150 ~7 ~-20 ~150 ~8 ~-18 glass
fill ~160 ~7 ~-20 ~160 ~8 ~-18 glass
fill ~150 ~7 ~-16 ~150 ~8 ~-14 glass
fill ~160 ~7 ~-16 ~160 ~8 ~-14 glass
fill ~150 ~10 ~-22 ~160 ~10 ~-22 iron_block
fill ~150 ~10 ~-12 ~160 ~10 ~-12 iron_block
fill ~150 ~10 ~-21 ~150 ~10 ~-13 iron_block
fill ~160 ~10 ~-21 ~160 ~10 ~-13 iron_block
setblock ~155 ~5 ~-17 glowstone
fill ~150 ~10 ~-22 ~160 ~10 ~-12 polished_deepslate
fill ~150 ~11 ~-22 ~160 ~14 ~-22 iron_block
fill ~150 ~11 ~-12 ~160 ~14 ~-12 iron_block
fill ~150 ~11 ~-22 ~150 ~14 ~-12 iron_block
fill ~160 ~11 ~-22 ~160 ~14 ~-12 iron_block
fill ~151 ~11 ~-21 ~159 ~14 ~-13 air
fill ~152 ~12 ~-22 ~154 ~13 ~-22 glass
fill ~152 ~12 ~-12 ~154 ~13 ~-12 glass
fill ~156 ~12 ~-22 ~158 ~13 ~-22 glass
fill ~156 ~12 ~-12 ~158 ~13 ~-12 glass
fill ~150 ~12 ~-20 ~150 ~13 ~-18 glass
fill ~160 ~12 ~-20 ~160 ~13 ~-18 glass
fill ~150 ~12 ~-16 ~150 ~13 ~-14 glass
fill ~160 ~12 ~-16 ~160 ~13 ~-14 glass
fill ~150 ~15 ~-22 ~160 ~15 ~-22 iron_block
fill ~150 ~15 ~-12 ~160 ~15 ~-12 iron_block
fill ~150 ~15 ~-21 ~150 ~15 ~-13 iron_block
fill ~160 ~15 ~-21 ~160 ~15 ~-13 iron_block
setblock ~155 ~10 ~-17 glowstone
fill ~150 ~15 ~-22 ~160 ~15 ~-12 polished_deepslate
fill ~150 ~16 ~-22 ~160 ~19 ~-22 iron_block
fill ~150 ~16 ~-12 ~160 ~19 ~-12 iron_block
fill ~150 ~16 ~-22 ~150 ~19 ~-12 iron_block
fill ~160 ~16 ~-22 ~160 ~19 ~-12 iron_block
fill ~151 ~16 ~-21 ~159 ~19 ~-13 air
fill ~152 ~17 ~-22 ~154 ~18 ~-22 glass
fill ~152 ~17 ~-12 ~154 ~18 ~-12 glass
fill ~156 ~17 ~-22 ~158 ~18 ~-22 glass
fill ~156 ~17 ~-12 ~158 ~18 ~-12 glass
fill ~150 ~17 ~-20 ~150 ~18 ~-18 glass
fill ~160 ~17 ~-20 ~160 ~18 ~-18 glass
fill ~150 ~17 ~-16 ~150 ~18 ~-14 glass
fill ~160 ~17 ~-16 ~160 ~18 ~-14 glass
fill ~150 ~20 ~-22 ~160 ~20 ~-22 iron_block
fill ~150 ~20 ~-12 ~160 ~20 ~-12 iron_block
fill ~150 ~20 ~-21 ~150 ~20 ~-13 iron_block
fill ~160 ~20 ~-21 ~160 ~20 ~-13 iron_block
setblock ~155 ~15 ~-17 glowstone
fill ~150 ~20 ~-22 ~160 ~20 ~-12 polished_deepslate
fill ~150 ~21 ~-22 ~160 ~24 ~-22 iron_block
fill ~150 ~21 ~-12 ~160 ~24 ~-12 iron_block
fill ~150 ~21 ~-22 ~150 ~24 ~-12 iron_block
fill ~160 ~21 ~-22 ~160 ~24 ~-12 iron_block
fill ~151 ~21 ~-21 ~159 ~24 ~-13 air
fill ~152 ~22 ~-22 ~154 ~23 ~-22 glass
fill ~152 ~22 ~-12 ~154 ~23 ~-12 glass
fill ~156 ~22 ~-22 ~158 ~23 ~-22 glass
fill ~156 ~22 ~-12 ~158 ~23 ~-12 glass
fill ~150 ~22 ~-20 ~150 ~23 ~-18 glass
fill ~160 ~22 ~-20 ~160 ~23 ~-18 glass
fill ~150 ~22 ~-16 ~150 ~23 ~-14 glass
fill ~160 ~22 ~-16 ~160 ~23 ~-14 glass
fill ~150 ~25 ~-22 ~160 ~25 ~-22 iron_block
fill ~150 ~25 ~-12 ~160 ~25 ~-12 iron_block
fill ~150 ~25 ~-21 ~150 ~25 ~-13 iron_block
fill ~160 ~25 ~-21 ~160 ~25 ~-13 iron_block
setblock ~155 ~20 ~-17 glowstone
fill ~150 ~25 ~-22 ~160 ~25 ~-12 polished_deepslate
fill ~150 ~26 ~-22 ~160 ~29 ~-22 iron_block
fill ~150 ~26 ~-12 ~160 ~29 ~-12 iron_block
fill ~150 ~26 ~-22 ~150 ~29 ~-12 iron_block
fill ~160 ~26 ~-22 ~160 ~29 ~-12 iron_block
fill ~151 ~26 ~-21 ~159 ~29 ~-13 air
fill ~152 ~27 ~-22 ~154 ~28 ~-22 glass
fill ~152 ~27 ~-12 ~154 ~28 ~-12 glass
fill ~156 ~27 ~-22 ~158 ~28 ~-22 glass
fill ~156 ~27 ~-12 ~158 ~28 ~-12 glass
fill ~150 ~27 ~-20 ~150 ~28 ~-18 glass
fill ~160 ~27 ~-20 ~160 ~28 ~-18 glass
fill ~150 ~27 ~-16 ~150 ~28 ~-14 glass
fill ~160 ~27 ~-16 ~160 ~28 ~-14 glass
fill ~150 ~30 ~-22 ~160 ~30 ~-22 iron_block
fill ~150 ~30 ~-12 ~160 ~30 ~-12 iron_block
fill ~150 ~30 ~-21 ~150 ~30 ~-13 iron_block
fill ~160 ~30 ~-21 ~160 ~30 ~-13 iron_block
setblock ~155 ~25 ~-17 glowstone
fill ~150 ~30 ~-22 ~160 ~30 ~-12 polished_deepslate
fill ~150 ~31 ~-22 ~160 ~34 ~-22 iron_block
fill ~150 ~31 ~-12 ~160 ~34 ~-12 iron_block
fill ~150 ~31 ~-22 ~150 ~34 ~-12 iron_block
fill ~160 ~31 ~-22 ~160 ~34 ~-12 iron_block
fill ~151 ~31 ~-21 ~159 ~34 ~-13 air
fill ~152 ~32 ~-22 ~154 ~33 ~-22 glass
fill ~152 ~32 ~-12 ~154 ~33 ~-12 glass
fill ~156 ~32 ~-22 ~158 ~33 ~-22 glass
fill ~156 ~32 ~-12 ~158 ~33 ~-12 glass
fill ~150 ~32 ~-20 ~150 ~33 ~-18 glass
fill ~160 ~32 ~-20 ~160 ~33 ~-18 glass
fill ~150 ~32 ~-16 ~150 ~33 ~-14 glass
fill ~160 ~32 ~-16 ~160 ~33 ~-14 glass
fill ~150 ~35 ~-22 ~160 ~35 ~-22 iron_block
fill ~150 ~35 ~-12 ~160 ~35 ~-12 iron_block
fill ~150 ~35 ~-21 ~150 ~35 ~-13 iron_block
fill ~160 ~35 ~-21 ~160 ~35 ~-13 iron_block
setblock ~155 ~30 ~-17 glowstone
fill ~150 ~35 ~-22 ~160 ~35 ~-12 polished_deepslate
fill ~150 ~36 ~-22 ~160 ~39 ~-22 iron_block
fill ~150 ~36 ~-12 ~160 ~39 ~-12 iron_block
fill ~150 ~36 ~-22 ~150 ~39 ~-12 iron_block
fill ~160 ~36 ~-22 ~160 ~39 ~-12 iron_block
fill ~151 ~36 ~-21 ~159 ~39 ~-13 air
fill ~152 ~37 ~-22 ~154 ~38 ~-22 glass
fill ~152 ~37 ~-12 ~154 ~38 ~-12 glass
fill ~156 ~37 ~-22 ~158 ~38 ~-22 glass
fill ~156 ~37 ~-12 ~158 ~38 ~-12 glass
fill ~150 ~37 ~-20 ~150 ~38 ~-18 glass
fill ~160 ~37 ~-20 ~160 ~38 ~-18 glass
fill ~150 ~37 ~-16 ~150 ~38 ~-14 glass
fill ~160 ~37 ~-16 ~160 ~38 ~-14 glass
fill ~150 ~40 ~-22 ~160 ~40 ~-22 iron_block
fill ~150 ~40 ~-12 ~160 ~40 ~-12 iron_block
fill ~150 ~40 ~-21 ~150 ~40 ~-13 iron_block
fill ~160 ~40 ~-21 ~160 ~40 ~-13 iron_block
setblock ~155 ~35 ~-17 glowstone
fill ~150 ~40 ~-22 ~160 ~40 ~-12 polished_deepslate
fill ~152 ~41 ~-20 ~154 ~42 ~-18 iron_block
fill ~153 ~1 ~-22 ~157 ~4 ~-22 air
fill ~153 ~5 ~-22 ~157 ~5 ~-22 iron_block
# --- Tower Epsilon (16x12, 60 tall) ---
fill ~116 ~-1 ~-10 ~132 ~-1 ~2 stone_bricks
fill ~116 ~0 ~-10 ~132 ~0 ~2 polished_deepslate
fill ~116 ~1 ~-10 ~132 ~4 ~-10 iron_block
fill ~116 ~1 ~2 ~132 ~4 ~2 iron_block
fill ~116 ~1 ~-10 ~116 ~4 ~2 iron_block
fill ~132 ~1 ~-10 ~132 ~4 ~2 iron_block
fill ~117 ~1 ~-9 ~131 ~4 ~1 air
fill ~118 ~2 ~-10 ~120 ~3 ~-10 glass
fill ~118 ~2 ~2 ~120 ~3 ~2 glass
fill ~122 ~2 ~-10 ~124 ~3 ~-10 glass
fill ~122 ~2 ~2 ~124 ~3 ~2 glass
fill ~126 ~2 ~-10 ~128 ~3 ~-10 glass
fill ~126 ~2 ~2 ~128 ~3 ~2 glass
fill ~116 ~2 ~-8 ~116 ~3 ~-6 glass
fill ~132 ~2 ~-8 ~132 ~3 ~-6 glass
fill ~116 ~2 ~-4 ~116 ~3 ~-2 glass
fill ~132 ~2 ~-4 ~132 ~3 ~-2 glass
fill ~116 ~5 ~-10 ~132 ~5 ~-10 iron_block
fill ~116 ~5 ~2 ~132 ~5 ~2 iron_block
fill ~116 ~5 ~-9 ~116 ~5 ~1 iron_block
fill ~132 ~5 ~-9 ~132 ~5 ~1 iron_block
setblock ~124 ~0 ~-4 glowstone
fill ~116 ~5 ~-10 ~132 ~5 ~2 polished_deepslate
fill ~116 ~6 ~-10 ~132 ~9 ~-10 iron_block
fill ~116 ~6 ~2 ~132 ~9 ~2 iron_block
fill ~116 ~6 ~-10 ~116 ~9 ~2 iron_block
fill ~132 ~6 ~-10 ~132 ~9 ~2 iron_block
fill ~117 ~6 ~-9 ~131 ~9 ~1 air
fill ~118 ~7 ~-10 ~120 ~8 ~-10 glass
fill ~118 ~7 ~2 ~120 ~8 ~2 glass
fill ~122 ~7 ~-10 ~124 ~8 ~-10 glass
fill ~122 ~7 ~2 ~124 ~8 ~2 glass
fill ~126 ~7 ~-10 ~128 ~8 ~-10 glass
fill ~126 ~7 ~2 ~128 ~8 ~2 glass
fill ~116 ~7 ~-8 ~116 ~8 ~-6 glass
fill ~132 ~7 ~-8 ~132 ~8 ~-6 glass
fill ~116 ~7 ~-4 ~116 ~8 ~-2 glass
fill ~132 ~7 ~-4 ~132 ~8 ~-2 glass
fill ~116 ~10 ~-10 ~132 ~10 ~-10 iron_block
fill ~116 ~10 ~2 ~132 ~10 ~2 iron_block
fill ~116 ~10 ~-9 ~116 ~10 ~1 iron_block
fill ~132 ~10 ~-9 ~132 ~10 ~1 iron_block
setblock ~124 ~5 ~-4 glowstone
fill ~116 ~10 ~-10 ~132 ~10 ~2 polished_deepslate
fill ~116 ~11 ~-10 ~132 ~14 ~-10 iron_block
fill ~116 ~11 ~2 ~132 ~14 ~2 iron_block
fill ~116 ~11 ~-10 ~116 ~14 ~2 iron_block
fill ~132 ~11 ~-10 ~132 ~14 ~2 iron_block
fill ~117 ~11 ~-9 ~131 ~14 ~1 air
fill ~118 ~12 ~-10 ~120 ~13 ~-10 glass
fill ~118 ~12 ~2 ~120 ~13 ~2 glass
fill ~122 ~12 ~-10 ~124 ~13 ~-10 glass
fill ~122 ~12 ~2 ~124 ~13 ~2 glass
fill ~126 ~12 ~-10 ~128 ~13 ~-10 glass
fill ~126 ~12 ~2 ~128 ~13 ~2 glass
fill ~116 ~12 ~-8 ~116 ~13 ~-6 glass
fill ~132 ~12 ~-8 ~132 ~13 ~-6 glass
fill ~116 ~12 ~-4 ~116 ~13 ~-2 glass
fill ~132 ~12 ~-4 ~132 ~13 ~-2 glass
fill ~116 ~15 ~-10 ~132 ~15 ~-10 iron_block
fill ~116 ~15 ~2 ~132 ~15 ~2 iron_block
fill ~116 ~15 ~-9 ~116 ~15 ~1 iron_block
fill ~132 ~15 ~-9 ~132 ~15 ~1 iron_block
setblock ~124 ~10 ~-4 glowstone
fill ~116 ~15 ~-10 ~132 ~15 ~2 polished_deepslate
fill ~116 ~16 ~-10 ~132 ~19 ~-10 iron_block
fill ~116 ~16 ~2 ~132 ~19 ~2 iron_block
fill ~116 ~16 ~-10 ~116 ~19 ~2 iron_block
fill ~132 ~16 ~-10 ~132 ~19 ~2 iron_block
fill ~117 ~16 ~-9 ~131 ~19 ~1 air
fill ~118 ~17 ~-10 ~120 ~18 ~-10 glass
fill ~118 ~17 ~2 ~120 ~18 ~2 glass
fill ~122 ~17 ~-10 ~124 ~18 ~-10 glass
fill ~122 ~17 ~2 ~124 ~18 ~2 glass
fill ~126 ~17 ~-10 ~128 ~18 ~-10 glass
fill ~126 ~17 ~2 ~128 ~18 ~2 glass
fill ~116 ~17 ~-8 ~116 ~18 ~-6 glass
fill ~132 ~17 ~-8 ~132 ~18 ~-6 glass
fill ~116 ~17 ~-4 ~116 ~18 ~-2 glass
fill ~132 ~17 ~-4 ~132 ~18 ~-2 glass
fill ~116 ~20 ~-10 ~132 ~20 ~-10 iron_block
fill ~116 ~20 ~2 ~132 ~20 ~2 iron_block
fill ~116 ~20 ~-9 ~116 ~20 ~1 iron_block
fill ~132 ~20 ~-9 ~132 ~20 ~1 iron_block
setblock ~124 ~15 ~-4 glowstone
fill ~116 ~20 ~-10 ~132 ~20 ~2 polished_deepslate
fill ~116 ~21 ~-10 ~132 ~24 ~-10 iron_block
fill ~116 ~21 ~2 ~132 ~24 ~2 iron_block
fill ~116 ~21 ~-10 ~116 ~24 ~2 iron_block
fill ~132 ~21 ~-10 ~132 ~24 ~2 iron_block
fill ~117 ~21 ~-9 ~131 ~24 ~1 air
fill ~118 ~22 ~-10 ~120 ~23 ~-10 glass
fill ~118 ~22 ~2 ~120 ~23 ~2 glass
fill ~122 ~22 ~-10 ~124 ~23 ~-10 glass
fill ~122 ~22 ~2 ~124 ~23 ~2 glass
fill ~126 ~22 ~-10 ~128 ~23 ~-10 glass
fill ~126 ~22 ~2 ~128 ~23 ~2 glass
fill ~116 ~22 ~-8 ~116 ~23 ~-6 glass
fill ~132 ~22 ~-8 ~132 ~23 ~-6 glass
fill ~116 ~22 ~-4 ~116 ~23 ~-2 glass
fill ~132 ~22 ~-4 ~132 ~23 ~-2 glass
fill ~116 ~25 ~-10 ~132 ~25 ~-10 iron_block
fill ~116 ~25 ~2 ~132 ~25 ~2 iron_block
fill ~116 ~25 ~-9 ~116 ~25 ~1 iron_block
fill ~132 ~25 ~-9 ~132 ~25 ~1 iron_block
setblock ~124 ~20 ~-4 glowstone
fill ~116 ~25 ~-10 ~132 ~25 ~2 polished_deepslate
fill ~116 ~26 ~-10 ~132 ~29 ~-10 iron_block
fill ~116 ~26 ~2 ~132 ~29 ~2 iron_block
fill ~116 ~26 ~-10 ~116 ~29 ~2 iron_block
fill ~132 ~26 ~-10 ~132 ~29 ~2 iron_block
fill ~117 ~26 ~-9 ~131 ~29 ~1 air
fill ~118 ~27 ~-10 ~120 ~28 ~-10 glass
fill ~118 ~27 ~2 ~120 ~28 ~2 glass
fill ~122 ~27 ~-10 ~124 ~28 ~-10 glass
fill ~122 ~27 ~2 ~124 ~28 ~2 glass
fill ~126 ~27 ~-10 ~128 ~28 ~-10 glass
fill ~126 ~27 ~2 ~128 ~28 ~2 glass
fill ~116 ~27 ~-8 ~116 ~28 ~-6 glass
fill ~132 ~27 ~-8 ~132 ~28 ~-6 glass
fill ~116 ~27 ~-4 ~116 ~28 ~-2 glass
fill ~132 ~27 ~-4 ~132 ~28 ~-2 glass
fill ~116 ~30 ~-10 ~132 ~30 ~-10 iron_block
fill ~116 ~30 ~2 ~132 ~30 ~2 iron_block
fill ~116 ~30 ~-9 ~116 ~30 ~1 iron_block
fill ~132 ~30 ~-9 ~132 ~30 ~1 iron_block
setblock ~124 ~25 ~-4 glowstone
fill ~116 ~30 ~-10 ~132 ~30 ~2 polished_deepslate
fill ~116 ~31 ~-10 ~132 ~34 ~-10 iron_block
fill ~116 ~31 ~2 ~132 ~34 ~2 iron_block
fill ~116 ~31 ~-10 ~116 ~34 ~2 iron_block
fill ~132 ~31 ~-10 ~132 ~34 ~2 iron_block
fill ~117 ~31 ~-9 ~131 ~34 ~1 air
fill ~118 ~32 ~-10 ~120 ~33 ~-10 glass
fill ~118 ~32 ~2 ~120 ~33 ~2 glass
fill ~122 ~32 ~-10 ~124 ~33 ~-10 glass
fill ~122 ~32 ~2 ~124 ~33 ~2 glass
fill ~126 ~32 ~-10 ~128 ~33 ~-10 glass
fill ~126 ~32 ~2 ~128 ~33 ~2 glass
fill ~116 ~32 ~-8 ~116 ~33 ~-6 glass
fill ~132 ~32 ~-8 ~132 ~33 ~-6 glass
fill ~116 ~32 ~-4 ~116 ~33 ~-2 glass
fill ~132 ~32 ~-4 ~132 ~33 ~-2 glass
fill ~116 ~35 ~-10 ~132 ~35 ~-10 iron_block
fill ~116 ~35 ~2 ~132 ~35 ~2 iron_block
fill ~116 ~35 ~-9 ~116 ~35 ~1 iron_block
fill ~132 ~35 ~-9 ~132 ~35 ~1 iron_block
setblock ~124 ~30 ~-4 glowstone
fill ~116 ~35 ~-10 ~132 ~35 ~2 polished_deepslate
fill ~116 ~36 ~-10 ~132 ~39 ~-10 iron_block
fill ~116 ~36 ~2 ~132 ~39 ~2 iron_block
fill ~116 ~36 ~-10 ~116 ~39 ~2 iron_block
fill ~132 ~36 ~-10 ~132 ~39 ~2 iron_block
fill ~117 ~36 ~-9 ~131 ~39 ~1 air
fill ~118 ~37 ~-10 ~120 ~38 ~-10 glass
fill ~118 ~37 ~2 ~120 ~38 ~2 glass
fill ~122 ~37 ~-10 ~124 ~38 ~-10 glass
fill ~122 ~37 ~2 ~124 ~38 ~2 glass
fill ~126 ~37 ~-10 ~128 ~38 ~-10 glass
fill ~126 ~37 ~2 ~128 ~38 ~2 glass
fill ~116 ~37 ~-8 ~116 ~38 ~-6 glass
fill ~132 ~37 ~-8 ~132 ~38 ~-6 glass
fill ~116 ~37 ~-4 ~116 ~38 ~-2 glass
fill ~132 ~37 ~-4 ~132 ~38 ~-2 glass
fill ~116 ~40 ~-10 ~132 ~40 ~-10 iron_block
fill ~116 ~40 ~2 ~132 ~40 ~2 iron_block
fill ~116 ~40 ~-9 ~116 ~40 ~1 iron_block
fill ~132 ~40 ~-9 ~132 ~40 ~1 iron_block
setblock ~124 ~35 ~-4 glowstone
fill ~116 ~40 ~-10 ~132 ~40 ~2 polished_deepslate
fill ~116 ~41 ~-10 ~132 ~44 ~-10 iron_block
fill ~116 ~41 ~2 ~132 ~44 ~2 iron_block
fill ~116 ~41 ~-10 ~116 ~44 ~2 iron_block
fill ~132 ~41 ~-10 ~132 ~44 ~2 iron_block
fill ~117 ~41 ~-9 ~131 ~44 ~1 air
fill ~118 ~42 ~-10 ~120 ~43 ~-10 glass
fill ~118 ~42 ~2 ~120 ~43 ~2 glass
fill ~122 ~42 ~-10 ~124 ~43 ~-10 glass
fill ~122 ~42 ~2 ~124 ~43 ~2 glass
fill ~126 ~42 ~-10 ~128 ~43 ~-10 glass
fill ~126 ~42 ~2 ~128 ~43 ~2 glass
fill ~116 ~42 ~-8 ~116 ~43 ~-6 glass
fill ~132 ~42 ~-8 ~132 ~43 ~-6 glass
fill ~116 ~42 ~-4 ~116 ~43 ~-2 glass
fill ~132 ~42 ~-4 ~132 ~43 ~-2 glass
fill ~116 ~45 ~-10 ~132 ~45 ~-10 iron_block
fill ~116 ~45 ~2 ~132 ~45 ~2 iron_block
fill ~116 ~45 ~-9 ~116 ~45 ~1 iron_block
fill ~132 ~45 ~-9 ~132 ~45 ~1 iron_block
setblock ~124 ~40 ~-4 glowstone
fill ~116 ~45 ~-10 ~132 ~45 ~2 polished_deepslate
fill ~116 ~46 ~-10 ~132 ~49 ~-10 iron_block
fill ~116 ~46 ~2 ~132 ~49 ~2 iron_block
fill ~116 ~46 ~-10 ~116 ~49 ~2 iron_block
fill ~132 ~46 ~-10 ~132 ~49 ~2 iron_block
fill ~117 ~46 ~-9 ~131 ~49 ~1 air
fill ~118 ~47 ~-10 ~120 ~48 ~-10 glass
fill ~118 ~47 ~2 ~120 ~48 ~2 glass
fill ~122 ~47 ~-10 ~124 ~48 ~-10 glass
fill ~122 ~47 ~2 ~124 ~48 ~2 glass
fill ~126 ~47 ~-10 ~128 ~48 ~-10 glass
fill ~126 ~47 ~2 ~128 ~48 ~2 glass
fill ~116 ~47 ~-8 ~116 ~48 ~-6 glass
fill ~132 ~47 ~-8 ~132 ~48 ~-6 glass
fill ~116 ~47 ~-4 ~116 ~48 ~-2 glass
fill ~132 ~47 ~-4 ~132 ~48 ~-2 glass
fill ~116 ~50 ~-10 ~132 ~50 ~-10 iron_block
fill ~116 ~50 ~2 ~132 ~50 ~2 iron_block
fill ~116 ~50 ~-9 ~116 ~50 ~1 iron_block
fill ~132 ~50 ~-9 ~132 ~50 ~1 iron_block
setblock ~124 ~45 ~-4 glowstone
fill ~116 ~50 ~-10 ~132 ~50 ~2 polished_deepslate
fill ~116 ~51 ~-10 ~132 ~54 ~-10 iron_block
fill ~116 ~51 ~2 ~132 ~54 ~2 iron_block
fill ~116 ~51 ~-10 ~116 ~54 ~2 iron_block
fill ~132 ~51 ~-10 ~132 ~54 ~2 iron_block
fill ~117 ~51 ~-9 ~131 ~54 ~1 air
fill ~118 ~52 ~-10 ~120 ~53 ~-10 glass
fill ~118 ~52 ~2 ~120 ~53 ~2 glass
fill ~122 ~52 ~-10 ~124 ~53 ~-10 glass
fill ~122 ~52 ~2 ~124 ~53 ~2 glass
fill ~126 ~52 ~-10 ~128 ~53 ~-10 glass
fill ~126 ~52 ~2 ~128 ~53 ~2 glass
fill ~116 ~52 ~-8 ~116 ~53 ~-6 glass
fill ~132 ~52 ~-8 ~132 ~53 ~-6 glass
fill ~116 ~52 ~-4 ~116 ~53 ~-2 glass
fill ~132 ~52 ~-4 ~132 ~53 ~-2 glass
fill ~116 ~55 ~-10 ~132 ~55 ~-10 iron_block
fill ~116 ~55 ~2 ~132 ~55 ~2 iron_block
fill ~116 ~55 ~-9 ~116 ~55 ~1 iron_block
fill ~132 ~55 ~-9 ~132 ~55 ~1 iron_block
setblock ~124 ~50 ~-4 glowstone
fill ~116 ~55 ~-10 ~132 ~55 ~2 polished_deepslate
fill ~116 ~56 ~-10 ~132 ~59 ~-10 iron_block
fill ~116 ~56 ~2 ~132 ~59 ~2 iron_block
fill ~116 ~56 ~-10 ~116 ~59 ~2 iron_block
fill ~132 ~56 ~-10 ~132 ~59 ~2 iron_block
fill ~117 ~56 ~-9 ~131 ~59 ~1 air
fill ~118 ~57 ~-10 ~120 ~58 ~-10 glass
fill ~118 ~57 ~2 ~120 ~58 ~2 glass
fill ~122 ~57 ~-10 ~124 ~58 ~-10 glass
fill ~122 ~57 ~2 ~124 ~58 ~2 glass
fill ~126 ~57 ~-10 ~128 ~58 ~-10 glass
fill ~126 ~57 ~2 ~128 ~58 ~2 glass
fill ~116 ~57 ~-8 ~116 ~58 ~-6 glass
fill ~132 ~57 ~-8 ~132 ~58 ~-6 glass
fill ~116 ~57 ~-4 ~116 ~58 ~-2 glass
fill ~132 ~57 ~-4 ~132 ~58 ~-2 glass
fill ~116 ~60 ~-10 ~132 ~60 ~-10 iron_block
fill ~116 ~60 ~2 ~132 ~60 ~2 iron_block
fill ~116 ~60 ~-9 ~116 ~60 ~1 iron_block
fill ~132 ~60 ~-9 ~132 ~60 ~1 iron_block
setblock ~124 ~55 ~-4 glowstone
fill ~116 ~60 ~-10 ~132 ~60 ~2 polished_deepslate
fill ~118 ~61 ~-8 ~120 ~62 ~-6 iron_block
fill ~122 ~1 ~-10 ~126 ~4 ~-10 air
fill ~122 ~5 ~-10 ~126 ~5 ~-10 iron_block
# --- Tower Zeta (10x10, 48 tall) ---
fill ~138 ~-1 ~-12 ~148 ~-1 ~-2 stone_bricks
fill ~138 ~0 ~-12 ~148 ~0 ~-2 polished_deepslate
fill ~138 ~1 ~-12 ~148 ~4 ~-12 iron_block
fill ~138 ~1 ~-2 ~148 ~4 ~-2 iron_block
fill ~138 ~1 ~-12 ~138 ~4 ~-2 iron_block
fill ~148 ~1 ~-12 ~148 ~4 ~-2 iron_block
fill ~139 ~1 ~-11 ~147 ~4 ~-3 air
fill ~140 ~2 ~-12 ~142 ~3 ~-12 glass
fill ~140 ~2 ~-2 ~142 ~3 ~-2 glass
fill ~144 ~2 ~-12 ~146 ~3 ~-12 glass
fill ~144 ~2 ~-2 ~146 ~3 ~-2 glass
fill ~138 ~2 ~-10 ~138 ~3 ~-8 glass
fill ~148 ~2 ~-10 ~148 ~3 ~-8 glass
fill ~138 ~2 ~-6 ~138 ~3 ~-4 glass
fill ~148 ~2 ~-6 ~148 ~3 ~-4 glass
fill ~138 ~5 ~-12 ~148 ~5 ~-12 iron_block
fill ~138 ~5 ~-2 ~148 ~5 ~-2 iron_block
fill ~138 ~5 ~-11 ~138 ~5 ~-3 iron_block
fill ~148 ~5 ~-11 ~148 ~5 ~-3 iron_block
setblock ~143 ~0 ~-7 glowstone
fill ~138 ~5 ~-12 ~148 ~5 ~-2 polished_deepslate
fill ~138 ~6 ~-12 ~148 ~9 ~-12 iron_block
fill ~138 ~6 ~-2 ~148 ~9 ~-2 iron_block
fill ~138 ~6 ~-12 ~138 ~9 ~-2 iron_block
fill ~148 ~6 ~-12 ~148 ~9 ~-2 iron_block
fill ~139 ~6 ~-11 ~147 ~9 ~-3 air
fill ~140 ~7 ~-12 ~142 ~8 ~-12 glass
fill ~140 ~7 ~-2 ~142 ~8 ~-2 glass
fill ~144 ~7 ~-12 ~146 ~8 ~-12 glass
fill ~144 ~7 ~-2 ~146 ~8 ~-2 glass
fill ~138 ~7 ~-10 ~138 ~8 ~-8 glass
fill ~148 ~7 ~-10 ~148 ~8 ~-8 glass
fill ~138 ~7 ~-6 ~138 ~8 ~-4 glass
fill ~148 ~7 ~-6 ~148 ~8 ~-4 glass
fill ~138 ~10 ~-12 ~148 ~10 ~-12 iron_block
fill ~138 ~10 ~-2 ~148 ~10 ~-2 iron_block
fill ~138 ~10 ~-11 ~138 ~10 ~-3 iron_block
fill ~148 ~10 ~-11 ~148 ~10 ~-3 iron_block
setblock ~143 ~5 ~-7 glowstone
fill ~138 ~10 ~-12 ~148 ~10 ~-2 polished_deepslate
fill ~138 ~11 ~-12 ~148 ~14 ~-12 iron_block
fill ~138 ~11 ~-2 ~148 ~14 ~-2 iron_block
fill ~138 ~11 ~-12 ~138 ~14 ~-2 iron_block
fill ~148 ~11 ~-12 ~148 ~14 ~-2 iron_block
fill ~139 ~11 ~-11 ~147 ~14 ~-3 air
fill ~140 ~12 ~-12 ~142 ~13 ~-12 glass
fill ~140 ~12 ~-2 ~142 ~13 ~-2 glass
fill ~144 ~12 ~-12 ~146 ~13 ~-12 glass
fill ~144 ~12 ~-2 ~146 ~13 ~-2 glass
fill ~138 ~12 ~-10 ~138 ~13 ~-8 glass
fill ~148 ~12 ~-10 ~148 ~13 ~-8 glass
fill ~138 ~12 ~-6 ~138 ~13 ~-4 glass
fill ~148 ~12 ~-6 ~148 ~13 ~-4 glass
fill ~138 ~15 ~-12 ~148 ~15 ~-12 iron_block
fill ~138 ~15 ~-2 ~148 ~15 ~-2 iron_block
fill ~138 ~15 ~-11 ~138 ~15 ~-3 iron_block
fill ~148 ~15 ~-11 ~148 ~15 ~-3 iron_block
setblock ~143 ~10 ~-7 glowstone
fill ~138 ~15 ~-12 ~148 ~15 ~-2 polished_deepslate
fill ~138 ~16 ~-12 ~148 ~19 ~-12 iron_block
fill ~138 ~16 ~-2 ~148 ~19 ~-2 iron_block
fill ~138 ~16 ~-12 ~138 ~19 ~-2 iron_block
fill ~148 ~16 ~-12 ~148 ~19 ~-2 iron_block
fill ~139 ~16 ~-11 ~147 ~19 ~-3 air
fill ~140 ~17 ~-12 ~142 ~18 ~-12 glass
fill ~140 ~17 ~-2 ~142 ~18 ~-2 glass
fill ~144 ~17 ~-12 ~146 ~18 ~-12 glass
fill ~144 ~17 ~-2 ~146 ~18 ~-2 glass
fill ~138 ~17 ~-10 ~138 ~18 ~-8 glass
fill ~148 ~17 ~-10 ~148 ~18 ~-8 glass
fill ~138 ~17 ~-6 ~138 ~18 ~-4 glass
fill ~148 ~17 ~-6 ~148 ~18 ~-4 glass
fill ~138 ~20 ~-12 ~148 ~20 ~-12 iron_block
fill ~138 ~20 ~-2 ~148 ~20 ~-2 iron_block
fill ~138 ~20 ~-11 ~138 ~20 ~-3 iron_block
fill ~148 ~20 ~-11 ~148 ~20 ~-3 iron_block
setblock ~143 ~15 ~-7 glowstone
fill ~138 ~20 ~-12 ~148 ~20 ~-2 polished_deepslate
fill ~138 ~21 ~-12 ~148 ~24 ~-12 iron_block
fill ~138 ~21 ~-2 ~148 ~24 ~-2 iron_block
fill ~138 ~21 ~-12 ~138 ~24 ~-2 iron_block
fill ~148 ~21 ~-12 ~148 ~24 ~-2 iron_block
fill ~139 ~21 ~-11 ~147 ~24 ~-3 air
fill ~140 ~22 ~-12 ~142 ~23 ~-12 glass
fill ~140 ~22 ~-2 ~142 ~23 ~-2 glass
fill ~144 ~22 ~-12 ~146 ~23 ~-12 glass
fill ~144 ~22 ~-2 ~146 ~23 ~-2 glass
fill ~138 ~22 ~-10 ~138 ~23 ~-8 glass
fill ~148 ~22 ~-10 ~148 ~23 ~-8 glass
fill ~138 ~22 ~-6 ~138 ~23 ~-4 glass
fill ~148 ~22 ~-6 ~148 ~23 ~-4 glass
fill ~138 ~25 ~-12 ~148 ~25 ~-12 iron_block
fill ~138 ~25 ~-2 ~148 ~25 ~-2 iron_block
fill ~138 ~25 ~-11 ~138 ~25 ~-3 iron_block
fill ~148 ~25 ~-11 ~148 ~25 ~-3 iron_block
setblock ~143 ~20 ~-7 glowstone
fill ~138 ~25 ~-12 ~148 ~25 ~-2 polished_deepslate
fill ~138 ~26 ~-12 ~148 ~29 ~-12 iron_block
fill ~138 ~26 ~-2 ~148 ~29 ~-2 iron_block
fill ~138 ~26 ~-12 ~138 ~29 ~-2 iron_block
fill ~148 ~26 ~-12 ~148 ~29 ~-2 iron_block
fill ~139 ~26 ~-11 ~147 ~29 ~-3 air
fill ~140 ~27 ~-12 ~142 ~28 ~-12 glass
fill ~140 ~27 ~-2 ~142 ~28 ~-2 glass
fill ~144 ~27 ~-12 ~146 ~28 ~-12 glass
fill ~144 ~27 ~-2 ~146 ~28 ~-2 glass
fill ~138 ~27 ~-10 ~138 ~28 ~-8 glass
fill ~148 ~27 ~-10 ~148 ~28 ~-8 glass
fill ~138 ~27 ~-6 ~138 ~28 ~-4 glass
fill ~148 ~27 ~-6 ~148 ~28 ~-4 glass
fill ~138 ~30 ~-12 ~148 ~30 ~-12 iron_block
fill ~138 ~30 ~-2 ~148 ~30 ~-2 iron_block
fill ~138 ~30 ~-11 ~138 ~30 ~-3 iron_block
fill ~148 ~30 ~-11 ~148 ~30 ~-3 iron_block
setblock ~143 ~25 ~-7 glowstone
fill ~138 ~30 ~-12 ~148 ~30 ~-2 polished_deepslate
fill ~138 ~31 ~-12 ~148 ~34 ~-12 iron_block
fill ~138 ~31 ~-2 ~148 ~34 ~-2 iron_block
fill ~138 ~31 ~-12 ~138 ~34 ~-2 iron_block
fill ~148 ~31 ~-12 ~148 ~34 ~-2 iron_block
fill ~139 ~31 ~-11 ~147 ~34 ~-3 air
fill ~140 ~32 ~-12 ~142 ~33 ~-12 glass
fill ~140 ~32 ~-2 ~142 ~33 ~-2 glass
fill ~144 ~32 ~-12 ~146 ~33 ~-12 glass
fill ~144 ~32 ~-2 ~146 ~33 ~-2 glass
fill ~138 ~32 ~-10 ~138 ~33 ~-8 glass
fill ~148 ~32 ~-10 ~148 ~33 ~-8 glass
fill ~138 ~32 ~-6 ~138 ~33 ~-4 glass
fill ~148 ~32 ~-6 ~148 ~33 ~-4 glass
fill ~138 ~35 ~-12 ~148 ~35 ~-12 iron_block
fill ~138 ~35 ~-2 ~148 ~35 ~-2 iron_block
fill ~138 ~35 ~-11 ~138 ~35 ~-3 iron_block
fill ~148 ~35 ~-11 ~148 ~35 ~-3 iron_block
setblock ~143 ~30 ~-7 glowstone
fill ~138 ~35 ~-12 ~148 ~35 ~-2 polished_deepslate
fill ~138 ~36 ~-12 ~148 ~39 ~-12 iron_block
fill ~138 ~36 ~-2 ~148 ~39 ~-2 iron_block
fill ~138 ~36 ~-12 ~138 ~39 ~-2 iron_block
fill ~148 ~36 ~-12 ~148 ~39 ~-2 iron_block
fill ~139 ~36 ~-11 ~147 ~39 ~-3 air
fill ~140 ~37 ~-12 ~142 ~38 ~-12 glass
fill ~140 ~37 ~-2 ~142 ~38 ~-2 glass
fill ~144 ~37 ~-12 ~146 ~38 ~-12 glass
fill ~144 ~37 ~-2 ~146 ~38 ~-2 glass
fill ~138 ~37 ~-10 ~138 ~38 ~-8 glass
fill ~148 ~37 ~-10 ~148 ~38 ~-8 glass
fill ~138 ~37 ~-6 ~138 ~38 ~-4 glass
fill ~148 ~37 ~-6 ~148 ~38 ~-4 glass
fill ~138 ~40 ~-12 ~148 ~40 ~-12 iron_block
fill ~138 ~40 ~-2 ~148 ~40 ~-2 iron_block
fill ~138 ~40 ~-11 ~138 ~40 ~-3 iron_block
fill ~148 ~40 ~-11 ~148 ~40 ~-3 iron_block
setblock ~143 ~35 ~-7 glowstone
fill ~138 ~40 ~-12 ~148 ~40 ~-2 polished_deepslate
fill ~138 ~41 ~-12 ~148 ~44 ~-12 iron_block
fill ~138 ~41 ~-2 ~148 ~44 ~-2 iron_block
fill ~138 ~41 ~-12 ~138 ~44 ~-2 iron_block
fill ~148 ~41 ~-12 ~148 ~44 ~-2 iron_block
fill ~139 ~41 ~-11 ~147 ~44 ~-3 air
fill ~140 ~42 ~-12 ~142 ~43 ~-12 glass
fill ~140 ~42 ~-2 ~142 ~43 ~-2 glass
fill ~144 ~42 ~-12 ~146 ~43 ~-12 glass
fill ~144 ~42 ~-2 ~146 ~43 ~-2 glass
fill ~138 ~42 ~-10 ~138 ~43 ~-8 glass
fill ~148 ~42 ~-10 ~148 ~43 ~-8 glass
fill ~138 ~42 ~-6 ~138 ~43 ~-4 glass
fill ~148 ~42 ~-6 ~148 ~43 ~-4 glass
fill ~138 ~45 ~-12 ~148 ~45 ~-12 iron_block
fill ~138 ~45 ~-2 ~148 ~45 ~-2 iron_block
fill ~138 ~45 ~-11 ~138 ~45 ~-3 iron_block
fill ~148 ~45 ~-11 ~148 ~45 ~-3 iron_block
setblock ~143 ~40 ~-7 glowstone
fill ~138 ~45 ~-12 ~148 ~45 ~-2 polished_deepslate
fill ~138 ~46 ~-12 ~148 ~47 ~-12 iron_block
fill ~138 ~46 ~-2 ~148 ~47 ~-2 iron_block
fill ~138 ~46 ~-12 ~138 ~47 ~-2 iron_block
fill ~148 ~46 ~-12 ~148 ~47 ~-2 iron_block
fill ~139 ~46 ~-11 ~147 ~47 ~-3 air
fill ~140 ~46 ~-12 ~142 ~47 ~-12 glass
fill ~140 ~46 ~-2 ~142 ~47 ~-2 glass
fill ~144 ~46 ~-12 ~146 ~47 ~-12 glass
fill ~144 ~46 ~-2 ~146 ~47 ~-2 glass
fill ~138 ~46 ~-10 ~138 ~47 ~-8 glass
fill ~148 ~46 ~-10 ~148 ~47 ~-8 glass
fill ~138 ~46 ~-6 ~138 ~47 ~-4 glass
fill ~148 ~46 ~-6 ~148 ~47 ~-4 glass
fill ~138 ~48 ~-12 ~148 ~48 ~-12 iron_block
fill ~138 ~48 ~-2 ~148 ~48 ~-2 iron_block
fill ~138 ~48 ~-11 ~138 ~48 ~-3 iron_block
fill ~148 ~48 ~-11 ~148 ~48 ~-3 iron_block
setblock ~143 ~45 ~-7 glowstone
fill ~138 ~48 ~-12 ~148 ~48 ~-2 polished_deepslate
fill ~140 ~49 ~-10 ~142 ~50 ~-8 iron_block
fill ~141 ~1 ~-12 ~145 ~4 ~-12 air
fill ~141 ~5 ~-12 ~145 ~5 ~-12 iron_block
fill ~95 ~1 ~-34 ~95 ~4 ~-34 iron_block
setblock ~95 ~5 ~-34 glowstone
fill ~95 ~1 ~-26 ~95 ~4 ~-26 iron_block
setblock ~95 ~5 ~-26 glowstone
fill ~110 ~1 ~-34 ~110 ~4 ~-34 iron_block
setblock ~110 ~5 ~-34 glowstone
fill ~110 ~1 ~-26 ~110 ~4 ~-26 iron_block
setblock ~110 ~5 ~-26 glowstone
fill ~125 ~1 ~-34 ~125 ~4 ~-34 iron_block
setblock ~125 ~5 ~-34 glowstone
fill ~125 ~1 ~-26 ~125 ~4 ~-26 iron_block
setblock ~125 ~5 ~-26 glowstone
fill ~140 ~1 ~-34 ~140 ~4 ~-34 iron_block
setblock ~140 ~5 ~-34 glowstone
fill ~140 ~1 ~-26 ~140 ~4 ~-26 iron_block
setblock ~140 ~5 ~-26 glowstone
fill ~155 ~1 ~-34 ~155 ~4 ~-34 iron_block
setblock ~155 ~5 ~-34 glowstone
fill ~155 ~1 ~-26 ~155 ~4 ~-26 iron_block
setblock ~155 ~5 ~-26 glowstone
fill ~88 ~0 ~-42 ~96 ~0 ~-12 grass_block
fill ~88 ~0 ~-11 ~96 ~0 ~-5 grass_block
setblock ~95 ~1 ~-24 oak_log
setblock ~95 ~2 ~-24 oak_log
setblock ~95 ~3 ~-24 oak_log
setblock ~95 ~4 ~-24 oak_log
fill ~94 ~5 ~-25 ~96 ~6 ~-23 oak_leaves
setblock ~91 ~1 ~-28 oak_log
setblock ~91 ~2 ~-28 oak_log
setblock ~91 ~3 ~-28 oak_log
setblock ~91 ~4 ~-28 oak_log
fill ~90 ~5 ~-29 ~92 ~6 ~-27 oak_leaves
setblock ~90 ~1 ~-28 oak_log
setblock ~90 ~2 ~-28 oak_log
setblock ~90 ~3 ~-28 oak_log
setblock ~90 ~4 ~-28 oak_log
fill ~89 ~5 ~-29 ~91 ~6 ~-27 oak_leaves
setblock ~95 ~1 ~-33 oak_log
setblock ~95 ~2 ~-33 oak_log
setblock ~95 ~3 ~-33 oak_log
setblock ~95 ~4 ~-33 oak_log
fill ~94 ~5 ~-34 ~96 ~6 ~-32 oak_leaves
setblock ~91 ~1 ~-10 oak_log
setblock ~91 ~2 ~-10 oak_log
setblock ~91 ~3 ~-10 oak_log
setblock ~91 ~4 ~-10 oak_log
fill ~90 ~5 ~-11 ~92 ~6 ~-9 oak_leaves
setblock ~93 ~1 ~-25 oak_log
setblock ~93 ~2 ~-25 oak_log
setblock ~93 ~3 ~-25 oak_log
setblock ~93 ~4 ~-25 oak_log
fill ~92 ~5 ~-26 ~94 ~6 ~-24 oak_leaves
setblock ~90 ~1 ~-8 oak_log
setblock ~90 ~2 ~-8 oak_log
setblock ~90 ~3 ~-8 oak_log
setblock ~90 ~4 ~-8 oak_log
fill ~89 ~5 ~-9 ~91 ~6 ~-7 oak_leaves
setblock ~89 ~1 ~-23 oak_log
setblock ~89 ~2 ~-23 oak_log
setblock ~89 ~3 ~-23 oak_log
setblock ~89 ~4 ~-23 oak_log
fill ~88 ~5 ~-24 ~90 ~6 ~-22 oak_leaves
