# Phase 4: South side houses
# --- Minimalist House at (0,53) ---
fill ~0 ~0 ~53 ~19 ~0 ~74 grass_block
fill ~8 ~0 ~53 ~11 ~0 ~56 gray_concrete
fill ~9 ~0 ~54 ~10 ~0 ~56 stone
fill ~0 ~1 ~74 ~19 ~1 ~74 dark_oak_fence
fill ~0 ~1 ~54 ~0 ~1 ~74 dark_oak_fence
fill ~19 ~1 ~54 ~19 ~1 ~74 dark_oak_fence
fill ~3 ~0 ~57 ~16 ~0 ~72 quartz_block
fill ~3 ~1 ~57 ~16 ~5 ~57 white_concrete
fill ~3 ~1 ~72 ~16 ~5 ~72 white_concrete
fill ~3 ~1 ~57 ~3 ~5 ~72 white_concrete
fill ~16 ~1 ~57 ~16 ~5 ~72 white_concrete
fill ~4 ~1 ~58 ~15 ~4 ~71 air
fill ~2 ~5 ~56 ~17 ~5 ~73 white_concrete
fill ~2 ~5 ~56 ~17 ~5 ~56 quartz_block
fill ~2 ~5 ~73 ~17 ~5 ~73 quartz_block
fill ~5 ~2 ~57 ~8 ~4 ~57 glass
fill ~11 ~2 ~57 ~14 ~4 ~57 glass
fill ~3 ~2 ~61 ~3 ~4 ~64 glass
fill ~3 ~2 ~67 ~3 ~4 ~70 glass
fill ~16 ~2 ~61 ~16 ~4 ~64 glass
fill ~16 ~2 ~67 ~16 ~4 ~70 glass
fill ~6 ~2 ~72 ~13 ~4 ~72 glass
fill ~9 ~1 ~57 ~10 ~3 ~57 air
fill ~9 ~4 ~57 ~10 ~4 ~57 quartz_block
fill ~4 ~1 ~58 ~8 ~1 ~62 quartz_block
fill ~4 ~1 ~61 ~7 ~1 ~61 quartz_block
fill ~4 ~2 ~62 ~7 ~2 ~62 quartz_block
fill ~5 ~1 ~59 ~6 ~1 ~60 dark_oak_planks
setblock ~4 ~2 ~58 black_concrete
setblock ~5 ~2 ~58 black_concrete
setblock ~6 ~2 ~58 black_concrete
fill ~11 ~1 ~58 ~15 ~1 ~58 polished_deepslate
fill ~11 ~1 ~59 ~15 ~1 ~59 polished_deepslate
setblock ~15 ~1 ~58 crafting_table
setblock ~13 ~2 ~58 glowstone
fill ~10 ~1 ~62 ~10 ~3 ~68 white_concrete
fill ~10 ~1 ~64 ~10 ~3 ~66 air
fill ~4 ~1 ~68 ~4 ~1 ~71 quartz_block
fill ~5 ~1 ~69 ~7 ~1 ~70 white_wool
fill ~5 ~1 ~71 ~7 ~2 ~71 quartz_block
setblock ~4 ~1 ~70 dark_oak_planks
setblock ~8 ~1 ~70 dark_oak_planks
setblock ~4 ~2 ~70 sea_lantern
setblock ~8 ~2 ~70 sea_lantern
fill ~12 ~0 ~68 ~15 ~0 ~71 quartz_block
fill ~13 ~1 ~71 ~15 ~1 ~71 quartz_block
setblock ~14 ~2 ~71 glass
setblock ~12 ~1 ~69 cauldron
setblock ~7 ~4 ~60 glowstone
setblock ~13 ~4 ~60 glowstone
setblock ~7 ~4 ~69 glowstone
setblock ~13 ~4 ~69 glowstone
fill ~17 ~0 ~57 ~22 ~0 ~64 polished_deepslate
fill ~17 ~1 ~64 ~22 ~4 ~64 white_concrete
fill ~22 ~1 ~57 ~22 ~4 ~64 white_concrete
fill ~17 ~1 ~57 ~17 ~4 ~64 white_concrete
fill ~17 ~4 ~57 ~22 ~4 ~64 white_concrete
fill ~18 ~1 ~58 ~21 ~3 ~63 air
fill ~18 ~1 ~57 ~21 ~3 ~57 air
setblock ~1 ~1 ~56 oak_leaves
setblock ~2 ~1 ~56 oak_leaves
setblock ~13 ~1 ~56 oak_leaves
setblock ~14 ~1 ~56 oak_leaves
setblock ~5 ~1 ~71 birch_log
setblock ~5 ~2 ~71 birch_log
setblock ~5 ~3 ~71 birch_log
setblock ~5 ~4 ~71 birch_log
fill ~3 ~5 ~69 ~7 ~6 ~73 birch_leaves
fill ~4 ~7 ~70 ~6 ~7 ~72 birch_leaves
setblock ~8 ~1 ~53 cobblestone_wall
setblock ~8 ~2 ~53 iron_block
setblock ~9 ~3 ~56 sea_lantern
# --- Contemporary House at (22,53) ---
fill ~22 ~0 ~53 ~41 ~0 ~74 grass_block
fill ~30 ~0 ~53 ~33 ~0 ~56 gray_concrete
fill ~31 ~0 ~54 ~32 ~0 ~56 stone
fill ~22 ~1 ~74 ~41 ~1 ~74 dark_oak_fence
fill ~22 ~1 ~54 ~22 ~1 ~74 dark_oak_fence
fill ~41 ~1 ~54 ~41 ~1 ~74 dark_oak_fence
fill ~25 ~0 ~57 ~38 ~0 ~72 birch_planks
fill ~25 ~1 ~57 ~38 ~5 ~57 white_concrete
fill ~25 ~1 ~72 ~38 ~5 ~72 white_concrete
fill ~25 ~1 ~57 ~25 ~5 ~72 white_concrete
fill ~38 ~1 ~57 ~38 ~5 ~72 white_concrete
fill ~26 ~1 ~58 ~37 ~4 ~71 air
fill ~24 ~5 ~56 ~39 ~5 ~73 gray_concrete
fill ~24 ~5 ~56 ~39 ~5 ~56 dark_oak_planks
fill ~24 ~5 ~73 ~39 ~5 ~73 dark_oak_planks
fill ~27 ~2 ~57 ~30 ~4 ~57 glass
fill ~33 ~2 ~57 ~36 ~4 ~57 glass
fill ~25 ~2 ~61 ~25 ~4 ~64 glass
fill ~25 ~2 ~67 ~25 ~4 ~70 glass
fill ~38 ~2 ~61 ~38 ~4 ~64 glass
fill ~38 ~2 ~67 ~38 ~4 ~70 glass
fill ~28 ~2 ~72 ~35 ~4 ~72 glass
fill ~31 ~1 ~57 ~32 ~3 ~57 air
fill ~31 ~4 ~57 ~32 ~4 ~57 dark_oak_planks
fill ~26 ~1 ~58 ~30 ~1 ~62 birch_planks
fill ~26 ~1 ~61 ~29 ~1 ~61 dark_oak_planks
fill ~26 ~2 ~62 ~29 ~2 ~62 dark_oak_planks
fill ~27 ~1 ~59 ~28 ~1 ~60 dark_oak_planks
setblock ~26 ~2 ~58 black_concrete
setblock ~27 ~2 ~58 black_concrete
setblock ~28 ~2 ~58 black_concrete
fill ~33 ~1 ~58 ~37 ~1 ~58 polished_deepslate
fill ~33 ~1 ~59 ~37 ~1 ~59 polished_deepslate
setblock ~37 ~1 ~58 crafting_table
setblock ~35 ~2 ~58 glowstone
fill ~32 ~1 ~62 ~32 ~3 ~68 white_concrete
fill ~32 ~1 ~64 ~32 ~3 ~66 air
fill ~26 ~1 ~68 ~26 ~1 ~71 birch_planks
fill ~27 ~1 ~69 ~29 ~1 ~70 white_wool
fill ~27 ~1 ~71 ~29 ~2 ~71 dark_oak_planks
setblock ~26 ~1 ~70 dark_oak_planks
setblock ~30 ~1 ~70 dark_oak_planks
setblock ~26 ~2 ~70 sea_lantern
setblock ~30 ~2 ~70 sea_lantern
fill ~34 ~0 ~68 ~37 ~0 ~71 quartz_block
fill ~35 ~1 ~71 ~37 ~1 ~71 quartz_block
setblock ~36 ~2 ~71 glass
setblock ~34 ~1 ~69 cauldron
setblock ~29 ~4 ~60 glowstone
setblock ~35 ~4 ~60 glowstone
setblock ~29 ~4 ~69 glowstone
setblock ~35 ~4 ~69 glowstone
fill ~39 ~0 ~57 ~44 ~0 ~64 polished_deepslate
fill ~39 ~1 ~64 ~44 ~4 ~64 white_concrete
fill ~44 ~1 ~57 ~44 ~4 ~64 white_concrete
fill ~39 ~1 ~57 ~39 ~4 ~64 white_concrete
fill ~39 ~4 ~57 ~44 ~4 ~64 gray_concrete
fill ~40 ~1 ~58 ~43 ~3 ~63 air
fill ~40 ~1 ~57 ~43 ~3 ~57 air
setblock ~23 ~1 ~56 oak_leaves
setblock ~24 ~1 ~56 oak_leaves
setblock ~35 ~1 ~56 oak_leaves
setblock ~36 ~1 ~56 oak_leaves
setblock ~27 ~1 ~71 birch_log
setblock ~27 ~2 ~71 birch_log
setblock ~27 ~3 ~71 birch_log
setblock ~27 ~4 ~71 birch_log
fill ~25 ~5 ~69 ~29 ~6 ~73 birch_leaves
fill ~26 ~7 ~70 ~28 ~7 ~72 birch_leaves
setblock ~30 ~1 ~53 cobblestone_wall
setblock ~30 ~2 ~53 iron_block
setblock ~31 ~3 ~56 sea_lantern
# --- Luxury House at (50,53) ---
fill ~50 ~0 ~53 ~69 ~0 ~74 grass_block
fill ~58 ~0 ~53 ~61 ~0 ~56 gray_concrete
fill ~59 ~0 ~54 ~60 ~0 ~56 stone
fill ~50 ~1 ~74 ~69 ~1 ~74 dark_oak_fence
fill ~50 ~1 ~54 ~50 ~1 ~74 dark_oak_fence
fill ~69 ~1 ~54 ~69 ~1 ~74 dark_oak_fence
fill ~53 ~0 ~57 ~66 ~0 ~72 dark_oak_planks
fill ~53 ~1 ~57 ~66 ~5 ~57 quartz_block
fill ~53 ~1 ~72 ~66 ~5 ~72 quartz_block
fill ~53 ~1 ~57 ~53 ~5 ~72 quartz_block
fill ~66 ~1 ~57 ~66 ~5 ~72 quartz_block
fill ~54 ~1 ~58 ~65 ~4 ~71 air
fill ~52 ~5 ~56 ~67 ~5 ~73 gray_concrete
fill ~52 ~5 ~56 ~67 ~5 ~56 gold_block
fill ~52 ~5 ~73 ~67 ~5 ~73 gold_block
fill ~55 ~2 ~57 ~58 ~4 ~57 glass
fill ~61 ~2 ~57 ~64 ~4 ~57 glass
fill ~53 ~2 ~61 ~53 ~4 ~64 glass
fill ~53 ~2 ~67 ~53 ~4 ~70 glass
fill ~66 ~2 ~61 ~66 ~4 ~64 glass
fill ~66 ~2 ~67 ~66 ~4 ~70 glass
fill ~56 ~2 ~72 ~63 ~4 ~72 glass
fill ~59 ~1 ~57 ~60 ~3 ~57 air
fill ~59 ~4 ~57 ~60 ~4 ~57 gold_block
fill ~54 ~1 ~58 ~58 ~1 ~62 dark_oak_planks
fill ~54 ~1 ~61 ~57 ~1 ~61 gold_block
fill ~54 ~2 ~62 ~57 ~2 ~62 gold_block
fill ~55 ~1 ~59 ~56 ~1 ~60 dark_oak_planks
setblock ~54 ~2 ~58 black_concrete
setblock ~55 ~2 ~58 black_concrete
setblock ~56 ~2 ~58 black_concrete
fill ~61 ~1 ~58 ~65 ~1 ~58 polished_deepslate
fill ~61 ~1 ~59 ~65 ~1 ~59 polished_deepslate
setblock ~65 ~1 ~58 crafting_table
setblock ~63 ~2 ~58 glowstone
fill ~60 ~1 ~62 ~60 ~3 ~68 quartz_block
fill ~60 ~1 ~64 ~60 ~3 ~66 air
fill ~54 ~1 ~68 ~54 ~1 ~71 dark_oak_planks
fill ~55 ~1 ~69 ~57 ~1 ~70 white_wool
fill ~55 ~1 ~71 ~57 ~2 ~71 gold_block
setblock ~54 ~1 ~70 dark_oak_planks
setblock ~58 ~1 ~70 dark_oak_planks
setblock ~54 ~2 ~70 sea_lantern
setblock ~58 ~2 ~70 sea_lantern
fill ~62 ~0 ~68 ~65 ~0 ~71 quartz_block
fill ~63 ~1 ~71 ~65 ~1 ~71 quartz_block
setblock ~64 ~2 ~71 glass
setblock ~62 ~1 ~69 cauldron
setblock ~57 ~4 ~60 glowstone
setblock ~63 ~4 ~60 glowstone
setblock ~57 ~4 ~69 glowstone
setblock ~63 ~4 ~69 glowstone
fill ~67 ~0 ~57 ~72 ~0 ~64 polished_deepslate
fill ~67 ~1 ~64 ~72 ~4 ~64 quartz_block
fill ~72 ~1 ~57 ~72 ~4 ~64 quartz_block
fill ~67 ~1 ~57 ~67 ~4 ~64 quartz_block
fill ~67 ~4 ~57 ~72 ~4 ~64 gray_concrete
fill ~68 ~1 ~58 ~71 ~3 ~63 air
fill ~68 ~1 ~57 ~71 ~3 ~57 air
setblock ~51 ~1 ~56 oak_leaves
setblock ~52 ~1 ~56 oak_leaves
setblock ~63 ~1 ~56 oak_leaves
setblock ~64 ~1 ~56 oak_leaves
setblock ~55 ~1 ~71 birch_log
setblock ~55 ~2 ~71 birch_log
setblock ~55 ~3 ~71 birch_log
setblock ~55 ~4 ~71 birch_log
fill ~53 ~5 ~69 ~57 ~6 ~73 birch_leaves
fill ~54 ~7 ~70 ~56 ~7 ~72 birch_leaves
setblock ~58 ~1 ~53 cobblestone_wall
setblock ~58 ~2 ~53 iron_block
setblock ~59 ~3 ~56 sea_lantern
# --- Industrial House at (72,53) ---
fill ~72 ~0 ~53 ~91 ~0 ~74 grass_block
fill ~80 ~0 ~53 ~83 ~0 ~56 gray_concrete
fill ~81 ~0 ~54 ~82 ~0 ~56 stone
fill ~72 ~1 ~74 ~91 ~1 ~74 dark_oak_fence
fill ~72 ~1 ~54 ~72 ~1 ~74 dark_oak_fence
fill ~91 ~1 ~54 ~91 ~1 ~74 dark_oak_fence
fill ~75 ~0 ~57 ~88 ~0 ~72 polished_deepslate
fill ~75 ~1 ~57 ~88 ~5 ~57 light_gray_concrete
fill ~75 ~1 ~72 ~88 ~5 ~72 light_gray_concrete
fill ~75 ~1 ~57 ~75 ~5 ~72 light_gray_concrete
fill ~88 ~1 ~57 ~88 ~5 ~72 light_gray_concrete
fill ~76 ~1 ~58 ~87 ~4 ~71 air
fill ~74 ~5 ~56 ~89 ~5 ~73 black_concrete
fill ~74 ~5 ~56 ~89 ~5 ~56 iron_block
fill ~74 ~5 ~73 ~89 ~5 ~73 iron_block
fill ~77 ~2 ~57 ~80 ~4 ~57 glass
fill ~83 ~2 ~57 ~86 ~4 ~57 glass
fill ~75 ~2 ~61 ~75 ~4 ~64 glass
fill ~75 ~2 ~67 ~75 ~4 ~70 glass
fill ~88 ~2 ~61 ~88 ~4 ~64 glass
fill ~88 ~2 ~67 ~88 ~4 ~70 glass
fill ~78 ~2 ~72 ~85 ~4 ~72 glass
fill ~81 ~1 ~57 ~82 ~3 ~57 air
fill ~81 ~4 ~57 ~82 ~4 ~57 iron_block
fill ~76 ~1 ~58 ~80 ~1 ~62 polished_deepslate
fill ~76 ~1 ~61 ~79 ~1 ~61 iron_block
fill ~76 ~2 ~62 ~79 ~2 ~62 iron_block
fill ~77 ~1 ~59 ~78 ~1 ~60 dark_oak_planks
setblock ~76 ~2 ~58 black_concrete
setblock ~77 ~2 ~58 black_concrete
setblock ~78 ~2 ~58 black_concrete
fill ~83 ~1 ~58 ~87 ~1 ~58 polished_deepslate
fill ~83 ~1 ~59 ~87 ~1 ~59 polished_deepslate
setblock ~87 ~1 ~58 crafting_table
setblock ~85 ~2 ~58 glowstone
fill ~82 ~1 ~62 ~82 ~3 ~68 light_gray_concrete
fill ~82 ~1 ~64 ~82 ~3 ~66 air
fill ~76 ~1 ~68 ~76 ~1 ~71 polished_deepslate
fill ~77 ~1 ~69 ~79 ~1 ~70 white_wool
fill ~77 ~1 ~71 ~79 ~2 ~71 iron_block
setblock ~76 ~1 ~70 dark_oak_planks
setblock ~80 ~1 ~70 dark_oak_planks
setblock ~76 ~2 ~70 sea_lantern
setblock ~80 ~2 ~70 sea_lantern
fill ~84 ~0 ~68 ~87 ~0 ~71 quartz_block
fill ~85 ~1 ~71 ~87 ~1 ~71 quartz_block
setblock ~86 ~2 ~71 glass
setblock ~84 ~1 ~69 cauldron
setblock ~79 ~4 ~60 glowstone
setblock ~85 ~4 ~60 glowstone
setblock ~79 ~4 ~69 glowstone
setblock ~85 ~4 ~69 glowstone
fill ~89 ~0 ~57 ~94 ~0 ~64 polished_deepslate
fill ~89 ~1 ~64 ~94 ~4 ~64 light_gray_concrete
fill ~94 ~1 ~57 ~94 ~4 ~64 light_gray_concrete
fill ~89 ~1 ~57 ~89 ~4 ~64 light_gray_concrete
fill ~89 ~4 ~57 ~94 ~4 ~64 black_concrete
fill ~90 ~1 ~58 ~93 ~3 ~63 air
fill ~90 ~1 ~57 ~93 ~3 ~57 air
setblock ~73 ~1 ~56 oak_leaves
setblock ~74 ~1 ~56 oak_leaves
setblock ~85 ~1 ~56 oak_leaves
setblock ~86 ~1 ~56 oak_leaves
setblock ~77 ~1 ~71 birch_log
setblock ~77 ~2 ~71 birch_log
setblock ~77 ~3 ~71 birch_log
setblock ~77 ~4 ~71 birch_log
fill ~75 ~5 ~69 ~79 ~6 ~73 birch_leaves
fill ~76 ~7 ~70 ~78 ~7 ~72 birch_leaves
setblock ~80 ~1 ~53 cobblestone_wall
setblock ~80 ~2 ~53 iron_block
setblock ~81 ~3 ~56 sea_lantern
# --- Rustic Modern House at (50,78) ---
fill ~50 ~0 ~78 ~69 ~0 ~99 grass_block
fill ~58 ~0 ~78 ~61 ~0 ~81 gray_concrete
fill ~59 ~0 ~79 ~60 ~0 ~81 stone
fill ~50 ~1 ~99 ~69 ~1 ~99 dark_oak_fence
fill ~50 ~1 ~79 ~50 ~1 ~99 dark_oak_fence
fill ~69 ~1 ~79 ~69 ~1 ~99 dark_oak_fence
fill ~53 ~0 ~82 ~66 ~0 ~97 spruce_planks
fill ~53 ~1 ~82 ~66 ~5 ~82 stone_bricks
fill ~53 ~1 ~97 ~66 ~5 ~97 stone_bricks
fill ~53 ~1 ~82 ~53 ~5 ~97 stone_bricks
fill ~66 ~1 ~82 ~66 ~5 ~97 stone_bricks
fill ~54 ~1 ~83 ~65 ~4 ~96 air
fill ~52 ~5 ~81 ~67 ~5 ~98 dark_oak_planks
fill ~52 ~5 ~81 ~67 ~5 ~81 spruce_planks
fill ~52 ~5 ~98 ~67 ~5 ~98 spruce_planks
fill ~55 ~2 ~82 ~58 ~4 ~82 glass
fill ~61 ~2 ~82 ~64 ~4 ~82 glass
fill ~53 ~2 ~86 ~53 ~4 ~89 glass
fill ~53 ~2 ~92 ~53 ~4 ~95 glass
fill ~66 ~2 ~86 ~66 ~4 ~89 glass
fill ~66 ~2 ~92 ~66 ~4 ~95 glass
fill ~56 ~2 ~97 ~63 ~4 ~97 glass
fill ~59 ~1 ~82 ~60 ~3 ~82 air
fill ~59 ~4 ~82 ~60 ~4 ~82 spruce_planks
fill ~54 ~1 ~83 ~58 ~1 ~87 spruce_planks
fill ~54 ~1 ~86 ~57 ~1 ~86 spruce_planks
fill ~54 ~2 ~87 ~57 ~2 ~87 spruce_planks
fill ~55 ~1 ~84 ~56 ~1 ~85 dark_oak_planks
setblock ~54 ~2 ~83 black_concrete
setblock ~55 ~2 ~83 black_concrete
setblock ~56 ~2 ~83 black_concrete
fill ~61 ~1 ~83 ~65 ~1 ~83 polished_deepslate
fill ~61 ~1 ~84 ~65 ~1 ~84 polished_deepslate
setblock ~65 ~1 ~83 crafting_table
setblock ~63 ~2 ~83 glowstone
fill ~60 ~1 ~87 ~60 ~3 ~93 stone_bricks
fill ~60 ~1 ~89 ~60 ~3 ~91 air
fill ~54 ~1 ~93 ~54 ~1 ~96 spruce_planks
fill ~55 ~1 ~94 ~57 ~1 ~95 white_wool
fill ~55 ~1 ~96 ~57 ~2 ~96 spruce_planks
setblock ~54 ~1 ~95 dark_oak_planks
setblock ~58 ~1 ~95 dark_oak_planks
setblock ~54 ~2 ~95 sea_lantern
setblock ~58 ~2 ~95 sea_lantern
fill ~62 ~0 ~93 ~65 ~0 ~96 quartz_block
fill ~63 ~1 ~96 ~65 ~1 ~96 quartz_block
setblock ~64 ~2 ~96 glass
setblock ~62 ~1 ~94 cauldron
setblock ~57 ~4 ~85 glowstone
setblock ~63 ~4 ~85 glowstone
setblock ~57 ~4 ~94 glowstone
setblock ~63 ~4 ~94 glowstone
fill ~67 ~0 ~82 ~72 ~0 ~89 polished_deepslate
fill ~67 ~1 ~89 ~72 ~4 ~89 stone_bricks
fill ~72 ~1 ~82 ~72 ~4 ~89 stone_bricks
fill ~67 ~1 ~82 ~67 ~4 ~89 stone_bricks
fill ~67 ~4 ~82 ~72 ~4 ~89 dark_oak_planks
fill ~68 ~1 ~83 ~71 ~3 ~88 air
fill ~68 ~1 ~82 ~71 ~3 ~82 air
setblock ~51 ~1 ~81 oak_leaves
setblock ~52 ~1 ~81 oak_leaves
setblock ~63 ~1 ~81 oak_leaves
setblock ~64 ~1 ~81 oak_leaves
setblock ~55 ~1 ~96 birch_log
setblock ~55 ~2 ~96 birch_log
setblock ~55 ~3 ~96 birch_log
setblock ~55 ~4 ~96 birch_log
fill ~53 ~5 ~94 ~57 ~6 ~98 birch_leaves
fill ~54 ~7 ~95 ~56 ~7 ~97 birch_leaves
setblock ~58 ~1 ~78 cobblestone_wall
setblock ~58 ~2 ~78 iron_block
setblock ~59 ~3 ~81 sea_lantern
function town_park
