# Phase 3: North side houses
# --- Contemporary House at (0,20) ---
fill ~0 ~0 ~20 ~19 ~0 ~41 grass_block
fill ~8 ~0 ~20 ~11 ~0 ~23 gray_concrete
fill ~9 ~0 ~21 ~10 ~0 ~23 stone
fill ~0 ~1 ~41 ~19 ~1 ~41 dark_oak_fence
fill ~0 ~1 ~21 ~0 ~1 ~41 dark_oak_fence
fill ~19 ~1 ~21 ~19 ~1 ~41 dark_oak_fence
fill ~3 ~0 ~24 ~16 ~0 ~39 birch_planks
fill ~3 ~1 ~24 ~16 ~5 ~24 white_concrete
fill ~3 ~1 ~39 ~16 ~5 ~39 white_concrete
fill ~3 ~1 ~24 ~3 ~5 ~39 white_concrete
fill ~16 ~1 ~24 ~16 ~5 ~39 white_concrete
fill ~4 ~1 ~25 ~15 ~4 ~38 air
fill ~2 ~5 ~23 ~17 ~5 ~40 gray_concrete
fill ~2 ~5 ~23 ~17 ~5 ~23 dark_oak_planks
fill ~2 ~5 ~40 ~17 ~5 ~40 dark_oak_planks
fill ~5 ~2 ~24 ~8 ~4 ~24 glass
fill ~11 ~2 ~24 ~14 ~4 ~24 glass
fill ~3 ~2 ~28 ~3 ~4 ~31 glass
fill ~3 ~2 ~34 ~3 ~4 ~37 glass
fill ~16 ~2 ~28 ~16 ~4 ~31 glass
fill ~16 ~2 ~34 ~16 ~4 ~37 glass
fill ~6 ~2 ~39 ~13 ~4 ~39 glass
fill ~9 ~1 ~24 ~10 ~3 ~24 air
fill ~9 ~4 ~24 ~10 ~4 ~24 dark_oak_planks
fill ~4 ~1 ~25 ~8 ~1 ~29 birch_planks
fill ~4 ~1 ~28 ~7 ~1 ~28 dark_oak_planks
fill ~4 ~2 ~29 ~7 ~2 ~29 dark_oak_planks
fill ~5 ~1 ~26 ~6 ~1 ~27 dark_oak_planks
setblock ~4 ~2 ~25 black_concrete
setblock ~5 ~2 ~25 black_concrete
setblock ~6 ~2 ~25 black_concrete
fill ~11 ~1 ~25 ~15 ~1 ~25 polished_deepslate
fill ~11 ~1 ~26 ~15 ~1 ~26 polished_deepslate
setblock ~15 ~1 ~25 crafting_table
setblock ~13 ~2 ~25 glowstone
fill ~10 ~1 ~29 ~10 ~3 ~35 white_concrete
fill ~10 ~1 ~31 ~10 ~3 ~33 air
fill ~4 ~1 ~35 ~4 ~1 ~38 birch_planks
fill ~5 ~1 ~36 ~7 ~1 ~37 white_wool
fill ~5 ~1 ~38 ~7 ~2 ~38 dark_oak_planks
setblock ~4 ~1 ~37 dark_oak_planks
setblock ~8 ~1 ~37 dark_oak_planks
setblock ~4 ~2 ~37 sea_lantern
setblock ~8 ~2 ~37 sea_lantern
fill ~12 ~0 ~35 ~15 ~0 ~38 quartz_block
fill ~13 ~1 ~38 ~15 ~1 ~38 quartz_block
setblock ~14 ~2 ~38 glass
setblock ~12 ~1 ~36 cauldron
setblock ~7 ~4 ~27 glowstone
setblock ~13 ~4 ~27 glowstone
setblock ~7 ~4 ~36 glowstone
setblock ~13 ~4 ~36 glowstone
fill ~17 ~0 ~24 ~22 ~0 ~31 polished_deepslate
fill ~17 ~1 ~31 ~22 ~4 ~31 white_concrete
fill ~22 ~1 ~24 ~22 ~4 ~31 white_concrete
fill ~17 ~1 ~24 ~17 ~4 ~31 white_concrete
fill ~17 ~4 ~24 ~22 ~4 ~31 gray_concrete
fill ~18 ~1 ~25 ~21 ~3 ~30 air
fill ~18 ~1 ~24 ~21 ~3 ~24 air
setblock ~1 ~1 ~23 oak_leaves
setblock ~2 ~1 ~23 oak_leaves
setblock ~13 ~1 ~23 oak_leaves
setblock ~14 ~1 ~23 oak_leaves
setblock ~5 ~1 ~38 birch_log
setblock ~5 ~2 ~38 birch_log
setblock ~5 ~3 ~38 birch_log
setblock ~5 ~4 ~38 birch_log
fill ~3 ~5 ~36 ~7 ~6 ~40 birch_leaves
fill ~4 ~7 ~37 ~6 ~7 ~39 birch_leaves
setblock ~8 ~1 ~20 cobblestone_wall
setblock ~8 ~2 ~20 iron_block
setblock ~9 ~3 ~23 sea_lantern
# --- Industrial House at (22,20) ---
fill ~22 ~0 ~20 ~41 ~0 ~41 grass_block
fill ~30 ~0 ~20 ~33 ~0 ~23 gray_concrete
fill ~31 ~0 ~21 ~32 ~0 ~23 stone
fill ~22 ~1 ~41 ~41 ~1 ~41 dark_oak_fence
fill ~22 ~1 ~21 ~22 ~1 ~41 dark_oak_fence
fill ~41 ~1 ~21 ~41 ~1 ~41 dark_oak_fence
fill ~25 ~0 ~24 ~38 ~0 ~39 polished_deepslate
fill ~25 ~1 ~24 ~38 ~5 ~24 light_gray_concrete
fill ~25 ~1 ~39 ~38 ~5 ~39 light_gray_concrete
fill ~25 ~1 ~24 ~25 ~5 ~39 light_gray_concrete
fill ~38 ~1 ~24 ~38 ~5 ~39 light_gray_concrete
fill ~26 ~1 ~25 ~37 ~4 ~38 air
fill ~24 ~5 ~23 ~39 ~5 ~40 black_concrete
fill ~24 ~5 ~23 ~39 ~5 ~23 iron_block
fill ~24 ~5 ~40 ~39 ~5 ~40 iron_block
fill ~27 ~2 ~24 ~30 ~4 ~24 glass
fill ~33 ~2 ~24 ~36 ~4 ~24 glass
fill ~25 ~2 ~28 ~25 ~4 ~31 glass
fill ~25 ~2 ~34 ~25 ~4 ~37 glass
fill ~38 ~2 ~28 ~38 ~4 ~31 glass
fill ~38 ~2 ~34 ~38 ~4 ~37 glass
fill ~28 ~2 ~39 ~35 ~4 ~39 glass
fill ~31 ~1 ~24 ~32 ~3 ~24 air
fill ~31 ~4 ~24 ~32 ~4 ~24 iron_block
fill ~26 ~1 ~25 ~30 ~1 ~29 polished_deepslate
fill ~26 ~1 ~28 ~29 ~1 ~28 iron_block
fill ~26 ~2 ~29 ~29 ~2 ~29 iron_block
fill ~27 ~1 ~26 ~28 ~1 ~27 dark_oak_planks
setblock ~26 ~2 ~25 black_concrete
setblock ~27 ~2 ~25 black_concrete
setblock ~28 ~2 ~25 black_concrete
fill ~33 ~1 ~25 ~37 ~1 ~25 polished_deepslate
fill ~33 ~1 ~26 ~37 ~1 ~26 polished_deepslate
setblock ~37 ~1 ~25 crafting_table
setblock ~35 ~2 ~25 glowstone
fill ~32 ~1 ~29 ~32 ~3 ~35 light_gray_concrete
fill ~32 ~1 ~31 ~32 ~3 ~33 air
fill ~26 ~1 ~35 ~26 ~1 ~38 polished_deepslate
fill ~27 ~1 ~36 ~29 ~1 ~37 white_wool
fill ~27 ~1 ~38 ~29 ~2 ~38 iron_block
setblock ~26 ~1 ~37 dark_oak_planks
setblock ~30 ~1 ~37 dark_oak_planks
setblock ~26 ~2 ~37 sea_lantern
setblock ~30 ~2 ~37 sea_lantern
fill ~34 ~0 ~35 ~37 ~0 ~38 quartz_block
fill ~35 ~1 ~38 ~37 ~1 ~38 quartz_block
setblock ~36 ~2 ~38 glass
setblock ~34 ~1 ~36 cauldron
setblock ~29 ~4 ~27 glowstone
setblock ~35 ~4 ~27 glowstone
setblock ~29 ~4 ~36 glowstone
setblock ~35 ~4 ~36 glowstone
fill ~39 ~0 ~24 ~44 ~0 ~31 polished_deepslate
fill ~39 ~1 ~31 ~44 ~4 ~31 light_gray_concrete
fill ~44 ~1 ~24 ~44 ~4 ~31 light_gray_concrete
fill ~39 ~1 ~24 ~39 ~4 ~31 light_gray_concrete
fill ~39 ~4 ~24 ~44 ~4 ~31 black_concrete
fill ~40 ~1 ~25 ~43 ~3 ~30 air
fill ~40 ~1 ~24 ~43 ~3 ~24 air
setblock ~23 ~1 ~23 oak_leaves
setblock ~24 ~1 ~23 oak_leaves
setblock ~35 ~1 ~23 oak_leaves
setblock ~36 ~1 ~23 oak_leaves
setblock ~27 ~1 ~38 birch_log
setblock ~27 ~2 ~38 birch_log
setblock ~27 ~3 ~38 birch_log
setblock ~27 ~4 ~38 birch_log
fill ~25 ~5 ~36 ~29 ~6 ~40 birch_leaves
fill ~26 ~7 ~37 ~28 ~7 ~39 birch_leaves
setblock ~30 ~1 ~20 cobblestone_wall
setblock ~30 ~2 ~20 iron_block
setblock ~31 ~3 ~23 sea_lantern
# --- Minimalist House at (50,20) ---
fill ~50 ~0 ~20 ~69 ~0 ~41 grass_block
fill ~58 ~0 ~20 ~61 ~0 ~23 gray_concrete
fill ~59 ~0 ~21 ~60 ~0 ~23 stone
fill ~50 ~1 ~41 ~69 ~1 ~41 dark_oak_fence
fill ~50 ~1 ~21 ~50 ~1 ~41 dark_oak_fence
fill ~69 ~1 ~21 ~69 ~1 ~41 dark_oak_fence
fill ~53 ~0 ~24 ~66 ~0 ~39 quartz_block
fill ~53 ~1 ~24 ~66 ~5 ~24 white_concrete
fill ~53 ~1 ~39 ~66 ~5 ~39 white_concrete
fill ~53 ~1 ~24 ~53 ~5 ~39 white_concrete
fill ~66 ~1 ~24 ~66 ~5 ~39 white_concrete
fill ~54 ~1 ~25 ~65 ~4 ~38 air
fill ~52 ~5 ~23 ~67 ~5 ~40 white_concrete
fill ~52 ~5 ~23 ~67 ~5 ~23 quartz_block
fill ~52 ~5 ~40 ~67 ~5 ~40 quartz_block
fill ~55 ~2 ~24 ~58 ~4 ~24 glass
fill ~61 ~2 ~24 ~64 ~4 ~24 glass
fill ~53 ~2 ~28 ~53 ~4 ~31 glass
fill ~53 ~2 ~34 ~53 ~4 ~37 glass
fill ~66 ~2 ~28 ~66 ~4 ~31 glass
fill ~66 ~2 ~34 ~66 ~4 ~37 glass
fill ~56 ~2 ~39 ~63 ~4 ~39 glass
fill ~59 ~1 ~24 ~60 ~3 ~24 air
fill ~59 ~4 ~24 ~60 ~4 ~24 quartz_block
fill ~54 ~1 ~25 ~58 ~1 ~29 quartz_block
fill ~54 ~1 ~28 ~57 ~1 ~28 quartz_block
fill ~54 ~2 ~29 ~57 ~2 ~29 quartz_block
fill ~55 ~1 ~26 ~56 ~1 ~27 dark_oak_planks
setblock ~54 ~2 ~25 black_concrete
setblock ~55 ~2 ~25 black_concrete
setblock ~56 ~2 ~25 black_concrete
fill ~61 ~1 ~25 ~65 ~1 ~25 polished_deepslate
fill ~61 ~1 ~26 ~65 ~1 ~26 polished_deepslate
setblock ~65 ~1 ~25 crafting_table
setblock ~63 ~2 ~25 glowstone
fill ~60 ~1 ~29 ~60 ~3 ~35 white_concrete
fill ~60 ~1 ~31 ~60 ~3 ~33 air
fill ~54 ~1 ~35 ~54 ~1 ~38 quartz_block
fill ~55 ~1 ~36 ~57 ~1 ~37 white_wool
fill ~55 ~1 ~38 ~57 ~2 ~38 quartz_block
setblock ~54 ~1 ~37 dark_oak_planks
setblock ~58 ~1 ~37 dark_oak_planks
setblock ~54 ~2 ~37 sea_lantern
setblock ~58 ~2 ~37 sea_lantern
fill ~62 ~0 ~35 ~65 ~0 ~38 quartz_block
fill ~63 ~1 ~38 ~65 ~1 ~38 quartz_block
setblock ~64 ~2 ~38 glass
setblock ~62 ~1 ~36 cauldron
setblock ~57 ~4 ~27 glowstone
setblock ~63 ~4 ~27 glowstone
setblock ~57 ~4 ~36 glowstone
setblock ~63 ~4 ~36 glowstone
fill ~67 ~0 ~24 ~72 ~0 ~31 polished_deepslate
fill ~67 ~1 ~31 ~72 ~4 ~31 white_concrete
fill ~72 ~1 ~24 ~72 ~4 ~31 white_concrete
fill ~67 ~1 ~24 ~67 ~4 ~31 white_concrete
fill ~67 ~4 ~24 ~72 ~4 ~31 white_concrete
fill ~68 ~1 ~25 ~71 ~3 ~30 air
fill ~68 ~1 ~24 ~71 ~3 ~24 air
setblock ~51 ~1 ~23 oak_leaves
setblock ~52 ~1 ~23 oak_leaves
setblock ~63 ~1 ~23 oak_leaves
setblock ~64 ~1 ~23 oak_leaves
setblock ~55 ~1 ~38 birch_log
setblock ~55 ~2 ~38 birch_log
setblock ~55 ~3 ~38 birch_log
setblock ~55 ~4 ~38 birch_log
fill ~53 ~5 ~36 ~57 ~6 ~40 birch_leaves
fill ~54 ~7 ~37 ~56 ~7 ~39 birch_leaves
setblock ~58 ~1 ~20 cobblestone_wall
setblock ~58 ~2 ~20 iron_block
setblock ~59 ~3 ~23 sea_lantern
# --- Rustic Modern House at (72,20) ---
fill ~72 ~0 ~20 ~91 ~0 ~41 grass_block
fill ~80 ~0 ~20 ~83 ~0 ~23 gray_concrete
fill ~81 ~0 ~21 ~82 ~0 ~23 stone
fill ~72 ~1 ~41 ~91 ~1 ~41 dark_oak_fence
fill ~72 ~1 ~21 ~72 ~1 ~41 dark_oak_fence
fill ~91 ~1 ~21 ~91 ~1 ~41 dark_oak_fence
fill ~75 ~0 ~24 ~88 ~0 ~39 spruce_planks
fill ~75 ~1 ~24 ~88 ~5 ~24 stone_bricks
fill ~75 ~1 ~39 ~88 ~5 ~39 stone_bricks
fill ~75 ~1 ~24 ~75 ~5 ~39 stone_bricks
fill ~88 ~1 ~24 ~88 ~5 ~39 stone_bricks
fill ~76 ~1 ~25 ~87 ~4 ~38 air
fill ~74 ~5 ~23 ~89 ~5 ~40 dark_oak_planks
fill ~74 ~5 ~23 ~89 ~5 ~23 spruce_planks
fill ~74 ~5 ~40 ~89 ~5 ~40 spruce_planks
fill ~77 ~2 ~24 ~80 ~4 ~24 glass
fill ~83 ~2 ~24 ~86 ~4 ~24 glass
fill ~75 ~2 ~28 ~75 ~4 ~31 glass
fill ~75 ~2 ~34 ~75 ~4 ~37 glass
fill ~88 ~2 ~28 ~88 ~4 ~31 glass
fill ~88 ~2 ~34 ~88 ~4 ~37 glass
fill ~78 ~2 ~39 ~85 ~4 ~39 glass
fill ~81 ~1 ~24 ~82 ~3 ~24 air
fill ~81 ~4 ~24 ~82 ~4 ~24 spruce_planks
fill ~76 ~1 ~25 ~80 ~1 ~29 spruce_planks
fill ~76 ~1 ~28 ~79 ~1 ~28 spruce_planks
fill ~76 ~2 ~29 ~79 ~2 ~29 spruce_planks
fill ~77 ~1 ~26 ~78 ~1 ~27 dark_oak_planks
setblock ~76 ~2 ~25 black_concrete
setblock ~77 ~2 ~25 black_concrete
setblock ~78 ~2 ~25 black_concrete
fill ~83 ~1 ~25 ~87 ~1 ~25 polished_deepslate
fill ~83 ~1 ~26 ~87 ~1 ~26 polished_deepslate
setblock ~87 ~1 ~25 crafting_table
setblock ~85 ~2 ~25 glowstone
fill ~82 ~1 ~29 ~82 ~3 ~35 stone_bricks
fill ~82 ~1 ~31 ~82 ~3 ~33 air
fill ~76 ~1 ~35 ~76 ~1 ~38 spruce_planks
fill ~77 ~1 ~36 ~79 ~1 ~37 white_wool
fill ~77 ~1 ~38 ~79 ~2 ~38 spruce_planks
setblock ~76 ~1 ~37 dark_oak_planks
setblock ~80 ~1 ~37 dark_oak_planks
setblock ~76 ~2 ~37 sea_lantern
setblock ~80 ~2 ~37 sea_lantern
fill ~84 ~0 ~35 ~87 ~0 ~38 quartz_block
fill ~85 ~1 ~38 ~87 ~1 ~38 quartz_block
setblock ~86 ~2 ~38 glass
setblock ~84 ~1 ~36 cauldron
setblock ~79 ~4 ~27 glowstone
setblock ~85 ~4 ~27 glowstone
setblock ~79 ~4 ~36 glowstone
setblock ~85 ~4 ~36 glowstone
fill ~89 ~0 ~24 ~94 ~0 ~31 polished_deepslate
fill ~89 ~1 ~31 ~94 ~4 ~31 stone_bricks
fill ~94 ~1 ~24 ~94 ~4 ~31 stone_bricks
fill ~89 ~1 ~24 ~89 ~4 ~31 stone_bricks
fill ~89 ~4 ~24 ~94 ~4 ~31 dark_oak_planks
fill ~90 ~1 ~25 ~93 ~3 ~30 air
fill ~90 ~1 ~24 ~93 ~3 ~24 air
setblock ~73 ~1 ~23 oak_leaves
setblock ~74 ~1 ~23 oak_leaves
setblock ~85 ~1 ~23 oak_leaves
setblock ~86 ~1 ~23 oak_leaves
setblock ~77 ~1 ~38 birch_log
setblock ~77 ~2 ~38 birch_log
setblock ~77 ~3 ~38 birch_log
setblock ~77 ~4 ~38 birch_log
fill ~75 ~5 ~36 ~79 ~6 ~40 birch_leaves
fill ~76 ~7 ~37 ~78 ~7 ~39 birch_leaves
setblock ~80 ~1 ~20 cobblestone_wall
setblock ~80 ~2 ~20 iron_block
setblock ~81 ~3 ~23 sea_lantern
# --- Luxury House at (0,0) ---
fill ~0 ~0 ~0 ~19 ~0 ~21 grass_block
fill ~8 ~0 ~0 ~11 ~0 ~3 gray_concrete
fill ~9 ~0 ~1 ~10 ~0 ~3 stone
fill ~0 ~1 ~21 ~19 ~1 ~21 dark_oak_fence
fill ~0 ~1 ~1 ~0 ~1 ~21 dark_oak_fence
fill ~19 ~1 ~1 ~19 ~1 ~21 dark_oak_fence
fill ~3 ~0 ~4 ~16 ~0 ~19 dark_oak_planks
fill ~3 ~1 ~4 ~16 ~5 ~4 quartz_block
fill ~3 ~1 ~19 ~16 ~5 ~19 quartz_block
fill ~3 ~1 ~4 ~3 ~5 ~19 quartz_block
fill ~16 ~1 ~4 ~16 ~5 ~19 quartz_block
fill ~4 ~1 ~5 ~15 ~4 ~18 air
fill ~2 ~5 ~3 ~17 ~5 ~20 gray_concrete
fill ~2 ~5 ~3 ~17 ~5 ~3 gold_block
fill ~2 ~5 ~20 ~17 ~5 ~20 gold_block
fill ~5 ~2 ~4 ~8 ~4 ~4 glass
fill ~11 ~2 ~4 ~14 ~4 ~4 glass
fill ~3 ~2 ~8 ~3 ~4 ~11 glass
fill ~3 ~2 ~14 ~3 ~4 ~17 glass
fill ~16 ~2 ~8 ~16 ~4 ~11 glass
fill ~16 ~2 ~14 ~16 ~4 ~17 glass
fill ~6 ~2 ~19 ~13 ~4 ~19 glass
fill ~9 ~1 ~4 ~10 ~3 ~4 air
fill ~9 ~4 ~4 ~10 ~4 ~4 gold_block
fill ~4 ~1 ~5 ~8 ~1 ~9 dark_oak_planks
fill ~4 ~1 ~8 ~7 ~1 ~8 gold_block
fill ~4 ~2 ~9 ~7 ~2 ~9 gold_block
fill ~5 ~1 ~6 ~6 ~1 ~7 dark_oak_planks
setblock ~4 ~2 ~5 black_concrete
setblock ~5 ~2 ~5 black_concrete
setblock ~6 ~2 ~5 black_concrete
fill ~11 ~1 ~5 ~15 ~1 ~5 polished_deepslate
fill ~11 ~1 ~6 ~15 ~1 ~6 polished_deepslate
setblock ~15 ~1 ~5 crafting_table
setblock ~13 ~2 ~5 glowstone
fill ~10 ~1 ~9 ~10 ~3 ~15 quartz_block
fill ~10 ~1 ~11 ~10 ~3 ~13 air
fill ~4 ~1 ~15 ~4 ~1 ~18 dark_oak_planks
fill ~5 ~1 ~16 ~7 ~1 ~17 white_wool
fill ~5 ~1 ~18 ~7 ~2 ~18 gold_block
setblock ~4 ~1 ~17 dark_oak_planks
setblock ~8 ~1 ~17 dark_oak_planks
setblock ~4 ~2 ~17 sea_lantern
setblock ~8 ~2 ~17 sea_lantern
fill ~12 ~0 ~15 ~15 ~0 ~18 quartz_block
fill ~13 ~1 ~18 ~15 ~1 ~18 quartz_block
setblock ~14 ~2 ~18 glass
setblock ~12 ~1 ~16 cauldron
setblock ~7 ~4 ~7 glowstone
setblock ~13 ~4 ~7 glowstone
setblock ~7 ~4 ~16 glowstone
setblock ~13 ~4 ~16 glowstone
fill ~17 ~0 ~4 ~22 ~0 ~11 polished_deepslate
fill ~17 ~1 ~11 ~22 ~4 ~11 quartz_block
fill ~22 ~1 ~4 ~22 ~4 ~11 quartz_block
fill ~17 ~1 ~4 ~17 ~4 ~11 quartz_block
fill ~17 ~4 ~4 ~22 ~4 ~11 gray_concrete
fill ~18 ~1 ~5 ~21 ~3 ~10 air
fill ~18 ~1 ~4 ~21 ~3 ~4 air
setblock ~1 ~1 ~3 oak_leaves
setblock ~2 ~1 ~3 oak_leaves
setblock ~13 ~1 ~3 oak_leaves
setblock ~14 ~1 ~3 oak_leaves
setblock ~5 ~1 ~18 birch_log
setblock ~5 ~2 ~18 birch_log
setblock ~5 ~3 ~18 birch_log
setblock ~5 ~4 ~18 birch_log
fill ~3 ~5 ~16 ~7 ~6 ~20 birch_leaves
fill ~4 ~7 ~17 ~6 ~7 ~19 birch_leaves
setblock ~8 ~1 ~0 cobblestone_wall
setblock ~8 ~2 ~0 iron_block
setblock ~9 ~3 ~3 sea_lantern
function town_houses2
